Workbook

Sheet Hinweise
A1: C-Grundlagenkataster – institutionelle Ausgangslage | B1: Stand: 14.10.2026 (verifizierte Fassung)
A2: Zweck | B2: Arbeitskataster C1–C5 für Niklas Assignment 01; kein fertiges Tragfähigkeitsrating.
A3: Hierarchie | B3: Bund → Kantone Uri / Basel-Landschaft / St. Gallen → Pilotgemeinden Seelisberg / Münchenstein / Wil.
A4: Datenlage | B4: Offizielle Links wurden recherchiert; Portal-Links sind ausdrücklich keine Belege für spezifische Einzelangaben.
A5: Geltung | B5: Rechtsfassungen, Berichtsjahre und konkrete Werte vor Verwendung prüfen.
A6: Tragfähigkeit | B6: Noch nicht bewertet, da Kennzahlen und qualitative Befunde nicht vollständig erhoben wurden.
A7: Confidence | B7: Confidence bewertet die Aussagekraft der Katalogzeile, nicht die Gemeindequalität.
A8: Aufgabenprofil | B8: C1 Finanzen, C2 Boden, C3 Governance, C4 Verwaltung, C5 Politik; Kennzahlen/Reifegrade begründen.
A9: Peer-Logik | B9: Ausgangshypothese: C1 Kanton × Grössenklasse plus Richtwerte; C2–C5 ohne Peer.
A10: Zusammenarbeit | B10: A-Daten von Lias und Luucy-/B-Daten von Nikolaos übernehmen, nicht neu erheben.
A11: Datenanfrage | B11: Blatt Gemeindeanfragen enthält pro Pilotgemeinde benötigte Ergänzungen.
A12: Quellenkonvention | B12: Herkunft unterscheidet öffentliche Webrecherche von methodischen Ableitungen aus Aufgabenprofil und Grundlagendokument.
... A22: Konsistenz (Formel) | B22: Soll = Zeilen in der Gesamtübersicht, die zur Gemeinde gehören; Ist = Zeilen im Gemeindeblatt.
A23: Seelisberg | B23: ="Soll "&(COUNTIF('Gesamtübersicht'!$B:$B,"Bund")+COUNTIFS('Gesamtübersicht'!$B:$B,"Kanton",'Gesamtübersicht'!$D:$D,"Uri")+COUNTIFS('Gesamtübersicht'!$B:$B,"Gemeinde",'Gesamtübersicht'!$E:$E,"Seelisberg"))&" / Ist "&(COUNTA('Seelisberg'!$A:$A)-1)&" – "&IF((COUNTIF('Gesamtübersicht'!$B:$B,"Bund")+COUNTIFS('Gesamtübersicht'!$B:$B,"Kanton",'Gesamtübersicht'!$D:$D,"Uri")+COUNTIFS('Gesamtübersicht'!$B:$B,"Gemeinde",'Gesamtübersicht'!$E:$E,"Seelisberg"))=(COUNTA('Seelisberg'!$A:$A)-1),"OK","ABWEICHUNG: Ansicht neu erzeugen")
A24: Münchenstein | B24: ="Soll "&(COUNTIF('Gesamtübersicht'!$B:$B,"Bund")+COUNTIFS('Gesamtübersicht'!$B:$B,"Kanton",'Gesamtübersicht'!$D:$D,"Basel-Landschaft")+COUNTIFS('Gesamtübersicht'!$B:$B,"Gemeinde",'Gesamtübersicht'!$E:$E,"Münchenstein"))&" / Ist "&(COUNTA('Münchenstein'!$A:$A)-1)&" – "&IF((COUNTIF('Gesamtübersicht'!$B:$B,"Bund")+COUNTIFS('Gesamtübersicht'!$B:$B,"Kanton",'Gesamtübersicht'!$D:$D,"Basel-Landschaft")+COUNTIFS('Gesamtübersicht'!$B:$B,"Gemeinde",'Gesamtübersicht'!$E:$E,"Münchenstein"))=(COUNTA('Münchenstein'!$A:$A)-1),"OK","ABWEICHUNG: Ansicht neu erzeugen")
A25: Wil | B25: ="Soll "&(COUNTIF('Gesamtübersicht'!$B:$B,"Bund")+COUNTIFS('Gesamtübersicht'!$B:$B,"Kanton",'Gesamtübersicht'!$D:$D,"St. Gallen")+COUNTIFS('Gesamtübersicht'!$B:$B,"Gemeinde",'Gesamtübersicht'!$E:$E,"Wil"))&" / Ist "&(COUNTA('Wil'!$A:$A)-1)&" – "&IF((COUNTIF('Gesamtübersicht'!$B:$B,"Bund")+COUNTIFS('Gesamtübersicht'!$B:$B,"Kanton",'Gesamtübersicht'!$D:$D,"St. Gallen")+COUNTIFS('Gesamtübersicht'!$B:$B,"Gemeinde",'Gesamtübersicht'!$E:$E,"Wil"))=(COUNTA('Wil'!$A:$A)-1),"OK","ABWEICHUNG: Ansicht neu erzeugen")

Sheet Gesamtübersicht
A1: ID | B1: Ebene | C1: Schweiz | D1: Kanton | E1: Gemeinde | F1: C-Dimension | G1: Themenfeld | H1: Dokument / Datengrundlage | I1: Dokumenttyp | J1: Dokumentstatus | K1: Rechts- / Verbindlichkeitsstatus | L1: Herausgeber / Zuständigkeit | M1: Link / Quelle | N1: Bezugsjahr / Stand | O1: Aktualität geprüft am | P1: Konkrete Aussage / Relevanz | Q1: Kennzahl / Prüfkriterium | R1: Erhebungs- / Bewertungsmethode | S1: Vergleichsmassstab | T1: Reifegrad / Tragfähigkeit | U1: Confidence | V1: Datenlücke / Gemeindeanfrage | W1: Verbindung A / B / Q | X1: Sprint-2-Verwendung | Y1: Prüfstatus / nächste Aktion | Z1: Herkunft / Nachweis | AA1: Weitere C-Dimensionen | AB1: Veröffentlichungsdatum | AC1: Offizielle Fundstelle | AD1: Linkstatus | AE1: HTTP-Status | AF1: Finale URL (nach Weiterleitung) | AG1: Dateityp | AH1: Inhaltsprüfung | AI1: Inhaltsprüfung – Nachweis | AJ1: Erkannter Dokumenttitel | AK1: Erkannte Jahresangaben | AL1: Linkstabilität | AM1: Letzte Linkprüfung | AN1: Quellenverfügbarkeit | AO1: Einheit / Bezugsjahr | AP1: Prüfnachweis (belegbare Aussage) | AQ1: Bewertungsbegründung | AR1: Gemeindeanfrage erforderlich | AS1: Zuständige Stelle | AT1: Bearbeitungsstatus | AU1: Recherchehinweis | AV1: Gleiche Quelle wie (ID) | AW1: Änderungsprotokoll
A2: CH-C1-01 | B2: Bund | C2: Schweiz | D2: Alle | E2: Alle | F2: C1 | G2: Öffentliche Finanzstatistik | H2: Finanzstatistik: Daten der Eidgenössischen Finanzverwaltung | I2: Datenportal | J2: Offizielle Quelle recherchiert | K2: Orientierung / Datengrundlage | L2: Bund | M2: https://www.efv.admin.ch/de/finanzstatistik-daten | N2: Zu prüfen | O2: 2026-10-14 | P2: Harmonisierte Finanzstatistik als Kontext und methodische Vergleichsbasis | Q2: Finanzkennzahlen, Ausgaben, Einnahmen | R2: Zeitreihen und Aufgabenabgrenzung prüfen | S2: Kanton × Grössenklasse; Richtwerte | T2: Noch nicht bewertet | U2: Hoch | W2: A1/A2; C1 | X2: Finanziellen Spielraum und DYN-Korridor plausibilisieren | Y2: Dokument auswerten; Aktualität und Geltung prüfen | Z2: Offizielles Bundesportal; methodische Auswahl | AC2: https://www.efv.admin.ch/ | AD2: Verifiziert | AE2: 200 | AG2: HTML | AH2: Bestätigt | AI2: Schlüsselwörter 1/1 gefunden (Finanzstatistik) | AJ2: Übersicht über die Daten der Finanzstatistik | Übersicht über die Daten der Finanzstatistik | AK2: 2008, 2026, 2025, 2014 | AL2: Mittel (Webseite) | AM2: 2026-10-14 13:53 | AN2: Öffentlich verfügbar und verifiziert | AO2: Zu prüfen | AP2: Belegt Existenz und Zugänglichkeit der Quelle; inhaltliche Aussagen erst nach Auswertung. | AQ2: Keine Einstufung: Kennzahlen/Befunde noch nicht ausgewertet; Schwellen der Bewertungslogik noch nicht validiert. | AR2: Nein | AS2: Bund | AT2: In Prüfung
A3: CH-C1-02 | B3: Bund | C3: Schweiz | D3: Alle | E3: Alle | F3: C1 | G3: Rechnungslegung | H3: EFV: Methodik und Vergleichbarkeit der Finanzstatistik | I3: Methodik | J3: Offizielle Quelle recherchiert | K3: Orientierung / Datengrundlage | L3: Bund | M3: https://www.efv.admin.ch/de/was-ist-die-finanzstatistik | N3: Zu prüfen | O3: 2026-10-14 | P3: Kantonale Aufgabenverteilung begrenzt Vergleichbarkeit | Q3: HRM / Aufgabenabgrenzung | R3: Vergleichbarkeit explizit dokumentieren | S3: Kanton × Grössenklasse | T3: Noch nicht bewertet | U3: Hoch | W3: A1; C1 | X3: Vergleichsregeln absichern | Y3: Dokument auswerten; Aktualität und Geltung prüfen | Z3: Offizielles Bundesportal; methodische Auswahl | AD3: Verifiziert | AE3: 200 | AG3: HTML | AH3: Bestätigt | AI3: Schlüsselwörter 1/1 gefunden (Finanzstatistik) | AJ3: Was ist die Finanzstatistik? | Was ist die Finanzstatistik? | AK3: 2014, 2010, 2026, 2024, 2023, 2025 | AL3: Mittel (Webseite) | AM3: 2026-10-14 13:53 | AN3: Öffentlich verfügbar und verifiziert | AO3: Zu prüfen | AP3: Belegt Existenz und Zugänglichkeit der Quelle; inhaltliche Aussagen erst nach Auswertung. | AQ3: Keine Einstufung: Kennzahlen/Befunde noch nicht ausgewertet; Schwellen der Bewertungslogik noch nicht validiert. | AR3: Nein | AS3: Bund | AT3: In Prüfung
A4: CH-C1-03 | B4: Bund | C4: Schweiz | D4: Alle | E4: Alle | F4: C1 | G4: Finanzstatistik Methode | H4: EFV: Methoden der Finanzstatistik (FS-Modell, HRM2-Zuordnung) | I4: Methodik | J4: Webseite | K4: Methodische Grundlage | L4: Eidgenössische Finanzverwaltung (EFV) | M4: https://www.efv.admin.ch/de/methoden-finanzstatistik | O4: 2026-10-14 | P4: Definitionen der Kennzahlen und HRM2-Abbildung für Vergleichbarkeit | Q4: Kennzahlendefinitionen | S4: Kanton × Grössenklasse | T4: Noch nicht bewertet | U4: Hoch | W4: C1 | X4: Vergleichsregeln C1 | Y4: Dokument auswerten; Aktualität und Geltung prüfen | Z4: Automatische Recherche GitHub Actions (Discovery), Fundstelle siehe Spalte Offizielle Fundstelle | AC4: https://www.efv.admin.ch/de/finanzstatistik-daten | AD4: Verifiziert | AE4: 200 | AG4: HTML | AH4: Bestätigt | AI4: Schlüsselwörter 2/2 gefunden (Methode, Finanzstatistik) | AJ4: Methoden der Finanzstatistik | Methoden der Finanzstatistik | AK4: 2016, 2026, 2015, 2020, 2014, 2025 | AL4: Mittel (Webseite) | AM4: 2026-10-14 13:54 | AN4: Öffentlich verfügbar und verifiziert | AP4: Belegt Existenz und Zugänglichkeit der Quelle; inhaltliche Aussagen erst nach Auswertung. | AQ4: Keine Einstufung: Kennzahlen/Befunde noch nicht ausgewertet; Schwellen der Bewertungslogik noch nicht validiert. | AR4: Nein | AS4: Eidgenössische Finanzverwaltung (EFV) | AT4: In Prüfung | AU4: Früherer PDF-Link zum FS-Methodenband (efv.admin.ch/dam/…) liefert HTTP 502 (Website-Umbau); Methodenseite über EFV-Finanzstatistik ermittelt. | AW4: 2026-10-14: neu aufgenommen
A5: CH-C1-04 | B5: Bund | C5: Schweiz | D5: Alle | E5: Alle | F5: C1 | G5: Finanzdaten Gemeinden | H5: EFV: Detaillierte Daten FS- und GFS-Modell (Open Government Data) | I5: Datensatz | J5: Direktes Dokument | K5: Datengrundlage | L5: EFV / opendata.swiss | M5: https://opendata.swiss/en/dataset/detaillierte-daten-fs-und-gfs-modell-standardauswertungen | O5: 2026-10-14 | P5: Maschinenlesbare Finanzdaten für Peer-Vergleich | Q5: Einnahmen, Ausgaben, Schulden | S5: Kanton × Grössenklasse | T5: Noch nicht bewertet | U5: Mittel | Y5: Dokument auswerten; Aktualität und Geltung prüfen | Z5: Websuche 14.10.2026 (URL im Suchergebnis gefunden) | AD5: Verifiziert | AE5: 200 | AG5: HTML | AH5: Bestätigt | AI5: Schlüsselwörter 2/2 gefunden (FS, GFS) | AJ5: Detailed data FS and GFS model: Regular tables | opendata.swiss | Detailed data FS and GFS model: Regular tables | AK5: 2008, 2025, 2014, 2023 | AL5: Mittel (Webseite) | AM5: 2026-10-14 13:54 | AN5: Öffentlich verfügbar und verifiziert | AP5: Belegt Existenz und Zugänglichkeit der Quelle; inhaltliche Aussagen erst nach Auswertung. | AQ5: Keine Einstufung: Kennzahlen/Befunde noch nicht ausgewertet; Schwellen der Bewertungslogik noch nicht validiert. | AR5: Nein | AS5: EFV / opendata.swiss | AT5: In Prüfung | AW5: 2026-10-14: neu aufgenommen
A6: CH-C2-01 | B6: Bund | C6: Schweiz | D6: Alle | E6: Alle | F6: C2 | G6: Eigentumsrechte | H6: Schweizerisches Zivilgesetzbuch (ZGB) | I6: Bundesgesetz | J6: Offizielle Quelle recherchiert | K6: Bundesgesetz (verbindlich) | L6: Bund | M6: https://www.fedlex.admin.ch/eli/cc/24/233_245_233/de | N6: SR 210, geltende Fassung | O6: 2026-10-14 | P6: Eigentum, Dienstbarkeiten und Baurechte als rechtlicher Rahmen | Q6: Baurecht, Dienstbarkeit, Eigentum | R6: Grundbuch und Verträge gemeindespezifisch prüfen | S6: Kein Peer-Vergleich | T6: Noch nicht bewertet | U6: Hoch | W6: B; Q1 | X6: Bodenmobilisierung / Verfügung prüfen | Y6: Dokument auswerten; Aktualität und Geltung prüfen | Z6: Offizielles Bundesportal; methodische Auswahl | AD6: Verifiziert | AE6: 200 | AG6: HTML | AH6: Bestätigt | AI6: Titel via Fedlex-SPARQL (https://fedlex.data.admin.ch/eli/cc/24/233_245_233); Schlüsselwörter 1/1 gefunden (Zivilgesetzbuch) | AJ6: Schweizerisches Zivilgesetzbuch vom 10. Dezember 1907 (ZGB) | AL6: Hoch (ELI-Permalink) | AM6: 2026-10-14 13:53 | AN6: Öffentlich verfügbar und verifiziert | AO6: SR 210, geltende Fassung | AP6: Belegt Existenz und Zugänglichkeit der Quelle; inhaltliche Aussagen erst nach Auswertung. | AQ6: Keine Einstufung: Kennzahlen/Befunde noch nicht ausgewertet; Schwellen der Bewertungslogik noch nicht validiert. | AR6: Nein | AS6: Bund | AT6: In Prüfung
A7: CH-C2-02 | B7: Bund | C7: Schweiz | D7: Alle | E7: Alle | F7: C2 | G7: Raumplanung / Baulandmobilisierung | H7: Bundesgesetz über die Raumplanung (RPG), SR 700 | I7: Bundesgesetz | J7: Direktes Dokument | K7: Bundesgesetz (verbindlich) | L7: Bund | M7: https://www.fedlex.admin.ch/eli/cc/1979/1573_1573_1573/de | N7: SR 700, geltende Fassung | O7: 2026-10-14 | P7: Art. 15a RPG: Förderung der Verfügbarkeit von Bauland; Mehrwertausgleich Art. 5 | Q7: Bauverpflichtung, Mehrwertabgabe | S7: Kein Peer-Vergleich | T7: Noch nicht bewertet | U7: Hoch | W7: B; Q1 | Y7: Dokument auswerten; Aktualität und Geltung prüfen | Z7: ELI-Permalink Fedlex; Identität per Fedlex-SPARQL geprüft | AD7: Verifiziert | AE7: 200 | AG7: HTML | AH7: Bestätigt | AI7: Titel via Fedlex-SPARQL (https://fedlex.data.admin.ch/eli/cc/1979/1573_1573_1573); Schlüsselwörter 1/1 gefunden (Raumplanung) | AJ7: Bundesgesetz vom 22. Juni 1979 über die Raumplanung (Raumplanungsgesetz, RPG) (RPG) | AL7: Hoch (ELI-Permalink) | AM7: 2026-10-14 13:54 | AN7: Öffentlich verfügbar und verifiziert | AO7: SR 700, geltende Fassung | AP7: Belegt Existenz und Zugänglichkeit der Quelle; inhaltliche Aussagen erst nach Auswertung. | AQ7: Keine Einstufung: Kennzahlen/Befunde noch nicht ausgewertet; Schwellen der Bewertungslogik noch nicht validiert. | AR7: Nein | AS7: Bund | AT7: In Prüfung | AW7: 2026-10-14: neu aufgenommen
A8: CH-C3-01 | B8: Bund | C8: Schweiz | D8: Alle | E8: Alle | F8: C3 | G8: Interkommunale Zusammenarbeit | H8: Bundesverfassung der Schweizerischen Eidgenossenschaft | I8: Bundesverfassung | J8: Offizielle Quelle recherchiert | K8: Bundesverfassung (verbindlich) | L8: Bund | M8: https://www.fedlex.admin.ch/eli/cc/1999/404/de | N8: SR 101, geltende Fassung | O8: 2026-10-14 | P8: Grundlagen von Föderalismus und Gemeindeautonomie; Details kantonal | Q8: Zuständigkeits- und Kooperationsregeln | R8: Kantonale Gemeindeerlasse ergänzen | S8: Qualitative Reifegradskala | T8: Noch nicht bewertet | U8: Hoch | W8: Q6; C4 | X8: Trägerschaft und Kooperation beurteilen | Y8: Dokument auswerten; Aktualität und Geltung prüfen | Z8: Offizielles Bundesportal; methodische Auswahl | AA8: C5 | AD8: Verifiziert | AE8: 200 | AG8: HTML | AH8: Bestätigt | AI8: Titel via Fedlex-SPARQL (https://fedlex.data.admin.ch/eli/cc/1999/404); Schlüsselwörter 1/1 gefunden (Bundesverfassung) | AJ8: Bundesverfassung der Schweizerischen Eidgenossenschaft vom 18. April 1999 (BV) | AL8: Hoch (ELI-Permalink) | AM8: 2026-10-14 13:53 | AN8: Öffentlich verfügbar und verifiziert | AO8: SR 101, geltende Fassung | AP8: Belegt Existenz und Zugänglichkeit der Quelle; inhaltliche Aussagen erst nach Auswertung. | AQ8: Keine Einstufung: Kennzahlen/Befunde noch nicht ausgewertet; Schwellen der Bewertungslogik noch nicht validiert. | AR8: Nein | AS8: Bund | AT8: In Prüfung | AV8: CH-C5-01
A9: CH-C4-01 | B9: Bund | C9: Schweiz | D9: Alle | E9: Alle | F9: C4 | G9: Öffentliche Beschaffung | H9: Bundesgesetz über das öffentliche Beschaffungswesen (BöB) | I9: Bundesgesetz | J9: Offizielle Quelle recherchiert | K9: Bundesgesetz (verbindlich für Bundesbeschaffungen; Gemeinden: IVöB/kantonales Recht) | L9: Bund | M9: https://www.fedlex.admin.ch/eli/cc/2020/126/de | N9: SR 172.056.1, geltende Fassung | O9: 2026-10-14 | P9: Beschaffungsrechtlicher Orientierungsrahmen; kommunale Geltung kantonal prüfen | Q9: Beschaffungsprozess, Zuständigkeit | R9: Kantonales Beschaffungsrecht vorrangig auf Geltung prüfen | S9: Qualitative Reifegradskala | T9: Noch nicht bewertet | U9: Hoch | W9: Q6; C3 | X9: Bestellerkompetenz / Umsetzungsorganisation | Y9: Dokument auswerten; Aktualität und Geltung prüfen | Z9: Offizielles Bundesportal; methodische Auswahl | AD9: Verifiziert | AE9: 200 | AG9: HTML | AH9: Bestätigt | AI9: Titel via Fedlex-SPARQL (https://fedlex.data.admin.ch/eli/cc/2020/126); Schlüsselwörter 1/1 gefunden (öffentliche Beschaffungswesen) | AJ9: Bundesgesetz vom 21. Juni 2019 über das öffentliche Beschaffungswesen (BöB) (BöB) | AK9: 2019 | AL9: Hoch (ELI-Permalink) | AM9: 2026-10-14 13:53 | AN9: Öffentlich verfügbar und verifiziert | AO9: SR 172.056.1, geltende Fassung | AP9: Belegt Existenz und Zugänglichkeit der Quelle; inhaltliche Aussagen erst nach Auswertung. | AQ9: Keine Einstufung: Kennzahlen/Befunde noch nicht ausgewertet; Schwellen der Bewertungslogik noch nicht validiert. | AR9: Nein | AS9: Bund | AT9: In Prüfung
A10: CH-C4-02 | B10: Bund | C10: Schweiz | D10: Alle | E10: Alle | F10: C4 | G10: Gemeindekennzahlen | H10: BFS: Regionalporträts – Kennzahlen aller Gemeinden (Datensatz) | I10: Datensatz | J10: Direktes Dokument | K10: Datengrundlage | L10: Bundesamt für Statistik (BFS) | M10: https://ckan.opendata.swiss/dataset/regionalportrats-2021-kennzahlen-aller-gemeinden | N10: 2021 (neuere Ausgabe prüfen) | O10: 2026-10-14 | P10: Strukturdaten (Einwohner, Fläche) zur Bildung der Grössenklassen | S10: Grössenklasse | T10: Noch nicht bewertet | U10: Mittel | Y10: Dokument auswerten; Aktualität und Geltung prüfen | Z10: Websuche 14.10.2026 (URL im Suchergebnis gefunden) | AA10: C1 | AD10: Verifiziert | AE10: 200 | AG10: HTML | AH10: Bestätigt | AI10: Schlüsselwörter 1/1 gefunden (Regionalporträts) | AJ10: Regional portraits 2021: key data of all communes - Dataset - opendata.swiss | Regional portraits 2021: key data of all communes | AK10: 2021, 2019, 2004 | AL10: Mittel (Webseite) | AM10: 2026-10-14 13:54 | AN10: Öffentlich verfügbar und verifiziert | AO10: 2021 (neuere Ausgabe prüfen) | AP10: Belegt Existenz und Zugänglichkeit der Quelle; inhaltliche Aussagen erst nach Auswertung. | AQ10: Keine Einstufung: Kennzahlen/Befunde noch nicht ausgewertet; Schwellen der Bewertungslogik noch nicht validiert. | AR10: Nein | AS10: Bundesamt für Statistik (BFS) | AT10: In Prüfung | AU10: Ausgabe 2021; aktuelle Ausgabe beim BFS prüfen. | AW10: 2026-10-14: neu aufgenommen
A11: CH-C5-01 | B11: Bund | C11: Schweiz | D11: Alle | E11: Alle | F11: C5 | G11: Politische Rechte | H11: Bundesverfassung der Schweizerischen Eidgenossenschaft | I11: Bundesverfassung | J11: Offizielle Quelle recherchiert | K11: Bundesverfassung (verbindlich) | L11: Bund | M11: https://www.fedlex.admin.ch/eli/cc/1999/404/de | N11: SR 101, geltende Fassung | O11: 2026-10-14 | P11: Demokratische Grundrechte und Beteiligung; konkrete kommunale Verfahren kantonal | Q11: Mitwirkung / Legitimation | R11: Kommunale und kantonale Bestimmungen ergänzen | S11: Qualitative Reifegradskala | T11: Noch nicht bewertet | U11: Hoch | W11: Q1; C3 | X11: Politische Machbarkeit | Y11: Dokument auswerten; Aktualität und Geltung prüfen | Z11: Offizielles Bundesportal; methodische Auswahl | AA11: C3 | AD11: Verifiziert | AE11: 200 | AG11: HTML | AH11: Bestätigt | AI11: Titel via Fedlex-SPARQL (https://fedlex.data.admin.ch/eli/cc/1999/404); Schlüsselwörter 1/1 gefunden (Bundesverfassung) | AJ11: Bundesverfassung der Schweizerischen Eidgenossenschaft vom 18. April 1999 (BV) | AL11: Hoch (ELI-Permalink) | AM11: 2026-10-14 13:53 | AN11: Öffentlich verfügbar und verifiziert | AO11: SR 101, geltende Fassung | AP11: Belegt Existenz und Zugänglichkeit der Quelle; inhaltliche Aussagen erst nach Auswertung. | AQ11: Keine Einstufung: Kennzahlen/Befunde noch nicht ausgewertet; Schwellen der Bewertungslogik noch nicht validiert. | AR11: Nein | AS11: Bund | AT11: In Prüfung | AU11: Gleiche Quelle wie CH-C3-01; bewusst doppelt geführt (Zuordnung C5 politische Rechte). | AV11: CH-C3-01
A12: UR-C1-01 | B12: Kanton | C12: Schweiz | D12: Uri | E12: Alle | F12: C1 | G12: Finanzstatistik | H12: Gemeindefinanzstatistik Uri | I12: Statistik | J12: Offizielle Quelle recherchiert | K12: Orientierung / Datengrundlage | L12: Kanton Uri | M12: https://www.ur.ch/publikationen/6680 | N12: Zu prüfen | O12: 2026-10-14 | P12: Kennzahlen aller Urner Gemeinden | Q12: Selbstfinanzierung, Verschuldung, Investitionen | R12: Jahreswerte für Seelisberg extrahieren | S12: Kanton × Grössenklasse / Richtwerte | T12: Noch nicht bewertet | U12: Mittel | V12: Geltende kantonale Detailgrundlage und Datenstand prüfen | W12: A1; C1 | X12: Finanztragfähigkeit | Y12: Dokument auswerten; Aktualität und Geltung prüfen | Z12: Webrecherche 14.10.2026 | AD12: Verifiziert | AE12: 200 | AG12: HTML | AH12: Bestätigt | AI12: Schlüsselwörter 1/1 gefunden (Gemeindefinanzstatistik); Ort/Zuständigkeit: Uri | AJ12: Kanton Uri - Gemeindefinanzstatistik | Kontakt | AK12: 2023, 2025, 2026, 2024, 2022, 2021 | AL12: Mittel (CMS-Dokumentlink) | AM12: 2026-10-14 13:53 | AN12: Öffentlich verfügbar und verifiziert | AO12: Zu prüfen | AP12: Belegt Existenz und Zugänglichkeit der Quelle; inhaltliche Aussagen erst nach Auswertung. | AQ12: Keine Einstufung: Kennzahlen/Befunde noch nicht ausgewertet; Schwellen der Bewertungslogik noch nicht validiert. | AR12: Nein | AS12: Kanton Uri | AT12: In Prüfung
A13: UR-C1-02 | B13: Kanton | C13: Schweiz | D13: Uri | E13: Alle | F13: C1 | G13: Steuerkraft | H13: Steuerstatistiken Kanton Uri | I13: Statistik | J13: Offizielle Quelle recherchiert | K13: Orientierung / Datengrundlage | L13: Kanton Uri | M13: https://www.ur.ch/finanzen/1588 | N13: Zu prüfen | O13: 2026-10-14 | P13: Steuerbasis als Kontext zur Finanzkraft | Q13: Steuerbares Einkommen und Vermögen | R13: Lias-Daten übernehmen, nicht neu erheben | S13: Kanton × Grössenklasse | T13: Noch nicht bewertet | U13: Mittel | V13: Geltende kantonale Detailgrundlage und Datenstand prüfen | W13: A1/A2 | X13: DYN-Finanzkontext | Y13: Dokument auswerten; Aktualität und Geltung prüfen | Z13: Webrecherche 14.10.2026 | AD13: Verifiziert | AE13: 200 | AG13: HTML | AH13: Bestätigt | AI13: Schlüsselwörter 1/1 gefunden (Steuerstatistik); Ort/Zuständigkeit: Uri | AJ13: Kanton Uri - Steuerstatistiken | Kontakt | AK13: 2009, 2010, 2011, 2012, 2013, 2014 | AL13: Mittel (Webseite) | AM13: 2026-10-14 13:53 | AN13: Öffentlich verfügbar und verifiziert | AO13: Zu prüfen | AP13: Belegt Existenz und Zugänglichkeit der Quelle; inhaltliche Aussagen erst nach Auswertung. | AQ13: Keine Einstufung: Kennzahlen/Befunde noch nicht ausgewertet; Schwellen der Bewertungslogik noch nicht validiert. | AR13: Nein | AS13: Kanton Uri | AT13: In Prüfung
A14: UR-C1-03 | B14: Kanton | C14: Schweiz | D14: Uri | E14: Alle | F14: C1 | G14: Finanzkennzahlen Gemeinden | H14: Kennzahlen Einwohnergemeinden Uri 2025 (Finanzkontrolle) | I14: Statistik / Bericht | J14: Direktes Dokument | K14: Datengrundlage | L14: Kanton Uri, Finanzkontrolle | M14: https://www.ur.ch/_doc/451636 | N14: Rechnungsjahr 2025 (publ. 2026) | O14: 2026-10-14 | P14: Kennzahlen je Urner Gemeinde inkl. Seelisberg (Selbstfinanzierung, Kapitaldienst) | Q14: Selbstfinanzierungsanteil, Kapitaldienstanteil, Steuern/Kopf | S14: Kanton × Grössenklasse | T14: Noch nicht bewertet | U14: Hoch | W14: A1; C1 | X14: Finanztragfähigkeit Seelisberg im Kantonsvergleich | Y14: Dokument auswerten; Aktualität und Geltung prüfen | Z14: Websuche 14.10.2026 (URL im Suchergebnis gefunden) | AC14: https://www.ur.ch/publikationen/6680 | AD14: Weiterleitung | AE14: 200 | AF14: https://www.ur.ch/_docn/451636/Gemeindekennzahlen_2025_signiert.pdf | AG14: PDF | AH14: Bestätigt | AI14: Schlüsselwörter 2/2 gefunden (Kennzahlen, Seelisberg); Ort/Zuständigkeit: Uri | AJ14: Microsoft Word - Brief Versand Kennzahlen.docx | AK14: 2025, 2026, 2013, 2019, 2024 | AL14: Mittel (Webseite) | AM14: 2026-10-14 13:54 | AN14: Öffentlich verfügbar und verifiziert | AO14: Rechnungsjahr 2025 (publ. 2026) | AP14: Belegt Existenz und Zugänglichkeit der Quelle; inhaltliche Aussagen erst nach Auswertung. | AQ14: Keine Einstufung: Kennzahlen/Befunde noch nicht ausgewertet; Schwellen der Bewertungslogik noch nicht validiert. | AR14: Nein | AS14: Kanton Uri, Finanzkontrolle | AT14: In Prüfung | AW14: 2026-10-14: neu aufgenommen
A15: UR-C1-04 | B15: Kanton | C15: Schweiz | D15: Uri | E15: Alle | F15: C1 | G15: Finanzkennzahlen Gemeinden | H15: Kennzahlen Einwohnergemeinden Uri 2024 (Finanzkontrolle) | I15: Statistik / Bericht | J15: Direktes Dokument | K15: Datengrundlage | L15: Kanton Uri, Finanzkontrolle | M15: https://www.ur.ch/_doc/420775 | N15: Rechnungsjahr 2024 | O15: 2026-10-14 | P15: Vorjahreswerte für Zeitreihe | Q15: wie UR-C1-03 | S15: Kanton × Grössenklasse | T15: Noch nicht bewertet | U15: Hoch | Y15: Dokument auswerten; Aktualität und Geltung prüfen | Z15: Websuche 14.10.2026 (URL im Suchergebnis gefunden) | AC15: https://www.ur.ch/publikationen/6680 | AD15: Weiterleitung | AE15: 200 | AF15: https://www.ur.ch/_docn/420775/Gemeindekennzahlen_2024_signiert.pdf | AG15: PDF | AH15: Bestätigt | AI15: Schlüsselwörter 2/2 gefunden (Kennzahlen, Seelisberg); Ort/Zuständigkeit: Uri | AJ15: Gemeindekennzahlen 2024_final.xlsx | AK15: 2024, 2025, 2013, 2018 | AL15: Mittel (Webseite) | AM15: 2026-10-14 13:54 | AN15: Öffentlich verfügbar und verifiziert | AO15: Rechnungsjahr 2024 | AP15: Belegt Existenz und Zugänglichkeit der Quelle; inhaltliche Aussagen erst nach Auswertung. | AQ15: Keine Einstufung: Kennzahlen/Befunde noch nicht ausgewertet; Schwellen der Bewertungslogik noch nicht validiert. | AR15: Nein | AS15: Kanton Uri, Finanzkontrolle | AT15: In Prüfung | AW15: 2026-10-14: neu aufgenommen
A16: UR-C1-05 | B16: Kanton | C16: Schweiz | D16: Uri | E16: Alle | F16: C1 | G16: Rechnungslegung Gemeinden | H16: Reglement über das Rechnungswesen der Einwohnergemeinden (RRE), RB 3.2115 | I16: Kantonales Reglement | J16: Direktes Dokument | K16: Kantonales Recht (verbindlich) | L16: Regierungsrat Uri | M16: https://rechtsbuch.ur.ch/api/de/versions/776/pdf_file | N16: Version 776 (Stand prüfen) | O16: 2026-10-14 | P16: Rechtsgrundlage HRM2 und kantonale Finanzaufsicht über Gemeinden (Uri kennt kein separates FHGG) | S16: Kanton × Grössenklasse | T16: Noch nicht bewertet | U16: Hoch | Y16: Dokument auswerten; Aktualität und Geltung prüfen | Z16: Websuche 14.10.2026 (URL im Suchergebnis gefunden) | AC16: https://www.ur.ch/dienstleistungen/3150 | AD16: Verifiziert | AE16: 200 | AG16: PDF | AH16: Bestätigt | AI16: Schlüsselwörter 2/2 gefunden (Rechnungswesen, Einwohnergemeinden) | AJ16: 3.2115 - Reglement über das Rechnungswesen der Einwohnergemeinden | AK16: 2010, 2021, 2009, 2008 | AL16: Hoch (Erlassnummer) | AM16: 2026-10-14 13:54 | AN16: Öffentlich verfügbar und verifiziert | AO16: Version 776 (Stand prüfen) | AP16: Belegt Existenz und Zugänglichkeit der Quelle; inhaltliche Aussagen erst nach Auswertung. | AQ16: Keine Einstufung: Kennzahlen/Befunde noch nicht ausgewertet; Schwellen der Bewertungslogik noch nicht validiert. | AR16: Nein | AS16: Regierungsrat Uri | AT16: In Prüfung | AU16: Versions-PDF: prüfen, ob dies die geltende Fassung ist. | AW16: 2026-10-14: neu aufgenommen
A17: UR-C1-06 | B17: Kanton | C17: Schweiz | D17: Uri | E17: Alle | F17: C1 | G17: Finanzausgleich | H17: Gesetz über den Finanz- und Lastenausgleich zwischen dem Kanton und den Gemeinden (FiLaG), RB 3.2131 | I17: Kantonales Gesetz | J17: Direktes Dokument | K17: Kantonales Recht (verbindlich) | L17: Kanton Uri | M17: https://rechtsbuch.ur.ch/app/de/texts_of_law/3.2131 | N17: geltende Fassung | O17: 2026-10-14 | P17: Art. 22: Sonderbeitrag an Seelisberg (Abgeschiedenheit); Ressourcen- und Lastenausgleich | Q17: Ausgleichszahlungen | S17: Kanton × Grössenklasse | T17: Noch nicht bewertet | U17: Hoch | Y17: Dokument auswerten; Aktualität und Geltung prüfen | Z17: URL nach dokumentiertem Schema der amtlichen Rechtssammlung gebildet; Identität per Runner geprüft | AD17: Verifiziert | AE17: 200 | AG17: HTML | AH17: Bestätigt | AI17: Titel via LexWork-API (https://rechtsbuch.ur.ch/api/de/texts_of_law/3.2131); Schlüsselwörter 1/1 gefunden (Lastenausgleich) | AJ17: Gesetz über den Finanz- und Lastenausgleich zwischen dem Kanton und den Gemeinden | AK17: 2007, 2026, 2025, 2008 | AL17: Hoch (Erlassnummer) | AM17: 2026-10-14 13:54 | AN17: Öffentlich verfügbar und verifiziert | AO17: geltende Fassung | AP17: Belegt Existenz und Zugänglichkeit der Quelle; inhaltliche Aussagen erst nach Auswertung. | AQ17: Keine Einstufung: Kennzahlen/Befunde noch nicht ausgewertet; Schwellen der Bewertungslogik noch nicht validiert. | AR17: Nein | AS17: Kanton Uri | AT17: In Prüfung | AW17: 2026-10-14: neu aufgenommen
A18: UR-C1-07 | B18: Kanton | C18: Schweiz | D18: Uri | E18: Alle | F18: C1 | G18: Finanzausgleich | H18: Finanz- und Lastenausgleich (FiLa) 2025 – Berechnung je Gemeinde | I18: Berechnungstabelle | J18: Direktes Dokument | K18: Datengrundlage | L18: Kanton Uri, Finanzdirektion | M18: https://www.ur.ch/_docn/426685/Berechnung_FiLa_2025.pdf | N18: 2025 | O18: 2026-10-14 | P18: Höhe der Ausgleichszahlungen an Seelisberg | Q18: Ressourcenausgleich, Lastenausgleich CHF | S18: Kanton × Grössenklasse | T18: Noch nicht bewertet | U18: Hoch | Y18: Dokument auswerten; Aktualität und Geltung prüfen | Z18: Websuche 14.10.2026 (URL im Suchergebnis gefunden) | AD18: Verifiziert | AE18: 200 | AG18: PDF | AH18: Bestätigt | AI18: Schlüsselwörter 2/2 gefunden (2025, Seelisberg); Ort/Zuständigkeit: Uri | AJ18: FINANZDIREKTION Beilage 2 | AK18: 2025, 2024, 2023, 2021, 2015, 2008 | AL18: Mittel (CMS-Dokumentlink) | AM18: 2026-10-14 13:54 | AN18: Öffentlich verfügbar und verifiziert | AO18: 2025 | AP18: Belegt Existenz und Zugänglichkeit der Quelle; inhaltliche Aussagen erst nach Auswertung. | AQ18: Keine Einstufung: Kennzahlen/Befunde noch nicht ausgewertet; Schwellen der Bewertungslogik noch nicht validiert. | AR18: Nein | AS18: Kanton Uri, Finanzdirektion | AT18: In Prüfung | AW18: 2026-10-14: neu aufgenommen
A19: UR-C2-01 | B19: Kanton | C19: Schweiz | D19: Uri | E19: Alle | F19: C2 | G19: Geodaten / Eigentum | H19: Geoportal Uri: Liegenschaften und Nutzungsplanung | I19: Geodatenportal | J19: Offizielle Quelle recherchiert | K19: Orientierung / Datengrundlage | L19: Kanton Uri | M19: https://geo.ur.ch/ | N19: Zu prüfen | O19: 2026-10-14 | P19: Räumliche Parzellenstruktur; kein Nachweis kommunalen Eigentums | Q19: Parzellen, ÖBA-Zonen | R19: Luucy übernehmen, Eigentum separat belegen | S19: Kein Peer | T19: Noch nicht bewertet | U19: Mittel | V19: Geltende kantonale Detailgrundlage und Datenstand prüfen | W19: B; Q1 | X19: Bodenpotenzial | Y19: Dokument auswerten; Aktualität und Geltung prüfen | Z19: Webrecherche 14.10.2026 | AD19: Verifiziert | AE19: 200 | AG19: HTML | AH19: Bestätigt | AI19: Schlüsselwörter 1/1 gefunden (Geo); Ort/Zuständigkeit: geo.ur | AJ19: geo.ur | AL19: Mittel (Startseite, kein Dokument) | AM19: 2026-10-14 13:53 | AN19: Öffentlich verfügbar und verifiziert | AO19: Zu prüfen | AP19: Belegt Existenz und Zugänglichkeit der Quelle; inhaltliche Aussagen erst nach Auswertung. | AQ19: Keine Einstufung: Kennzahlen/Befunde noch nicht ausgewertet; Schwellen der Bewertungslogik noch nicht validiert. | AR19: Nein | AS19: Kanton Uri | AT19: In Prüfung | AU19: Kartenportal (JavaScript); Inhaltsprüfung nur eingeschränkt möglich. Kein Eigentumsnachweis.
A20: UR-C2-02 | B20: Kanton | C20: Schweiz | D20: Uri | E20: Alle | F20: C2 | G20: Raumplanung / Baulandmobilisierung | H20: Planungs- und Baugesetz (PBG) des Kantons Uri, RB 40.1111 | I20: Kantonales Gesetz | J20: Direktes Dokument | K20: Kantonales Recht (verbindlich) | L20: Kanton Uri | M20: https://rechtsbuch.ur.ch/app/de/texts_of_law/40.1111 | N20: geltende Fassung | O20: 2026-10-14 | P20: Bauverpflichtung/Baulandmobilisierung, Mehrwertausgleich | S20: Kein Peer-Vergleich | T20: Noch nicht bewertet | U20: Hoch | W20: B; Q1 | Y20: Dokument auswerten; Aktualität und Geltung prüfen | Z20: Websuche 14.10.2026 (URL im Suchergebnis gefunden) | AD20: Verifiziert | AE20: 200 | AG20: HTML | AH20: Bestätigt | AI20: Titel via LexWork-API (https://rechtsbuch.ur.ch/api/de/texts_of_law/40.1111); Schlüsselwörter 1/1 gefunden (Planungs) | AJ20: Planungs- und Baugesetz | AK20: 2010, 2022, 2012, 2021 | AL20: Hoch (Erlassnummer) | AM20: 2026-10-14 13:54 | AN20: Öffentlich verfügbar und verifiziert | AO20: geltende Fassung | AP20: Belegt Existenz und Zugänglichkeit der Quelle; inhaltliche Aussagen erst nach Auswertung. | AQ20: Keine Einstufung: Kennzahlen/Befunde noch nicht ausgewertet; Schwellen der Bewertungslogik noch nicht validiert. | AR20: Nein | AS20: Kanton Uri | AT20: In Prüfung | AW20: 2026-10-14: neu aufgenommen
A21: UR-C2-03 | B21: Kanton | C21: Schweiz | D21: Uri | E21: Alle | F21: C2 | G21: Bauland | H21: Kanton Uri: Baulanddatenbank (unbebaute Bauzonen, Raum+) | I21: Datenbank / Webseite | J21: Webseite | K21: Information | L21: Kanton Uri, Amt für Raumentwicklung | M21: https://www.ur.ch/dienstleistungen/4297 | O21: 2026-10-14 | P21: Unüberbaute Bauzonenreserven; kein Nachweis kommunalen Eigentums | S21: Kein Peer-Vergleich | T21: Noch nicht bewertet | U21: Mittel | Y21: Dokument auswerten; Aktualität und Geltung prüfen | Z21: Websuche 14.10.2026 (URL im Suchergebnis gefunden) | AD21: Verifiziert | AE21: 200 | AG21: HTML | AH21: Bestätigt | AI21: Schlüsselwörter 1/1 gefunden (Bauland); Ort/Zuständigkeit: Uri | AJ21: Kanton Uri - Baulanddatenbank | Kontakt | AK21: 2030, 2023, 2025, 2027, 2026 | AL21: Mittel (Webseite) | AM21: 2026-10-14 13:54 | AN21: Öffentlich verfügbar und verifiziert | AP21: Belegt Existenz und Zugänglichkeit der Quelle; inhaltliche Aussagen erst nach Auswertung. | AQ21: Keine Einstufung: Kennzahlen/Befunde noch nicht ausgewertet; Schwellen der Bewertungslogik noch nicht validiert. | AR21: Nein | AS21: Kanton Uri, Amt für Raumentwicklung | AT21: In Prüfung | AW21: 2026-10-14: neu aufgenommen
A22: UR-C3-01 | B22: Kanton | C22: Schweiz | D22: Uri | E22: Alle | F22: C3 | G22: Gemeinderecht | H22: Gemeindegesetz (GEG) des Kantons Uri, RB 1.1111 | I22: Kantonales Gesetz | J22: Offizielle Quelle recherchiert | K22: Kantonales Gesetz (verbindlich) | L22: Kanton Uri | M22: https://rechtsbuch.ur.ch/app/de/texts_of_law/1.1111 | N22: vom 21.5.2017; geltende Fassung | O22: 2026-10-14 | P22: Gemeinderechtliche Grundlagen und Zuständigkeiten recherchieren | Q22: Zuständigkeiten / Kooperation | R22: Konkrete Erlasse und geltende Fassung identifizieren | S22: Qualitativ | T22: Noch nicht bewertet | U22: Mittel | V22: Geltende kantonale Detailgrundlage und Datenstand prüfen | W22: Q6; C5 | X22: Governance | Y22: Dokument auswerten; Aktualität und Geltung prüfen | Z22: URL nach dokumentiertem Schema der amtlichen Rechtssammlung gebildet; Identität per Runner geprüft | AD22: Verifiziert | AE22: 200 | AG22: HTML | AH22: Bestätigt | AI22: Titel via LexWork-API (https://rechtsbuch.ur.ch/api/de/texts_of_law/1.1111); Schlüsselwörter 1/1 gefunden (Gemeindegesetz) | AJ22: Gemeindegesetz | AK22: 2017, 2026, 2025 | AL22: Hoch (Erlassnummer) | AM22: 2026-10-14 13:53 | AN22: Öffentlich verfügbar und verifiziert | AO22: vom 21.5.2017; geltende Fassung | AP22: Belegt Existenz und Zugänglichkeit der Quelle; inhaltliche Aussagen erst nach Auswertung. | AQ22: Keine Einstufung: Kennzahlen/Befunde noch nicht ausgewertet; Schwellen der Bewertungslogik noch nicht validiert. | AR22: Nein | AS22: Kanton Uri | AT22: In Prüfung | AW22: 2026-10-14: Link ersetzt (vorher https://rechtsbuch.ur.ch/). Grund: Startseite der Rechtssammlung durch direkten Erlass ersetzt (Gemeindegesetz, RB 1.1111).
A23: UR-C3-02 | B23: Kanton | C23: Schweiz | D23: Uri | E23: Alle | F23: C3 | G23: Kantonsverfassung | H23: Verfassung des Kantons Uri, RB 1.1101 | I23: Kantonsverfassung | J23: Direktes Dokument | K23: Kantonales Recht (verbindlich) | L23: Kanton Uri | M23: https://rechtsbuch.ur.ch/app/de/texts_of_law/1.1101 | N23: vom 28.10.1984; geltende Fassung | O23: 2026-10-14 | P23: Gemeindeautonomie; Art. 58 Finanzplanung der Gemeinden; Art. 110 Rechtsetzung Gemeinden | S23: Kein Peer-Vergleich | T23: Noch nicht bewertet | U23: Hoch | Y23: Dokument auswerten; Aktualität und Geltung prüfen | Z23: URL nach dokumentiertem Schema der amtlichen Rechtssammlung gebildet; Identität per Runner geprüft | AA23: C1, C5 | AD23: Verifiziert | AE23: 200 | AG23: HTML | AH23: Bestätigt | AI23: Titel via LexWork-API (https://rechtsbuch.ur.ch/api/de/texts_of_law/1.1101); Schlüsselwörter 1/1 gefunden (Verfassung) | AJ23: Verfassung des Kantons Uri | AK23: 2023, 2018 | AL23: Hoch (Erlassnummer) | AM23: 2026-10-14 13:54 | AN23: Öffentlich verfügbar und verifiziert | AO23: vom 28.10.1984; geltende Fassung | AP23: Belegt Existenz und Zugänglichkeit der Quelle; inhaltliche Aussagen erst nach Auswertung. | AQ23: Keine Einstufung: Kennzahlen/Befunde noch nicht ausgewertet; Schwellen der Bewertungslogik noch nicht validiert. | AR23: Nein | AS23: Kanton Uri | AT23: In Prüfung | AW23: 2026-10-14: neu aufgenommen
A24: UR-C4-01 | B24: Kanton | C24: Schweiz | D24: Uri | E24: Alle | F24: C4 | G24: Verwaltung | H24: Kanton Uri: Submissionsrecht (IVöB 2019, in Kraft seit 1.6.2023) | I24: Behördeninformation | J24: Offizielle Quelle recherchiert | K24: Information zu verbindlichem Recht | L24: Kanton Uri | M24: https://www.ur.ch/dienstleistungen/8444 | N24: Zu prüfen | O24: 2026-10-14 | P24: Rahmenbedingungen und interkommunale Aufgaben | Q24: Verwaltungsaufgaben / Organisation | R24: Gemeindespezifische Unterlagen ergänzen | S24: Qualitativ | T24: Noch nicht bewertet | U24: Mittel | V24: Geltende kantonale Detailgrundlage und Datenstand prüfen | W24: C3; Q6 | X24: Verwaltungskapazität | Y24: Dokument auswerten; Aktualität und Geltung prüfen | Z24: Webrecherche 14.10.2026 | AD24: Verifiziert | AE24: 200 | AG24: HTML | AH24: Bestätigt | AI24: Schlüsselwörter 1/1 gefunden (Submission); Ort/Zuständigkeit: Uri | AJ24: Kanton Uri - Submissionsrecht | Kontakt | AK24: 2023, 2030, 2025, 2027, 2026 | AL24: Mittel (Webseite) | AM24: 2026-10-14 13:53 | AN24: Öffentlich verfügbar und verifiziert | AO24: Zu prüfen | AP24: Belegt Existenz und Zugänglichkeit der Quelle; inhaltliche Aussagen erst nach Auswertung. | AQ24: Keine Einstufung: Kennzahlen/Befunde noch nicht ausgewertet; Schwellen der Bewertungslogik noch nicht validiert. | AR24: Nein | AS24: Kanton Uri | AT24: In Prüfung | AW24: 2026-10-14: Link ersetzt (vorher https://www.ur.ch/). Grund: Allgemeine Startseite ur.ch durch themenspezifische Seite zum Beschaffungsrecht ersetzt.
A25: UR-C4-02 | B25: Kanton | C25: Schweiz | D25: Uri | E25: Alle | F25: C4 | G25: Beschaffung | H25: Interkantonale Vereinbarung über das öffentliche Beschaffungswesen (IVöB 2019), RB 3.3111 | I25: Interkantonales Recht | J25: Direktes Dokument | K25: Interkantonales Recht (verbindlich) | L25: Kanton Uri | M25: https://rechtsbuch.ur.ch/app/de/texts_of_law/3.3111 | O25: 2026-10-14 | P25: Beschaffungsrecht für Gemeinden (Schwellenwerte, Verfahren) | S25: Kein Peer-Vergleich | T25: Noch nicht bewertet | U25: Hoch | Y25: Dokument auswerten; Aktualität und Geltung prüfen | Z25: URL nach dokumentiertem Schema der amtlichen Rechtssammlung gebildet; Identität per Runner geprüft | AD25: Verifiziert | AE25: 200 | AG25: HTML | AH25: Bestätigt | AI25: Titel via LexWork-API (https://rechtsbuch.ur.ch/api/de/texts_of_law/3.3111); Schlüsselwörter 1/1 gefunden (Beschaffungswesen) | AJ25: Interkantonale Vereinbarung über das öffentliche Beschaffungswesen | AK25: 2023, 2019 | AL25: Hoch (Erlassnummer) | AM25: 2026-10-14 13:54 | AN25: Öffentlich verfügbar und verifiziert | AP25: Belegt Existenz und Zugänglichkeit der Quelle; inhaltliche Aussagen erst nach Auswertung. | AQ25: Keine Einstufung: Kennzahlen/Befunde noch nicht ausgewertet; Schwellen der Bewertungslogik noch nicht validiert. | AR25: Nein | AS25: Kanton Uri | AT25: In Prüfung | AW25: 2026-10-14: neu aufgenommen
A26: UR-C5-01 | B26: Kanton | C26: Schweiz | D26: Uri | E26: Alle | F26: C5 | G26: Politische Rechte | H26: Gesetz über die geheimen Wahlen, Abstimmungen und die Volksrechte (WAVG), RB 2.1201 | I26: Kantonales Gesetz | J26: Offizielle Quelle recherchiert | K26: Kantonales Gesetz (verbindlich) | L26: Kanton Uri | M26: https://rechtsbuch.ur.ch/app/de/texts_of_law/2.1201 | N26: geltende Fassung; Revision hängig (Synopse 2026) | O26: 2026-10-14 | P26: Rechtsrahmen für kommunale Entscheidungen | Q26: Referendum / Zuständigkeiten | R26: Gemeindeordnung konkret prüfen | S26: Qualitativ | T26: Noch nicht bewertet | U26: Mittel | V26: Geltende kantonale Detailgrundlage und Datenstand prüfen | W26: C3; Q1 | X26: Politische Tragfähigkeit | Y26: Dokument auswerten; Aktualität und Geltung prüfen | Z26: URL nach dokumentiertem Schema der amtlichen Rechtssammlung gebildet; Identität per Runner geprüft | AD26: Verifiziert | AE26: 200 | AG26: HTML | AH26: Bestätigt | AI26: Titel via LexWork-API (https://rechtsbuch.ur.ch/api/de/texts_of_law/2.1201); Schlüsselwörter 1/1 gefunden (Wahlen) | AJ26: Gesetz über die geheimen Wahlen, Abstimmungen und die Volksrechte | AK26: 2010, 2009 | AL26: Hoch (Erlassnummer) | AM26: 2026-10-14 13:53 | AN26: Öffentlich verfügbar und verifiziert | AO26: geltende Fassung; Revision hängig (Synopse 2026) | AP26: Belegt Existenz und Zugänglichkeit der Quelle; inhaltliche Aussagen erst nach Auswertung. | AQ26: Keine Einstufung: Kennzahlen/Befunde noch nicht ausgewertet; Schwellen der Bewertungslogik noch nicht validiert. | AR26: Nein | AS26: Kanton Uri | AT26: In Prüfung | AW26: 2026-10-14: Link ersetzt (vorher https://rechtsbuch.ur.ch/). Grund: Startseite der Rechtssammlung durch direkten Erlass ersetzt (WAVG, RB 2.1201).
A27: BL-C1-01 | B27: Kanton | C27: Schweiz | D27: Basel-Landschaft | E27: Alle | F27: C1 | G27: Gemeindefinanzen | H27: Statistik Basel-Landschaft: Gemeindefinanzen / Finanzausgleich | I27: Statistik | J27: Offizielle Quelle recherchiert | K27: Orientierung / Datengrundlage | L27: Kanton Basel-Landschaft | M27: https://statistik.bl.ch/web_portal/18_5 | N27: Zu prüfen | O27: 2026-10-14 | P27: Finanz- und Finanzausgleichsdaten nach Gemeinde | Q27: Finanzausgleich, Finanzkennzahlen | R27: Münchenstein herausfiltern | S27: Kanton × Grössenklasse | T27: Noch nicht bewertet | U27: Mittel | V27: Geltende kantonale Detailgrundlage und Datenstand prüfen | W27: A1; C1 | X27: Finanztragfähigkeit | Y27: Dokument auswerten; Aktualität und Geltung prüfen | Z27: Webrecherche 14.10.2026 | AD27: Verifiziert | AE27: 200 | AG27: HTML | AH27: Bestätigt | AI27: Schlüsselwörter 1/1 gefunden (Gemeindefinanzen); Ort/Zuständigkeit: Basel-Landschaft, Baselland | AJ27: Statistik Baselland | AK27: 2026, 2025, 2024, 2023, 2022, 2021 | AL27: Mittel (Webseite) | AM27: 2026-10-14 13:53 | AN27: Öffentlich verfügbar und verifiziert | AO27: Zu prüfen | AP27: Belegt Existenz und Zugänglichkeit der Quelle; inhaltliche Aussagen erst nach Auswertung. | AQ27: Keine Einstufung: Kennzahlen/Befunde noch nicht ausgewertet; Schwellen der Bewertungslogik noch nicht validiert. | AR27: Nein | AS27: Kanton Basel-Landschaft | AT27: In Prüfung
A28: BL-C1-02 | B28: Kanton | C28: Schweiz | D28: Basel-Landschaft | E28: Alle | F28: C1 | G28: Rechnungslegung | H28: Gemeindefinanzen BL: Rechnungslegung und Excel-Vorlagen | I28: Arbeitshilfe | J28: Offizielle Quelle recherchiert | K28: Orientierung / Datengrundlage | L28: Kanton Basel-Landschaft | M28: https://www.baselland.ch/politik-und-behorden/gemeinden/gemeindefinanzen/rechnungslegung-einwohnergemeinden/excel-vorlagen | N28: Zu prüfen | O28: 14.10.2026 | P28: HRM2-Struktur, Bilanz und Investitionsrechnung | Q28: Investitionen / Bilanz | R28: Jahresrechnung nach einheitlichem Raster auswerten | S28: Kanton × Grössenklasse | T28: Noch nicht bewertet | U28: Mittel | V28: Geltende kantonale Detailgrundlage und Datenstand prüfen | W28: C1 | X28: Vergleichbarkeit | Y28: Dokument auswerten; Aktualität und Geltung prüfen | Z28: Webrecherche 14.10.2026 | AD28: Nicht prüfbar | AE28: 403 | AH28: Offen | AI28: Zugriff verweigert/gedrosselt (HTTP 403); keine Umgehung versucht | AL28: Mittel (Webseite) | AM28: 2026-10-14 13:53 | AN28: Nicht zugänglich / nicht prüfbar | AO28: Zu prüfen | AP28: Belegt Existenz und Zugänglichkeit der Quelle; inhaltliche Aussagen erst nach Auswertung. | AQ28: Keine Einstufung: Kennzahlen/Befunde noch nicht ausgewertet; Schwellen der Bewertungslogik noch nicht validiert. | AR28: Nein | AS28: Kanton Basel-Landschaft | AT28: Offen | AU28: Automatisch nicht prüfbar – manuell im Browser prüfen
A29: BL-C1-03 | B29: Kanton | C29: Schweiz | D29: Basel-Landschaft | E29: Alle | F29: C1 | G29: Rechnungslegung Gemeinden | H29: Kanton BL: Gemeindefinanzen (Rechtsgrundlagen, Finanzausgleich, Rechnungslegung) | I29: Behördeninformation | J29: Webseite | K29: Information | L29: Kanton Basel-Landschaft, Finanz- und Kirchendirektion | M29: https://www.baselland.ch/politik-und-behorden/gemeinden/gemeindefinanzen | O29: 2026-10-14 | P29: Einstieg zu Finanzhandbuch, Rechtsgrundlagen und Finanzausgleich | S29: Kanton × Grössenklasse | T29: Noch nicht bewertet | U29: Mittel | Y29: Dokument auswerten; Aktualität und Geltung prüfen | Z29: Websuche 14.10.2026 (URL im Suchergebnis gefunden) | AD29: Nicht prüfbar | AE29: 403 | AH29: Offen | AI29: Zugriff verweigert/gedrosselt (HTTP 403); keine Umgehung versucht | AL29: Mittel (Webseite) | AM29: 2026-10-14 13:54 | AN29: Nicht zugänglich / nicht prüfbar | AP29: Belegt Existenz und Zugänglichkeit der Quelle; inhaltliche Aussagen erst nach Auswertung. | AQ29: Keine Einstufung: Kennzahlen/Befunde noch nicht ausgewertet; Schwellen der Bewertungslogik noch nicht validiert. | AR29: Nein | AS29: Kanton Basel-Landschaft, Finanz- und Kirchendirektion | AT29: Offen | AU29: Automatisch nicht prüfbar – manuell im Browser prüfen | AW29: 2026-10-14: neu aufgenommen
A30: BL-C1-05 | B30: Kanton | C30: Schweiz | D30: Basel-Landschaft | E30: Alle | F30: C1 | G30: Finanzstatistik Gemeinden | H30: Statistisches Amt BL: Webartikel Gemeindefinanzen 2023 (18.9.2024) | I30: Statistischer Bericht | J30: Webseite | K30: Information | L30: Statistisches Amt Basel-Landschaft | M30: https://www.baselland.ch/politik-und-behorden/direktionen/finanz-und-kirchendirektion/daten-statistik/abteilung-statistik/publikationen-und-statistiken/finanzen-und-steuern/webartikel-vom-18-09-2024-gemeindefinanzen-2023 | N30: 2023 | O30: 2026-10-14 | P30: Kantonaler Überblick Ergebnis/Eigenkapital der Gemeinden | S30: Kanton × Grössenklasse | T30: Noch nicht bewertet | U30: Mittel | Y30: Dokument auswerten; Aktualität und Geltung prüfen | Z30: Websuche 14.10.2026 (URL im Suchergebnis gefunden) | AD30: Nicht prüfbar | AE30: 403 | AH30: Offen | AI30: Zugriff verweigert/gedrosselt (HTTP 403); keine Umgehung versucht | AL30: Mittel (Webseite) | AM30: 2026-10-14 13:54 | AN30: Nicht zugänglich / nicht prüfbar | AO30: 2023 | AP30: Belegt Existenz und Zugänglichkeit der Quelle; inhaltliche Aussagen erst nach Auswertung. | AQ30: Keine Einstufung: Kennzahlen/Befunde noch nicht ausgewertet; Schwellen der Bewertungslogik noch nicht validiert. | AR30: Nein | AS30: Statistisches Amt Basel-Landschaft | AT30: Offen | AU30: Automatisch nicht prüfbar – manuell im Browser prüfen | AW30: 2026-10-14: neu aufgenommen
A31: BL-C1-06 | B31: Kanton | C31: Schweiz | D31: Basel-Landschaft | E31: Alle | F31: C1 | G31: Finanzausgleich | H31: Finanzausgleichsgesetz (FAG) Basel-Landschaft, SGS 185 | I31: Kantonales Gesetz | J31: Direktes Dokument | K31: Kantonales Recht (verbindlich) | L31: Kanton Basel-Landschaft | M31: https://bl.clex.ch/app/de/texts_of_law/185 | O31: 2026-10-14 | P31: Ressourcen- und Lastenausgleich; Münchenstein als Geber/Nehmer prüfen | S31: Kanton × Grössenklasse | T31: Noch nicht bewertet | U31: Hoch | Y31: Dokument auswerten; Aktualität und Geltung prüfen | Z31: URL nach dokumentiertem Schema der amtlichen Rechtssammlung gebildet; Identität per Runner geprüft | AD31: Verifiziert | AE31: 200 | AG31: HTML | AH31: Bestätigt | AI31: Titel via LexWork-API (https://bl.clex.ch/api/de/texts_of_law/185); Schlüsselwörter 1/1 gefunden (Finanzausgleich) | AJ31: Finanzausgleichsgesetz | AK31: 2023, 2009, 2010, 2024, 2025, 2026 | AL31: Hoch (Erlassnummer) | AM31: 2026-10-14 13:54 | AN31: Öffentlich verfügbar und verifiziert | AP31: Belegt Existenz und Zugänglichkeit der Quelle; inhaltliche Aussagen erst nach Auswertung. | AQ31: Keine Einstufung: Kennzahlen/Befunde noch nicht ausgewertet; Schwellen der Bewertungslogik noch nicht validiert. | AR31: Nein | AS31: Kanton Basel-Landschaft | AT31: In Prüfung | AW31: 2026-10-14: neu aufgenommen
A32: BL-C2-01 | B32: Kanton | C32: Schweiz | D32: Basel-Landschaft | E32: Alle | F32: C2 | G32: Geodaten | H32: Geoportal Basel-Landschaft | I32: Geodatenportal | J32: Offizielle Quelle recherchiert | K32: Orientierung / Datengrundlage | L32: Kanton Basel-Landschaft | M32: https://geoview.bl.ch/ | N32: Zu prüfen | O32: 2026-10-14 | P32: Parzellen- und Zoneninformationen; Eigentum gesondert nachweisen | Q32: ÖBA, Parzellenstruktur | R32: Luucy übernehmen; Eigentümerdaten abgleichen | S32: Kein Peer | T32: Noch nicht bewertet | U32: Mittel | V32: Geltende kantonale Detailgrundlage und Datenstand prüfen | W32: B; Q1 | X32: Bodenverfügbarkeit | Y32: Dokument auswerten; Aktualität und Geltung prüfen | Z32: Webrecherche 14.10.2026 | AD32: Verifiziert | AE32: 200 | AG32: HTML | AH32: Bestätigt | AI32: Schlüsselwörter 1/1 gefunden (GeoView); Ort/Zuständigkeit: BL, geoview | AJ32: GeoView BL | AK32: 2011, 2001 | AL32: Mittel (Startseite, kein Dokument) | AM32: 2026-10-14 13:53 | AN32: Öffentlich verfügbar und verifiziert | AO32: Zu prüfen | AP32: Belegt Existenz und Zugänglichkeit der Quelle; inhaltliche Aussagen erst nach Auswertung. | AQ32: Keine Einstufung: Kennzahlen/Befunde noch nicht ausgewertet; Schwellen der Bewertungslogik noch nicht validiert. | AR32: Nein | AS32: Kanton Basel-Landschaft | AT32: In Prüfung | AU32: Kartenportal (JavaScript); kein Eigentumsnachweis.
A33: BL-C2-02 | B33: Kanton | C33: Schweiz | D33: Basel-Landschaft | E33: Alle | F33: C2 | G33: Raumplanung / Baulandmobilisierung | H33: Raumplanungs- und Baugesetz (RBG) Basel-Landschaft, SGS 400 | I33: Kantonales Gesetz | J33: Direktes Dokument | K33: Kantonales Recht (verbindlich) | L33: Kanton Basel-Landschaft | M33: https://bl.clex.ch/app/de/texts_of_law/400 | N33: vom 8.1.1998; geltende Fassung | O33: 2026-10-14 | P33: Mehrwertabgabe, Quartierplanung, Mitwirkung § 7 RBG | S33: Kein Peer-Vergleich | T33: Noch nicht bewertet | U33: Hoch | W33: B; Q1 | Y33: Dokument auswerten; Aktualität und Geltung prüfen | Z33: Websuche 14.10.2026 (URL im Suchergebnis gefunden) | AA33: C5 | AD33: Verifiziert | AE33: 200 | AG33: HTML | AH33: Bestätigt | AI33: Titel via LexWork-API (https://bl.clex.ch/api/de/texts_of_law/400); Schlüsselwörter 1/1 gefunden (Raumplanungs) | AJ33: Raumplanungs- und Baugesetz | AK33: 2024, 2023 | AL33: Hoch (Erlassnummer) | AM33: 2026-10-14 13:54 | AN33: Öffentlich verfügbar und verifiziert | AO33: vom 8.1.1998; geltende Fassung | AP33: Belegt Existenz und Zugänglichkeit der Quelle; inhaltliche Aussagen erst nach Auswertung. | AQ33: Keine Einstufung: Kennzahlen/Befunde noch nicht ausgewertet; Schwellen der Bewertungslogik noch nicht validiert. | AR33: Nein | AS33: Kanton Basel-Landschaft | AT33: In Prüfung | AW33: 2026-10-14: neu aufgenommen
A34: BL-C3-01 | B34: Kanton | C34: Schweiz | D34: Basel-Landschaft | E34: Alle | F34: C3 | G34: Gemeinderecht | H34: Gemeindegesetz (GemG) Basel-Landschaft, SGS 180 | I34: Kantonales Gesetz | J34: Offizielle Quelle recherchiert | K34: Kantonales Gesetz (verbindlich) | L34: Kanton Basel-Landschaft | M34: https://bl.clex.ch/app/de/texts_of_law/180 | N34: vom 28.5.1970; geltende Fassung | O34: 2026-10-14 | P34: Gemeinderecht und Kooperationsinstrumente | Q34: Gemeindeordnung / Kooperation | R34: Relevante Normen konkret auswählen | S34: Qualitativ | T34: Noch nicht bewertet | U34: Mittel | V34: Geltende kantonale Detailgrundlage und Datenstand prüfen | W34: C4; C5 | X34: Trägerschaft | Y34: Dokument auswerten; Aktualität und Geltung prüfen | Z34: Websuche 14.10.2026 (URL im Suchergebnis gefunden) | AD34: Verifiziert | AE34: 200 | AG34: HTML | AH34: Bestätigt | AI34: Titel via LexWork-API (https://bl.clex.ch/api/de/texts_of_law/180); Schlüsselwörter 1/1 gefunden (Gemeinden) | AJ34: Gesetz über die Organisation und die Verwaltung der Gemeinden | AK34: 2026, 2008, 2004, 2005, 2009 | AL34: Hoch (Erlassnummer) | AM34: 2026-10-14 13:53 | AN34: Öffentlich verfügbar und verifiziert | AO34: vom 28.5.1970; geltende Fassung | AP34: Belegt Existenz und Zugänglichkeit der Quelle; inhaltliche Aussagen erst nach Auswertung. | AQ34: Keine Einstufung: Kennzahlen/Befunde noch nicht ausgewertet; Schwellen der Bewertungslogik noch nicht validiert. | AR34: Nein | AS34: Kanton Basel-Landschaft | AT34: In Prüfung | AW34: 2026-10-14: Link ersetzt (vorher https://bl.clex.ch/). Grund: Startseite der Gesetzessammlung durch direkten Erlass ersetzt (Gemeindegesetz SGS 180).
A35: BL-C3-02 | B35: Kanton | C35: Schweiz | D35: Basel-Landschaft | E35: Alle | F35: C3 | G35: Regionale Kooperation | H35: Medienmitteilung Kanton BL: Birsstadt erhält den Wakkerpreis (Verein Birsstadt, Raumkonzept Birsstadt 2035) | I35: Medienmitteilung | J35: Webseite | K35: Information | L35: Kanton Basel-Landschaft, Bau- und Umweltschutzdirektion | M35: https://www.baselland.ch/politik-und-behorden/direktionen/bau-und-umweltschutzdirektion/medienmitteilungen/ausgezeichnete-agglomeration-birsstadt-erhaelt-den-wakkerpreis | O35: 2026-10-14 | P35: Belegt interkommunale Kooperation Birsstadt (10 Gemeinden inkl. Münchenstein) | S35: Kein Peer-Vergleich | T35: Noch nicht bewertet | U35: Mittel | Y35: Dokument auswerten; Aktualität und Geltung prüfen | Z35: Websuche 14.10.2026 (URL im Suchergebnis gefunden) | AD35: Nicht prüfbar | AE35: 403 | AH35: Offen | AI35: Zugriff verweigert/gedrosselt (HTTP 403); keine Umgehung versucht | AL35: Mittel (Webseite) | AM35: 2026-10-14 13:54 | AN35: Nicht zugänglich / nicht prüfbar | AP35: Belegt Existenz und Zugänglichkeit der Quelle; inhaltliche Aussagen erst nach Auswertung. | AQ35: Keine Einstufung: Kennzahlen/Befunde noch nicht ausgewertet; Schwellen der Bewertungslogik noch nicht validiert. | AR35: Nein | AS35: Kanton Basel-Landschaft, Bau- und Umweltschutzdirektion | AT35: Offen | AU35: Automatisch nicht prüfbar – manuell im Browser prüfen | AW35: 2026-10-14: neu aufgenommen
A36: BL-C4-01 | B36: Kanton | C36: Schweiz | D36: Basel-Landschaft | E36: Alle | F36: C4 | G36: Verwaltung | H36: Kanton Basel-Landschaft: Gemeindefachstellen | I36: Behördenportal | J36: Offizielle Quelle recherchiert | K36: Orientierung / Datengrundlage | L36: Kanton Basel-Landschaft | M36: https://www.baselland.ch/politik-und-behorden/gemeinden | N36: Zu prüfen | O36: 14.10.2026 | P36: Fachliche Rahmenbedingungen für Gemeindeverwaltung | Q36: Organisation / Kompetenzen | R36: Kommunale Organisationsdokumente ergänzen | S36: Qualitativ | T36: Noch nicht bewertet | U36: Mittel | V36: Geltende kantonale Detailgrundlage und Datenstand prüfen | W36: Q6 | X36: Bestellerkompetenz | Y36: Dokument auswerten; Aktualität und Geltung prüfen | Z36: Webrecherche 14.10.2026 | AD36: Nicht prüfbar | AE36: 403 | AH36: Offen | AI36: Zugriff verweigert/gedrosselt (HTTP 403); keine Umgehung versucht | AL36: Mittel (Webseite) | AM36: 2026-10-14 13:53 | AN36: Nicht zugänglich / nicht prüfbar | AO36: Zu prüfen | AP36: Belegt Existenz und Zugänglichkeit der Quelle; inhaltliche Aussagen erst nach Auswertung. | AQ36: Keine Einstufung: Kennzahlen/Befunde noch nicht ausgewertet; Schwellen der Bewertungslogik noch nicht validiert. | AR36: Nein | AS36: Kanton Basel-Landschaft | AT36: Offen | AU36: Automatisch nicht prüfbar – manuell im Browser prüfen
A37: BL-C4-02 | B37: Kanton | C37: Schweiz | D37: Basel-Landschaft | E37: Alle | F37: C4 | G37: Beschaffung | H37: Verordnung zum Einführungsgesetz zur IVöB (Vo EG IVöB) Basel-Landschaft, SGS 420.11 | I37: Kantonale Verordnung | J37: Direktes Dokument | K37: Kantonales Recht (verbindlich) | L37: Kanton Basel-Landschaft | M37: https://bl.clex.ch/app/de/texts_of_law/420.11 | O37: 2026-10-14 | P37: Beschaffungsrecht für Gemeinden ab 1.1.2024 | S37: Kein Peer-Vergleich | T37: Noch nicht bewertet | U37: Hoch | Y37: Dokument auswerten; Aktualität und Geltung prüfen | Z37: URL nach dokumentiertem Schema der amtlichen Rechtssammlung gebildet; Identität per Runner geprüft | AD37: Verifiziert | AE37: 200 | AG37: HTML | AH37: Bestätigt | AI37: Titel via LexWork-API (https://bl.clex.ch/api/de/texts_of_law/420.11); Schlüsselwörter 1/1 gefunden (Beschaffung) | AJ37: Verordnung zum Einführungsgesetz zur Interkantonalen Vereinbarung über das öffentliche Beschaffungswesen | AK37: 2026, 2023, 2024, 2022 | AL37: Hoch (Erlassnummer) | AM37: 2026-10-14 13:54 | AN37: Öffentlich verfügbar und verifiziert | AP37: Belegt Existenz und Zugänglichkeit der Quelle; inhaltliche Aussagen erst nach Auswertung. | AQ37: Keine Einstufung: Kennzahlen/Befunde noch nicht ausgewertet; Schwellen der Bewertungslogik noch nicht validiert. | AR37: Nein | AS37: Kanton Basel-Landschaft | AT37: In Prüfung | AW37: 2026-10-14: neu aufgenommen
A38: BL-C5-01 | B38: Kanton | C38: Schweiz | D38: Basel-Landschaft | E38: Alle | F38: C5 | G38: Mitwirkung | H38: Gesetz über die politischen Rechte (GpR) Basel-Landschaft, SGS 120 | I38: Kantonales Gesetz | J38: Offizielle Quelle recherchiert | K38: Kantonales Gesetz (verbindlich) | L38: Kanton Basel-Landschaft | M38: https://bl.clex.ch/app/de/texts_of_law/120 | N38: vom 7.9.1981; geltende Fassung | O38: 2026-10-14 | P38: Rechtsrahmen von Gemeindeversammlung und Mitwirkung | Q38: Entscheidungswege | R38: Gemeindeordnung und Beschlüsse prüfen | S38: Qualitativ | T38: Noch nicht bewertet | U38: Mittel | V38: Geltende kantonale Detailgrundlage und Datenstand prüfen | W38: C3 | X38: Politische Machbarkeit | Y38: Dokument auswerten; Aktualität und Geltung prüfen | Z38: URL nach dokumentiertem Schema der amtlichen Rechtssammlung gebildet; Identität per Runner geprüft | AD38: Verifiziert | AE38: 200 | AG38: HTML | AH38: Bestätigt | AI38: Titel via LexWork-API (https://bl.clex.ch/api/de/texts_of_law/120); Schlüsselwörter 1/1 gefunden (politischen Rechte) | AJ38: Gesetz über die politischen Rechte | AK38: 2025, 2024, 2014, 2006 | AL38: Hoch (Erlassnummer) | AM38: 2026-10-14 13:53 | AN38: Öffentlich verfügbar und verifiziert | AO38: vom 7.9.1981; geltende Fassung | AP38: Belegt Existenz und Zugänglichkeit der Quelle; inhaltliche Aussagen erst nach Auswertung. | AQ38: Keine Einstufung: Kennzahlen/Befunde noch nicht ausgewertet; Schwellen der Bewertungslogik noch nicht validiert. | AR38: Nein | AS38: Kanton Basel-Landschaft | AT38: In Prüfung | AW38: 2026-10-14: Link ersetzt (vorher https://bl.clex.ch/). Grund: Startseite der Gesetzessammlung durch direkten Erlass ersetzt (GpR SGS 120).
A39: SG-C1-01 | B39: Kanton | C39: Schweiz | D39: St. Gallen | E39: Alle | F39: C1 | G39: Gemeindefinanzen | H39: Kanton St. Gallen, Amt für Gemeinden: Rechnungslegung (RMSG) / Gemeindefinanzen | I39: Behördeninformation | J39: Offizielle Quelle recherchiert | K39: Orientierung / Datengrundlage | L39: Kanton St. Gallen, Amt für Gemeinden | M39: https://www.sg.ch/politik-verwaltung/gemeinden/gemeindefinanzen/rechnungslegung--rmsg-.html | N39: Zu prüfen | O39: 2026-10-14 | P39: Finanzdaten als kantonaler Einstieg | Q39: Selbstfinanzierung, Verschuldung | R39: SG- und Wil-Werte mit kantonaler Rechnungslegung abgleichen | S39: Kanton × Grössenklasse | T39: Noch nicht bewertet | U39: Mittel | V39: Geltende kantonale Detailgrundlage und Datenstand prüfen | W39: A1; C1 | X39: Finanztragfähigkeit | Y39: Dokument auswerten; Aktualität und Geltung prüfen | Z39: Webrecherche 14.10.2026 | AD39: Verifiziert | AE39: 200 | AG39: HTML | AH39: Bestätigt | AI39: Schlüsselwörter 1/1 gefunden (Rechnungslegung); Ort/Zuständigkeit: St. Gallen, St.Gallen | AJ39: Rechnungslegung (RMSG) | sg.ch | Rechnungslegung (RMSG) | AK39: 2017, 2021, 2026, 2022, 2020, 2025 | AL39: Mittel (Webseite) | AM39: 2026-10-14 13:53 | AN39: Öffentlich verfügbar und verifiziert | AO39: Zu prüfen | AP39: Belegt Existenz und Zugänglichkeit der Quelle; inhaltliche Aussagen erst nach Auswertung. | AQ39: Keine Einstufung: Kennzahlen/Befunde noch nicht ausgewertet; Schwellen der Bewertungslogik noch nicht validiert. | AR39: Nein | AS39: Kanton St. Gallen, Amt für Gemeinden | AT39: In Prüfung | AW39: 2026-10-14: Link ersetzt (vorher https://www.efv.admin.ch/de/finanzstatistik-daten). Grund: Herausgeber «Kanton St. Gallen» passte nicht zum EFV-Bundeslink (Dublette zu CH-C1-01); durch kantonale Fundstelle ersetzt.
