Workbook

Sheet Übersicht
A1: Qualitätsrahmen Q1–Q6 · Erste Übersicht · Münchenstein, Wil, Seelisberg
A2: Raumgleiter · LP01 · Assignment 01 (Q-Restriktionsprofil, Entwurf) · Recherchestand 14.10.2026 · Basis: Q_Grundlagenkataster_3_Gemeinden_bereinigt.xlsx plus Ergänzungen
A4: Aufbau
A5: 1_Q1_Rechtsordnung | B5: Erlasse und Pläne: Bund → Interkantonal → Kanton → Gemeinde (alle Q)
A6: 2_Q2_Landschaft | B6: Dokumente, Inventare, Geodaten Landschaft/Biodiversität (inkl. nicht öffentliche Daten)
A7: 3_Q3_Klima_Energie | B7: Dokumente, Inventare, Geodaten Klimaschutz/Energie/Ressourcen
A8: 4_Q4_Resilienz | B8: Dokumente, Inventare, Geodaten Klimaanpassung/Resilienz
A9: 5_Q5_Ortsbild | B9: Dokumente, Inventare, Geodaten Ortsbild/Baukultur
A10: 6_Q6_Bestellung | B10: Dokumente, Grundlagen integrierte lebenszyklusorientierte Bestellung/Vergabe
A11: 7_GIS_Layers | B11: Sammlung der GIS-Layer mit Links (CH-weit und je Gemeinde) zur Betroffenheitsprüfung
A12: 8_Hinweise_Kataster | B12: Auffälligkeiten im Kataster, Umsetzungsstand
A15: Abdeckung je Blatt und Gemeinde (Anzahl Zeilen, per Formel aus den Blättern)
A16: Blatt | B16: Gemeinde | C16: gilt / belegt | D16: belegt – Betroffenheit offen | E16: keine Regelung (geprüft) | F16: nicht belegt (Recherche offen) | G16: Datenanfrage | H16: Summe | I16: Anteil belegt
A17: 1_Q1_Rechtsordnung | B17: Münchenstein | C17: =COUNTIF('1_Q1_Rechtsordnung'!$I$6:$I$95,"belegt")+COUNTIF('1_Q1_Rechtsordnung'!$I$6:$I$95,"gilt") | D17: =COUNTIF('1_Q1_Rechtsordnung'!$I$6:$I$95,"belegt – Betroffenheit offen") | E17: =COUNTIF('1_Q1_Rechtsordnung'!$I$6:$I$95,"keine Regelung (geprüft)") | F17: =COUNTIF('1_Q1_Rechtsordnung'!$I$6:$I$95,"nicht belegt (Recherche offen)") | G17: =COUNTIF('1_Q1_Rechtsordnung'!$I$6:$I$95,"Datenanfrage (nicht öffentlich)") | H17: =SUM(C17:G17) | I17: =IF(H17=0,0,(C17+D17)/H17)
B18: Wil | C18: =COUNTIF('1_Q1_Rechtsordnung'!$J$6:$J$95,"belegt")+COUNTIF('1_Q1_Rechtsordnung'!$J$6:$J$95,"gilt") | D18: =COUNTIF('1_Q1_Rechtsordnung'!$J$6:$J$95,"belegt – Betroffenheit offen") | E18: =COUNTIF('1_Q1_Rechtsordnung'!$J$6:$J$95,"keine Regelung (geprüft)") | F18: =COUNTIF('1_Q1_Rechtsordnung'!$J$6:$J$95,"nicht belegt (Recherche offen)") | G18: =COUNTIF('1_Q1_Rechtsordnung'!$J$6:$J$95,"Datenanfrage (nicht öffentlich)") | H18: =SUM(C18:G18) | I18: =IF(H18=0,0,(C18+D18)/H18)
B19: Seelisberg | C19: =COUNTIF('1_Q1_Rechtsordnung'!$K$6:$K$95,"belegt")+COUNTIF('1_Q1_Rechtsordnung'!$K$6:$K$95,"gilt") | D19: =COUNTIF('1_Q1_Rechtsordnung'!$K$6:$K$95,"belegt – Betroffenheit offen") | E19: =COUNTIF('1_Q1_Rechtsordnung'!$K$6:$K$95,"keine Regelung (geprüft)") | F19: =COUNTIF('1_Q1_Rechtsordnung'!$K$6:$K$95,"nicht belegt (Recherche offen)") | G19: =COUNTIF('1_Q1_Rechtsordnung'!$K$6:$K$95,"Datenanfrage (nicht öffentlich)") | H19: =SUM(C19:G19) | I19: =IF(H19=0,0,(C19+D19)/H19)
A20: 2_Q2_Landschaft | B20: Münchenstein | C20: =COUNTIF('2_Q2_Landschaft'!$I$6:$I$36,"belegt")+COUNTIF('2_Q2_Landschaft'!$I$6:$I$36,"gilt") | D20: =COUNTIF('2_Q2_Landschaft'!$I$6:$I$36,"belegt – Betroffenheit offen") | E20: =COUNTIF('2_Q2_Landschaft'!$I$6:$I$36,"keine Regelung (geprüft)") | F20: =COUNTIF('2_Q2_Landschaft'!$I$6:$I$36,"nicht belegt (Recherche offen)") | G20: =COUNTIF('2_Q2_Landschaft'!$I$6:$I$36,"Datenanfrage (nicht öffentlich)") | H20: =SUM(C20:G20) | I20: =IF(H20=0,0,(C20+D20)/H20)
B21: Wil | C21: =COUNTIF('2_Q2_Landschaft'!$J$6:$J$36,"belegt")+COUNTIF('2_Q2_Landschaft'!$J$6:$J$36,"gilt") | D21: =COUNTIF('2_Q2_Landschaft'!$J$6:$J$36,"belegt – Betroffenheit offen") | E21: =COUNTIF('2_Q2_Landschaft'!$J$6:$J$36,"keine Regelung (geprüft)") | F21: =COUNTIF('2_Q2_Landschaft'!$J$6:$J$36,"nicht belegt (Recherche offen)") | G21: =COUNTIF('2_Q2_Landschaft'!$J$6:$J$36,"Datenanfrage (nicht öffentlich)") | H21: =SUM(C21:G21) | I21: =IF(H21=0,0,(C21+D21)/H21)
B22: Seelisberg | C22: =COUNTIF('2_Q2_Landschaft'!$K$6:$K$36,"belegt")+COUNTIF('2_Q2_Landschaft'!$K$6:$K$36,"gilt") | D22: =COUNTIF('2_Q2_Landschaft'!$K$6:$K$36,"belegt – Betroffenheit offen") | E22: =COUNTIF('2_Q2_Landschaft'!$K$6:$K$36,"keine Regelung (geprüft)") | F22: =COUNTIF('2_Q2_Landschaft'!$K$6:$K$36,"nicht belegt (Recherche offen)") | G22: =COUNTIF('2_Q2_Landschaft'!$K$6:$K$36,"Datenanfrage (nicht öffentlich)") | H22: =SUM(C22:G22) | I22: =IF(H22=0,0,(C22+D22)/H22)
A23: 3_Q3_Klima_Energie | B23: Münchenstein | C23: =COUNTIF('3_Q3_Klima_Energie'!$I$6:$I$32,"belegt")+COUNTIF('3_Q3_Klima_Energie'!$I$6:$I$32,"gilt") | D23: =COUNTIF('3_Q3_Klima_Energie'!$I$6:$I$32,"belegt – Betroffenheit offen") | E23: =COUNTIF('3_Q3_Klima_Energie'!$I$6:$I$32,"keine Regelung (geprüft)") | F23: =COUNTIF('3_Q3_Klima_Energie'!$I$6:$I$32,"nicht belegt (Recherche offen)") | G23: =COUNTIF('3_Q3_Klima_Energie'!$I$6:$I$32,"Datenanfrage (nicht öffentlich)") | H23: =SUM(C23:G23) | I23: =IF(H23=0,0,(C23+D23)/H23)
B24: Wil | C24: =COUNTIF('3_Q3_Klima_Energie'!$J$6:$J$32,"belegt")+COUNTIF('3_Q3_Klima_Energie'!$J$6:$J$32,"gilt") | D24: =COUNTIF('3_Q3_Klima_Energie'!$J$6:$J$32,"belegt – Betroffenheit offen") | E24: =COUNTIF('3_Q3_Klima_Energie'!$J$6:$J$32,"keine Regelung (geprüft)") | F24: =COUNTIF('3_Q3_Klima_Energie'!$J$6:$J$32,"nicht belegt (Recherche offen)") | G24: =COUNTIF('3_Q3_Klima_Energie'!$J$6:$J$32,"Datenanfrage (nicht öffentlich)") | H24: =SUM(C24:G24) | I24: =IF(H24=0,0,(C24+D24)/H24)
B25: Seelisberg | C25: =COUNTIF('3_Q3_Klima_Energie'!$K$6:$K$32,"belegt")+COUNTIF('3_Q3_Klima_Energie'!$K$6:$K$32,"gilt") | D25: =COUNTIF('3_Q3_Klima_Energie'!$K$6:$K$32,"belegt – Betroffenheit offen") | E25: =COUNTIF('3_Q3_Klima_Energie'!$K$6:$K$32,"keine Regelung (geprüft)") | F25: =COUNTIF('3_Q3_Klima_Energie'!$K$6:$K$32,"nicht belegt (Recherche offen)") | G25: =COUNTIF('3_Q3_Klima_Energie'!$K$6:$K$32,"Datenanfrage (nicht öffentlich)") | H25: =SUM(C25:G25) | I25: =IF(H25=0,0,(C25+D25)/H25)
A26: 4_Q4_Resilienz | B26: Münchenstein | C26: =COUNTIF('4_Q4_Resilienz'!$I$6:$I$34,"belegt")+COUNTIF('4_Q4_Resilienz'!$I$6:$I$34,"gilt") | D26: =COUNTIF('4_Q4_Resilienz'!$I$6:$I$34,"belegt – Betroffenheit offen") | E26: =COUNTIF('4_Q4_Resilienz'!$I$6:$I$34,"keine Regelung (geprüft)") | F26: =COUNTIF('4_Q4_Resilienz'!$I$6:$I$34,"nicht belegt (Recherche offen)") | G26: =COUNTIF('4_Q4_Resilienz'!$I$6:$I$34,"Datenanfrage (nicht öffentlich)") | H26: =SUM(C26:G26) | I26: =IF(H26=0,0,(C26+D26)/H26)
B27: Wil | C27: =COUNTIF('4_Q4_Resilienz'!$J$6:$J$34,"belegt")+COUNTIF('4_Q4_Resilienz'!$J$6:$J$34,"gilt") | D27: =COUNTIF('4_Q4_Resilienz'!$J$6:$J$34,"belegt – Betroffenheit offen") | E27: =COUNTIF('4_Q4_Resilienz'!$J$6:$J$34,"keine Regelung (geprüft)") | F27: =COUNTIF('4_Q4_Resilienz'!$J$6:$J$34,"nicht belegt (Recherche offen)") | G27: =COUNTIF('4_Q4_Resilienz'!$J$6:$J$34,"Datenanfrage (nicht öffentlich)") | H27: =SUM(C27:G27) | I27: =IF(H27=0,0,(C27+D27)/H27)
B28: Seelisberg | C28: =COUNTIF('4_Q4_Resilienz'!$K$6:$K$34,"belegt")+COUNTIF('4_Q4_Resilienz'!$K$6:$K$34,"gilt") | D28: =COUNTIF('4_Q4_Resilienz'!$K$6:$K$34,"belegt – Betroffenheit offen") | E28: =COUNTIF('4_Q4_Resilienz'!$K$6:$K$34,"keine Regelung (geprüft)") | F28: =COUNTIF('4_Q4_Resilienz'!$K$6:$K$34,"nicht belegt (Recherche offen)") | G28: =COUNTIF('4_Q4_Resilienz'!$K$6:$K$34,"Datenanfrage (nicht öffentlich)") | H28: =SUM(C28:G28) | I28: =IF(H28=0,0,(C28+D28)/H28)
A29: 5_Q5_Ortsbild | B29: Münchenstein | C29: =COUNTIF('5_Q5_Ortsbild'!$I$6:$I$31,"belegt")+COUNTIF('5_Q5_Ortsbild'!$I$6:$I$31,"gilt") | D29: =COUNTIF('5_Q5_Ortsbild'!$I$6:$I$31,"belegt – Betroffenheit offen") | E29: =COUNTIF('5_Q5_Ortsbild'!$I$6:$I$31,"keine Regelung (geprüft)") | F29: =COUNTIF('5_Q5_Ortsbild'!$I$6:$I$31,"nicht belegt (Recherche offen)") | G29: =COUNTIF('5_Q5_Ortsbild'!$I$6:$I$31,"Datenanfrage (nicht öffentlich)") | H29: =SUM(C29:G29) | I29: =IF(H29=0,0,(C29+D29)/H29)
B30: Wil | C30: =COUNTIF('5_Q5_Ortsbild'!$J$6:$J$31,"belegt")+COUNTIF('5_Q5_Ortsbild'!$J$6:$J$31,"gilt") | D30: =COUNTIF('5_Q5_Ortsbild'!$J$6:$J$31,"belegt – Betroffenheit offen") | E30: =COUNTIF('5_Q5_Ortsbild'!$J$6:$J$31,"keine Regelung (geprüft)") | F30: =COUNTIF('5_Q5_Ortsbild'!$J$6:$J$31,"nicht belegt (Recherche offen)") | G30: =COUNTIF('5_Q5_Ortsbild'!$J$6:$J$31,"Datenanfrage (nicht öffentlich)") | H30: =SUM(C30:G30) | I30: =IF(H30=0,0,(C30+D30)/H30)
B31: Seelisberg | C31: =COUNTIF('5_Q5_Ortsbild'!$K$6:$K$31,"belegt")+COUNTIF('5_Q5_Ortsbild'!$K$6:$K$31,"gilt") | D31: =COUNTIF('5_Q5_Ortsbild'!$K$6:$K$31,"belegt – Betroffenheit offen") | E31: =COUNTIF('5_Q5_Ortsbild'!$K$6:$K$31,"keine Regelung (geprüft)") | F31: =COUNTIF('5_Q5_Ortsbild'!$K$6:$K$31,"nicht belegt (Recherche offen)") | G31: =COUNTIF('5_Q5_Ortsbild'!$K$6:$K$31,"Datenanfrage (nicht öffentlich)") | H31: =SUM(C31:G31) | I31: =IF(H31=0,0,(C31+D31)/H31)
A32: 6_Q6_Bestellung | B32: Münchenstein | C32: =COUNTIF('6_Q6_Bestellung'!$I$6:$I$36,"belegt")+COUNTIF('6_Q6_Bestellung'!$I$6:$I$36,"gilt") | D32: =COUNTIF('6_Q6_Bestellung'!$I$6:$I$36,"belegt – Betroffenheit offen") | E32: =COUNTIF('6_Q6_Bestellung'!$I$6:$I$36,"keine Regelung (geprüft)") | F32: =COUNTIF('6_Q6_Bestellung'!$I$6:$I$36,"nicht belegt (Recherche offen)") | G32: =COUNTIF('6_Q6_Bestellung'!$I$6:$I$36,"Datenanfrage (nicht öffentlich)") | H32: =SUM(C32:G32) | I32: =IF(H32=0,0,(C32+D32)/H32)
B33: Wil | C33: =COUNTIF('6_Q6_Bestellung'!$J$6:$J$36,"belegt")+COUNTIF('6_Q6_Bestellung'!$J$6:$J$36,"gilt") | D33: =COUNTIF('6_Q6_Bestellung'!$J$6:$J$36,"belegt – Betroffenheit offen") | E33: =COUNTIF('6_Q6_Bestellung'!$J$6:$J$36,"keine Regelung (geprüft)") | F33: =COUNTIF('6_Q6_Bestellung'!$J$6:$J$36,"nicht belegt (Recherche offen)") | G33: =COUNTIF('6_Q6_Bestellung'!$J$6:$J$36,"Datenanfrage (nicht öffentlich)") | H33: =SUM(C33:G33) | I33: =IF(H33=0,0,(C33+D33)/H33)
B34: Seelisberg | C34: =COUNTIF('6_Q6_Bestellung'!$K$6:$K$36,"belegt")+COUNTIF('6_Q6_Bestellung'!$K$6:$K$36,"gilt") | D34: =COUNTIF('6_Q6_Bestellung'!$K$6:$K$36,"belegt – Betroffenheit offen") | E34: =COUNTIF('6_Q6_Bestellung'!$K$6:$K$36,"keine Regelung (geprüft)") | F34: =COUNTIF('6_Q6_Bestellung'!$K$6:$K$36,"nicht belegt (Recherche offen)") | G34: =COUNTIF('6_Q6_Bestellung'!$K$6:$K$36,"Datenanfrage (nicht öffentlich)") | H34: =SUM(C34:G34) | I34: =IF(H34=0,0,(C34+D34)/H34)
A35: Anteil belegt = (belegt + belegt – Betroffenheit offen) / Summe; «n. a.» wird nicht gezählt.
A37: Legende Status
A38: gilt | B38: Rechtsnorm gilt für die Gemeinde
A39: belegt | B39: Beleg mit Link vorhanden (Link-Status in der Spalte «Link-Status»)
A40: belegt – Betroffenheit offen | B40: Layer/Inventar existiert; Lage in der Gemeinde per GIS-Overlay zu prüfen (Blatt 7)
A41: keine Regelung (geprüft) | B41: Recherche zeigt: die Ebene regelt/erhebt nichts, übergeordnetes Recht gilt (derzeit keine Zeile)
A42: nicht belegt (Recherche offen) | B42: bisher kein Beleg gefunden
A43: Datenanfrage (nicht öffentlich) | B43: nicht öffentlich; Existenzerwartung (hoch/mittel/unbekannt) im Prüfhinweis
A44: n. a. | B44: nicht anwendbar (andere Gebietskörperschaft)
...

Sheet 1_Q1_Rechtsordnung
A1: 1 · Q1 Recht und Planung – Rechtsordnung (Bund → Interkantonal → Kanton → Gemeinde)
A2: Erlasse und behördenverbindliche Pläne aller Q-Dimensionen (Spalte «Q»), gegliedert nach Rechtsebene. | Gemeinden: Münchenstein (BL), Wil (SG), Seelisberg (UR) | Recherchestand: 14.10.2026
A3: Status: gilt / belegt = Beleg mit Link vorhanden · belegt – Betroffenheit offen = Layer/Inventar existiert, Lage in der Gemeinde per GIS zu prüfen (Blatt 7) · keine Regelung (geprüft) = Ebene regelt nichts, übergeordnetes Recht gilt · nicht belegt (Recherche offen) = bisher kein Beleg · Datenanfrage = nicht öffentlich · n. a. = andere Gebietskörperschaft
A5: Ebene | B5: Q | C5: Typ | D5: Bezeichnung | E5: Referenz (SR/SGS/RB) | F5: Stand | G5: Zuständige Stelle | H5: Zugang | I5: Münchenstein (BL) | J5: Wil (SG) | K5: Seelisberg (UR) | L5: Inhalt / Mindestanforderung | M5: Link / Quelle | N5: Link-Status | O5: Herkunft · Confidence | P5: Prüfnachweis / Hinweis
A6: BUND (gilt für alle drei Gemeinden)
A7: Bund | B7: Q1–Q6 | C7: Verfassung | D7: Bundesverfassung (Art. 73 Nachhaltigkeit, 75 Raumplanung, 75b Zweitwohnungen, 78 Natur-/Heimatschutz, 89 Energie) | E7: SR 101 | F7: konsolidierte Fassung (Fedlex) | G7: BK | H7: öffentlich | I7: gilt | J7: gilt | K7: gilt | L7: Verfassungsgrundlagen für Raumplanung, Natur-/Heimatschutz, Energie | M7: https://www.fedlex.admin.ch/eli/cc/1999/404/de | N7: geprüft · OK | O7: Ergänzung · hoch
A8: Bund | B8: Q1 | C8: Gesetz | D8: Raumplanungsgesetz (RPG) | E8: SR 700 | F8: konsolidierte Fassung (Fedlex) | G8: Bund (ARE) | H8: öffentlich | I8: gilt | J8: gilt | K8: gilt | L8: Zonenkonformität, haushälterische Bodennutzung, Bauen ausserhalb Bauzonen | M8: https://www.fedlex.admin.ch/eli/cc/1979/1573_1573_1573/de | N8: geprüft · OK | O8: Katalog · hoch
A9: Bund | B9: Q1 | C9: Verordnung | D9: Raumplanungsverordnung (RPV) | E9: SR 700.1 | F9: konsolidierte Fassung (Fedlex) | G9: Bund (ARE) | H9: öffentlich | I9: gilt | J9: gilt | K9: gilt | L9: Ausführungsanforderungen zur Raumplanung (u. a. Sachplan FFF, Bauzonendimensionierung) | M9: https://www.fedlex.admin.ch/eli/cc/2000/310/de | N9: geprüft · OK | O9: Katalog · hoch
A10: Bund | B10: Q1 | C10: Gesetz | D10: Zweitwohnungsgesetz (ZWG) | E10: SR 702 | F10: 01.10.2024 (Fedlex-Fassung lt. Suchtreffer) | G10: Bund (ARE) | H10: öffentlich | I10: gilt | J10: gilt | K10: gilt | L10: Beschränkung Zweitwohnungen in Gemeinden >20 % Anteil | M10: https://www.fedlex.admin.ch/eli/cc/2015/886/de | N10: geprüft · OK | O10: Ergänzung · hoch | P10: Massgebend für den Zweitwohnungsanteil ist die jährliche Feststellung des Bundes (Art. 5 ZWG). Seelisberg: siehe ZWV-Anhang
A11: Bund | B11: Q1 | C11: Gesetz | D11: Zweitwohnungsverordnung (ZWV) | E11: SR 702.1 | F11: konsolidierte Fassung (Fedlex) | G11: Bund (ARE) | H11: öffentlich | I11: gilt | J11: gilt | K11: gilt | L11: Vollzug ZWG; Anhang: Gemeinden mit vermutetem Zweitwohnungsanteil >20 % | M11: https://www.fedlex.admin.ch/eli/cc/2015/887/de | N11: geprüft · OK | O11: Ergänzung · hoch | P11: Anhang: Seelisberg (UR, BFS-Nr. 1215) aufgeführt; Wil in der SG-Liste nicht aufgeführt; Münchenstein: BL-Teil der Liste nicht eingesehen
A12: Bund | B12: Q2 / Q5 | C12: Gesetz | D12: Natur- und Heimatschutzgesetz (NHG) | E12: SR 451 | F12: konsolidierte Fassung (Fedlex) | G12: Bund (BAFU / BAK) | H12: öffentlich | I12: gilt | J12: gilt | K12: gilt | L12: Schutz von Landschaften, Biotopen, Ortsbildern je nach Schutzstatus | M12: https://www.fedlex.admin.ch/eli/cc/1966/1637_1694_1679/de | N12: geprüft · OK | O12: Katalog · hoch
A13: Bund | B13: Q2 / Q5 | C13: Verordnung | D13: Natur- und Heimatschutzverordnung (NHV) | E13: SR 451.1 | F13: konsolidierte Fassung (Fedlex) | G13: Bund (BAFU / BAK / ASTRA) | H13: öffentlich | I13: gilt | J13: gilt | K13: gilt | L13: Vollzug NHG; Bundesinventare, Bundesaufgaben | M13: https://www.fedlex.admin.ch/eli/cc/1991/249_249_249/de | N13: geprüft · OK | O13: Ergänzung · hoch
A14: Bund | B14: Q2 / Q5 | C14: Verordnung | D14: Verordnung über das Bundesinventar der Landschaften und Naturdenkmäler (VBLN) | E14: SR 451.11 | F14: konsolidierte Fassung (Fedlex) | G14: Bund (BAFU) | H14: öffentlich | I14: gilt | J14: gilt | K14: gilt | L14: Rechtsgrundlage BLN | M14: https://www.fedlex.admin.ch/eli/cc/2017/290/de | N14: geprüft · OK | O14: Ergänzung · hoch
A15: Bund | B15: Q2 / Q5 | C15: Verordnung | D15: Verordnung über das Bundesinventar der schützenswerten Ortsbilder der Schweiz (VISOS) | E15: SR 451.12 | F15: konsolidierte Fassung (Fedlex) | G15: Bund (BAK) | H15: öffentlich | I15: gilt | J15: gilt | K15: gilt | L15: Rechtsgrundlage ISOS | M15: https://www.fedlex.admin.ch/eli/cc/2019/673/de | N15: geprüft · OK | O15: Ergänzung · hoch
A16: Bund | B16: Q2 / Q5 | C16: Verordnung | D16: Verordnung über das Bundesinventar der historischen Verkehrswege der Schweiz (VIVS) | E16: SR 451.13 | F16: konsolidierte Fassung (Fedlex) | G16: Bund (ASTRA) | H16: öffentlich | I16: gilt | J16: gilt | K16: gilt | L16: Rechtsgrundlage IVS | M16: https://www.fedlex.admin.ch/eli/cc/2010/227/de | N16: geprüft · OK | O16: Ergänzung · hoch
A17: Bund | B17: Q2 | C17: Verordnung | D17: Verordnung über den Schutz der Auengebiete von nationaler Bedeutung (Auenverordnung) | E17: SR 451.31 | F17: Erlass 28.10.1992; konsolidierte Fassung (Fedlex) | G17: Bund (BAFU) | H17: öffentlich | I17: gilt | J17: gilt | K17: gilt | L17: Rechtsgrundlage Bundesinventar: Auengebiete | M17: https://www.fedlex.admin.ch/eli/cc/1992/2080_2080_2080/de | N17: geprüft · OK | O17: Ergänzung · hoch
A18: Bund | B18: Q2 | C18: Verordnung | D18: Verordnung über den Schutz der Hoch- und Übergangsmoore von nationaler Bedeutung (Hochmoorverordnung) | E18: SR 451.32 | F18: Erlass 21.01.1991; konsolidierte Fassung (Fedlex) | G18: Bund (BAFU) | H18: öffentlich | I18: gilt | J18: gilt | K18: gilt | L18: Rechtsgrundlage Bundesinventar: Hoch- und Übergangsmoore | M18: https://www.fedlex.admin.ch/eli/cc/1991/270_270_270/de | N18: geprüft · OK | O18: Ergänzung · hoch
A19: Bund | B19: Q2 | C19: Verordnung | D19: Verordnung über den Schutz der Flachmoore von nationaler Bedeutung (Flachmoorverordnung) | E19: SR 451.33 | F19: Erlass 07.09.1994; konsolidierte Fassung (Fedlex) | G19: Bund (BAFU) | H19: öffentlich | I19: gilt | J19: gilt | K19: gilt | L19: Rechtsgrundlage Bundesinventar: Flachmoore | M19: https://www.fedlex.admin.ch/eli/cc/1994/2092_2092_2092/de | N19: geprüft · OK | O19: Ergänzung · hoch
A20: Bund | B20: Q2 | C20: Verordnung | D20: Verordnung über den Schutz der Amphibienlaichgebiete von nationaler Bedeutung (Amphibienlaichgebiete-Verordnung; AlgV) | E20: SR 451.34 | F20: Erlass 15.06.2001; konsolidierte Fassung (Fedlex) | G20: Bund (BAFU) | H20: öffentlich | I20: gilt | J20: gilt | K20: gilt | L20: Rechtsgrundlage Bundesinventar: Amphibienlaichgebiete | M20: https://www.fedlex.admin.ch/eli/cc/2001/328/de | N20: geprüft · OK | O20: Ergänzung · hoch
A21: Bund | B21: Q2 | C21: Verordnung | D21: Verordnung über den Schutz der Moorlandschaften von besonderer Schönheit und von nationaler Bedeutung (Moorlandschaftsverordnung) | E21: SR 451.35 | F21: Erlass 01.05.1996; konsolidierte Fassung (Fedlex) | G21: Bund (BAFU) | H21: öffentlich | I21: gilt | J21: gilt | K21: gilt | L21: Rechtsgrundlage Bundesinventar: Moorlandschaften | M21: https://www.fedlex.admin.ch/eli/cc/1996/1839_1839_1839/de | N21: geprüft · OK | O21: Ergänzung · hoch
A22: Bund | B22: Q2 | C22: Verordnung | D22: Verordnung über die Pärke von nationaler Bedeutung (Pärkeverordnung, PäV) | E22: SR 451.36 | F22: Erlass 07.11.2007; konsolidierte Fassung (Fedlex) | G22: Bund (BAFU) | H22: öffentlich | I22: gilt | J22: gilt | K22: gilt | L22: Rechtsgrundlage Bundesinventar: Pärke von nationaler Bedeutung | M22: https://www.fedlex.admin.ch/eli/cc/2007/743/de | N22: geprüft · OK | O22: Ergänzung · hoch
A23: Bund | B23: Q2 | C23: Verordnung | D23: Verordnung über den Schutz der Trockenwiesen und -weiden von nationaler Bedeutung (Trockenwiesenverordnung, TwwV) | E23: SR 451.37 | F23: Erlass 13.01.2010; konsolidierte Fassung (Fedlex) | G23: Bund (BAFU) | H23: öffentlich | I23: gilt | J23: gilt | K23: gilt | L23: Rechtsgrundlage Bundesinventar: Trockenwiesen und -weiden | M23: https://www.fedlex.admin.ch/eli/cc/2010/38/de | N23: geprüft · OK | O23: Ergänzung · hoch
A24: Bund | B24: Q2 | C24: Gesetz | D24: Gewässerschutzgesetz (GSchG) | E24: SR 814.20 | F24: konsolidierte Fassung (Fedlex); GSchV Stand 01.08.2025 | G24: Bund (BAFU) | H24: öffentlich | I24: gilt | J24: gilt | K24: gilt | L24: Gewässerschutz, Gewässerraum, Restwasser, Grundwasserschutz | M24: https://www.fedlex.admin.ch/eli/cc/1992/1860_1860_1860/de | N24: geprüft · OK | O24: Katalog · hoch
A25: Bund | B25: Q2 | C25: Gesetz | D25: Gewässerschutzverordnung (GSchV) | E25: SR 814.201 | F25: 01.08.2025 (Fassung lt. Suchtreffer) | G25: Bund (BAFU) | H25: öffentlich | I25: gilt | J25: gilt | K25: gilt | L25: Entwässerungsplanung (Art. 4/5: regionale und kommunale Entwässerungsplanung), Gewässerraum | M25: https://www.fedlex.admin.ch/eli/cc/1998/2863_2863_2863/de | N25: geprüft · OK | O25: Ergänzung · hoch | P25: Art. 5 GSchV = Grundlage GEP
A26: Bund | B26: Q2 | C26: Gesetz | D26: Waldgesetz (WaG) | E26: SR 921.0 | F26: konsolidierte Fassung (Fedlex) | G26: Bund (BAFU) | H26: öffentlich | I26: gilt | J26: gilt | K26: gilt | L26: Waldschutz, Waldabstand, Rodungsverbot | M26: https://www.fedlex.admin.ch/eli/cc/1992/2521_2521_2521/de | N26: geprüft · OK | O26: Katalog · hoch
A27: Bund | B27: Q2 | C27: Gesetz | D27: Waldverordnung (WaV) | E27: SR 921.01 | F27: konsolidierte Fassung (Fedlex) | G27: Bund (BAFU) | H27: öffentlich | I27: gilt | J27: gilt | K27: gilt | L27: Vollzug WaG | M27: https://www.fedlex.admin.ch/eli/cc/1992/2538_2538_2538/de | N27: geprüft · OK | O27: Ergänzung · hoch
A28: Bund | B28: Q2 | C28: Gesetz | D28: Jagdgesetz (JSG) | E28: SR 922.0 | F28: konsolidierte Fassung (Fedlex) | G28: Bund (BAFU) | H28: öffentlich | I28: gilt | J28: gilt | K28: gilt | L28: Wildtierschutz, Banngebiete, Wildtierkorridore | M28: https://www.fedlex.admin.ch/eli/cc/1988/506_506_506/de | N28: geprüft · OK | O28: Ergänzung · hoch
A29: Bund | B29: Q2 | C29: Gesetz | D29: Bundesgesetz über die Fischerei (BGF) | E29: SR 923.0 | F29: konsolidierte Fassung (Fedlex) | G29: Bund (BAFU) | H29: öffentlich | I29: gilt | J29: gilt | K29: gilt | L29: Fischereischutz, Lebensräume, Gewässer | M29: https://www.fedlex.admin.ch/eli/cc/1991/2259_2259_2259/de | N29: geprüft · OK | O29: Ergänzung · hoch
A30: Bund | B30: Q3 / Q4 | C30: Gesetz | D30: Umweltschutzgesetz (USG) | E30: SR 814.01 | F30: konsolidierte Fassung (Fedlex) | G30: Bund (BAFU) | H30: öffentlich | I30: gilt | J30: gilt | K30: gilt | L30: Umweltbelastungen, Emissionen, Lärm, Boden, Störfall | M30: https://www.fedlex.admin.ch/eli/cc/1984/1122_1122_1122/de | N30: geprüft · OK | O30: Katalog · hoch
A31: Bund | B31: Q3 | C31: Gesetz | D31: Energiegesetz (EnG) | E31: SR 730.0 | F31: konsolidierte Fassung (Fedlex) | G31: Bund (BFE) | H31: öffentlich | I31: gilt | J31: gilt | K31: gilt | L31: Bundesrechtliche Energieanforderungen; Gebäudestandards primär kantonal | M31: https://www.fedlex.admin.ch/eli/cc/2017/762/de | N31: geprüft · OK | O31: Katalog · hoch
A32: Bund | B32: Q3 | C32: Gesetz | D32: Energieverordnung (EnV) | E32: SR 730.01 | F32: konsolidierte Fassung (Fedlex) | G32: Bund (BFE) | H32: öffentlich | I32: gilt | J32: gilt | K32: gilt | L32: Vollzug EnG | M32: https://www.fedlex.admin.ch/eli/cc/2017/763/de | N32: geprüft · OK | O32: Ergänzung · hoch
A33: Bund | B33: Q3 | C33: Gesetz | D33: CO₂-Gesetz | E33: SR 641.71 | F33: konsolidierte Fassung (Fedlex) | G33: Bund (BAFU) | H33: öffentlich | I33: gilt | J33: gilt | K33: gilt | L33: Reduktionsziele, Gebäudeprogramm, Lenkungsabgabe | M33: https://www.fedlex.admin.ch/eli/cc/2012/855/de | N33: geprüft · OK | O33: Ergänzung · hoch
A34: Bund | B34: Q3 | C34: Gesetz | D34: CO₂-Verordnung | E34: SR 641.711 | F34: konsolidierte Fassung (Fedlex) | G34: Bund (BAFU) | H34: öffentlich | I34: gilt | J34: gilt | K34: gilt | L34: Reduktionsziele, Gebäudeprogramm, Lenkungsabgabe | M34: https://www.fedlex.admin.ch/eli/cc/2012/856/de | N34: geprüft · OK | O34: Ergänzung · hoch
A35: Bund | B35: Q3 | C35: Gesetz | D35: Klima- und Innovationsgesetz (KlG) | E35: SR 814.310 | F35: konsolidierte Fassung (Fedlex) | G35: Bund (BAFU) | H35: öffentlich | I35: gilt | J35: gilt | K35: gilt | L35: Klimaziel Netto-Null 2050, Zwischenziele, Vorbildfunktion | M35: https://www.fedlex.admin.ch/eli/cc/2023/655/de | N35: geprüft · OK | O35: Katalog · hoch
A36: Bund | B36: Q3 | C36: Gesetz | D36: Bundesgesetz über sichere Stromversorgung mit erneuerbaren Energien (Mantelerlass; Änderung EnG/StromVG) | E36: AS 2024 679 | F36: in Kraft 2025 | G36: Bund (BFE) | H36: öffentlich | I36: gilt | J36: gilt | K36: gilt | L36: Ausbauziele Erneuerbare, Solaranlagen, Raumplanungsbezüge | M36: https://www.fedlex.admin.ch/eli/oc/2024/679/de | N36: geprüft · OK | O36: Ergänzung · hoch | P36: Änderungserlass (Mantelerlass) ohne eigene SR-Nummer; die Änderungen sind in EnG und StromVG konsolidiert
A37: Bund | B37: Q4 | C37: Gesetz | D37: Wasserbaugesetz (WBG) | E37: SR 721.100 | F37: konsolidierte Fassung (Fedlex) | G37: Bund (BAFU) | H37: öffentlich | I37: gilt | J37: gilt | K37: gilt | L37: Hochwasserschutz, Gefahrenkarten, Raumbedarf Gewässer | M37: https://www.fedlex.admin.ch/eli/cc/1993/234_234_234/de | N37: geprüft · OK | O37: Ergänzung · hoch
A38: Bund | B38: Q4 | C38: Gesetz | D38: Wasserbauverordnung (WBV) | E38: SR 721.100.1 | F38: konsolidierte Fassung (Fedlex) | G38: Bund (BAFU) | H38: öffentlich | I38: gilt | J38: gilt | K38: gilt | L38: Vollzug WBG | M38: https://www.fedlex.admin.ch/eli/cc/2025/450/de | N38: geprüft · OK | O38: Ergänzung · hoch
A39: Bund | B39: Q6 | C39: Gesetz | D39: Binnenmarktgesetz (BGBM) | E39: SR 943.02 | F39: konsolidierte Fassung (Fedlex) | G39: Bund (WEKO) | H39: öffentlich | I39: gilt | J39: gilt | K39: gilt | L39: Marktzugang, Vergabegrundsätze für Kantone/Gemeinden | M39: https://www.fedlex.admin.ch/eli/cc/1996/1738_1738_1738/de | N39: geprüft · OK | O39: Ergänzung · hoch
A40: Bund | B40: Q6 | C40: Gesetz | D40: Bundesgesetz über das öffentliche Beschaffungswesen (BöB) | E40: SR 172.056.1 | F40: konsolidierte Fassung (Fedlex) | G40: Bund (BBL / KBOB) | H40: öffentlich | I40: n. a. | J40: n. a. | K40: n. a. | L40: Gilt nur für Bundesvergaben – für Gemeinden nur Orientierung | M40: https://www.fedlex.admin.ch/eli/cc/2020/126/de | N40: geprüft · OK | O40: Ergänzung · hoch | P40: Gemeinden unterstehen kantonalem Recht / IVöB
A41: Bund | B41: Q3 / Q4 | C41: Verordnung | D41: Lärmschutz-Verordnung (LSV) | E41: SR 814.41 | F41: konsolidierte Fassung (Fedlex) | G41: Bund (BAFU) | H41: öffentlich | I41: gilt | J41: gilt | K41: gilt | L41: Lärmgrenzwerte, Empfindlichkeitsstufen | M41: https://www.fedlex.admin.ch/eli/cc/1987/338_338_338/de | N41: geprüft · OK | O41: Ergänzung · hoch
...

Sheet 2_Q2_Landschaft
A1: 2 · Q2 Landschaft, Kulturland und Biodiversität – Dokumente, Inventare, Geodaten
A2: Öffentliche Quellen je Ebene; nicht öffentliche Daten sind separat markiert (orange). | Gemeinden: Münchenstein (BL), Wil (SG), Seelisberg (UR) | Recherchestand: 14.10.2026
A3: Status: gilt / belegt = Beleg mit Link vorhanden · belegt – Betroffenheit offen = Layer/Inventar existiert, Lage in der Gemeinde per GIS zu prüfen (Blatt 7) · keine Regelung (geprüft) = Ebene regelt nichts, übergeordnetes Recht gilt · nicht belegt (Recherche offen) = bisher kein Beleg · Datenanfrage = nicht öffentlich · n. a. = andere Gebietskörperschaft
A5: Ebene | B5: Q | C5: Typ | D5: Bezeichnung | E5: Referenz (SR/SGS/RB) | F5: Stand | G5: Zuständige Stelle | H5: Zugang | I5: Münchenstein (BL) | J5: Wil (SG) | K5: Seelisberg (UR) | L5: Inhalt / Mindestanforderung | M5: Link / Quelle | N5: Link-Status | O5: Herkunft · Confidence | P5: Prüfnachweis / Hinweis
A6: BUND (gilt für alle drei Gemeinden)
A7: Bund | B7: Q2 | C7: Inventar / Layer | D7: BLN – Bundesinventar der Landschaften und Naturdenkmäler | E7: VBLN | F7: – | G7: BAFU / swisstopo | H7: öffentlich | I7: belegt – Betroffenheit offen | J7: belegt – Betroffenheit offen | K7: belegt – Betroffenheit offen | L7: Landschaften von nationaler Bedeutung; Bundesaufgaben-Bindung | M7: https://map.geo.admin.ch/#/map?lang=de&center=2660000,1190000&z=1&bgLayer=ch.swisstopo.pixelkarte-grau&layers=ch.bafu.bundesinventare-bln | N7: geprüft · korrigiert | O7: Ergänzung · mittel | P7: Seelisberg: Lage im BLN-Gebiet Vierwaldstättersee wahrscheinlich → verifizieren | Linkprüfung 14.10.2026: Hyperlink führte nur auf https://map.geo.admin.ch/ statt auf den angezeigten Link. Alter Link: https://map.geo.admin.ch/#/map?lang=de&center=2660000,1190000&z=1&bgLayer=ch.swisstopo.pixelkarte-grau&layers=ch.bafu.bundesinventare-bln
A8: Bund | B8: Q2 | C8: Inventar / Layer | D8: Bundesinventare Moore, Moorlandschaften, Auen, Amphibienlaichgebiete, Trockenwiesen/-weiden (TWW) | E8: NHG / Inventarverordnungen | F8: – | G8: BAFU | H8: öffentlich | I8: belegt – Betroffenheit offen | J8: belegt – Betroffenheit offen | K8: belegt – Betroffenheit offen | L8: Biotope von nationaler Bedeutung, Pufferzonen | M8: https://map.geo.admin.ch/#/map?lang=de&center=2660000,1190000&z=1&bgLayer=ch.swisstopo.pixelkarte-grau&layers=ch.bafu.bundesinventare-hochmoore | N8: geprüft · korrigiert | O8: Ergänzung · mittel | P8: Betroffenheit je Gemeinde per Geodaten-Overlay prüfen | Linkprüfung 14.10.2026: Hyperlink führte nur auf https://map.geo.admin.ch/ statt auf den angezeigten Link. Alter Link: https://map.geo.admin.ch/#/map?lang=de&center=2660000,1190000&z=1&bgLayer=ch.swisstopo.pixelkarte-grau&layers=ch.bafu.bundesinventare-hochmoore
A9: Bund | B9: Q2 | C9: Inventar / Layer | D9: Jagdbanngebiete, Wasser- und Zugvogelreservate, Smaragd-Gebiete | E9: JSG | F9: – | G9: BAFU | H9: öffentlich | I9: belegt – Betroffenheit offen | J9: belegt – Betroffenheit offen | K9: belegt – Betroffenheit offen | L9: Wildtier- und Vogelschutz | M9: https://map.geo.admin.ch/#/map?lang=de&center=2660000,1190000&z=1&bgLayer=ch.swisstopo.pixelkarte-grau&layers=ch.bafu.bundesinventare-jagdbanngebiete | N9: geprüft · korrigiert | O9: Ergänzung · mittel | P9: Linkprüfung 14.10.2026: Hyperlink führte nur auf https://map.geo.admin.ch/ statt auf den angezeigten Link. Alter Link: https://map.geo.admin.ch/#/map?lang=de&center=2660000,1190000&z=1&bgLayer=ch.swisstopo.pixelkarte-grau&layers=ch.bafu.bundesinventare-jagdbanngebiete
A10: Bund | B10: Q2 | C10: Layer | D10: Wildtierkorridore / Landschaftsverbindungen (überregional) | E10: – | F10: – | G10: BAFU / ASTRA | H10: öffentlich | I10: belegt – Betroffenheit offen | J10: belegt – Betroffenheit offen | K10: belegt – Betroffenheit offen | L10: Vernetzung, Konfliktpotenzial bei Siedlungsentwicklung | M10: https://map.geo.admin.ch/#/map?lang=de&center=2660000,1190000&z=1&bgLayer=ch.swisstopo.pixelkarte-grau&layers=ch.bafu.fauna-wildtierkorridor_national | N10: geprüft · korrigiert | O10: Ergänzung · mittel | P10: Linkprüfung 14.10.2026: Layer-ID ch.bafu.fauna-wildtierkorridore_national existiert nicht, richtig: ch.bafu.fauna-wildtierkorridor_national; Hyperlink führte nur auf https://map.geo.admin.ch/ statt auf den angezeigten Link. Alter Link: https://map.geo.admin.ch/#/map?lang=de&center=2660000,1190000&z=1&bgLayer=ch.swisstopo.pixelkarte-grau&layers=ch.bafu.fauna-wildtierkorridore_national
A11: Bund | B11: Q2 | C11: Layer | D11: Wald: Waldareal, Waldreservate, Schutzwald (Bundesgeodaten) | E11: WaG | F11: – | G11: BAFU | H11: öffentlich | I11: belegt – Betroffenheit offen | J11: belegt – Betroffenheit offen | K11: belegt – Betroffenheit offen | L11: Waldabstand, Rodungsrestriktion | M11: https://map.geo.admin.ch/#/map?lang=de&center=2660000,1190000&z=1&bgLayer=ch.swisstopo.pixelkarte-grau&layers=ch.bafu.waldreservate | N11: geprüft · korrigiert | O11: Ergänzung · mittel | P11: Linkprüfung 14.10.2026: Hyperlink führte nur auf https://map.geo.admin.ch/ statt auf den angezeigten Link. Alter Link: https://map.geo.admin.ch/#/map?lang=de&center=2660000,1190000&z=1&bgLayer=ch.swisstopo.pixelkarte-grau&layers=ch.bafu.waldreservate
A12: Bund | B12: Q2 | C12: Dokument | D12: Sachplan Fruchtfolgeflächen (SP FFF, 2020) und kantonale Mindestkontingente | E12: RPV Art. 26–30 | F12: 2020 | G12: ARE | H12: öffentlich | I12: belegt | J12: belegt | K12: belegt | L12: Kontingent je Kanton; Beanspruchung nur mit Kompensation | M12: https://www.are.admin.ch | N12: Einstiegsseite · geprüft · nur Einstiegsseite | O12: Ergänzung · mittel
A13: Bund | B13: Q2 | C13: Dokument | D13: Landschaftskonzept Schweiz / Strategie Biodiversität Schweiz / Aktionsplan | E13: – | F13: – | G13: BAFU | H13: öffentlich | I13: belegt | J13: belegt | K13: belegt | L13: Strategische Leitplanken für Landschaft und Biodiversität | M13: https://www.bafu.admin.ch | N13: Einstiegsseite · geprüft · nur Einstiegsseite | O13: Ergänzung · mittel
A14: Bund | B14: Q2 | C14: Layer | D14: Gewässernetz, Gewässerschutzkarten, Grundwasserschutzzonen (Bundesdienste) | E14: GSchG | F14: – | G14: BAFU / swisstopo | H14: öffentlich | I14: belegt – Betroffenheit offen | J14: belegt – Betroffenheit offen | K14: belegt – Betroffenheit offen | L14: Gewässerraum, Grundwasserschutz | M14: https://map.geo.admin.ch | N14: geprüft · korrigiert | O14: Ergänzung · mittel | P14: Linkprüfung 14.10.2026: Hyperlink führte nur auf https://map.geo.admin.ch/ statt auf den angezeigten Link. Alter Link: https://map.geo.admin.ch
A15: Bund | B15: Q2 | C15: Layer | D15: Arealstatistik / Bodenbedeckung / Landschaftstypologie | E15: – | F15: – | G15: BFS / ARE | H15: öffentlich | I15: belegt – Betroffenheit offen | J15: belegt – Betroffenheit offen | K15: belegt – Betroffenheit offen | L15: Flächenbilanz, Siedlungsflächenverbrauch | M15: https://www.are.admin.ch | N15: Einstiegsseite · geprüft · nur Einstiegsseite | O15: Ergänzung · mittel
A16: KANTON BASEL-LANDSCHAFT → Münchenstein
A17: Kanton BL | B17: Q2 | C17: Inventar / Layer | D17: Kantonale Schutzinventare / Fruchtfolgeflächen BL | E17: – | F17: Katalog: kein Stand | G17: Kanton BL (Raumplanung / ARP) | H17: öffentlich | I17: belegt | J17: n. a. | K17: n. a. | L17: Schutzobjekte, Kulturlandrestriktionen standortspezifisch erheben (GIS-Overlay, Flächenbilanz) | M17: https://arp-daten.bl.ch/ | N17: Kataster · geprüft · nur Einstiegsseite | O17: Katalog · hoch | P17: Stand ergänzen; FFF und Schutzinventare separat ausweisen
A18: Kanton BL | B18: Q2 | C18: Konzept / Layer | D18: Inventar der geschützten Naturobjekte und Natur- und Landschaftsschutzkonzept BL | E18: – | F18: – | G18: Kanton BL | H18: öffentlich | I18: nicht belegt (Recherche offen) | J18: n. a. | K18: n. a. | L18: Biotopvernetzung, Landschaftsqualität | M18: https://geoview.bl.ch | N18: Kataster · geprüft · nur Einstiegsseite | O18: Ergänzung · tief | P18: Rechtsgrundlage: § 8 und § 12 NLG (SGS 790); Naturschutzgebiets-Verordnungen verweisen auf Geoportal BL
A19: KANTON ST. GALLEN → Wil
A20: Kanton SG | B20: Q2 | C20: Inventar / Layer | D20: Kantonale Natur-/Landschaftsschutzgebiete, Biotope, Vernetzung SG | E20: – | F20: – | G20: Kanton SG | H20: öffentlich | I20: n. a. | J20: nicht belegt (Recherche offen) | K20: n. a. | L20: Im Katalog keine Kantonsebene für Q2 | M20: https://www.geoportal.ch/ktsg | N20: Kataster · geprüft · manuell prüfen | O20: Ergänzung · tief | P20: Rechtsgrundlage vorhanden (Naturschutzverordnung sGS 671.1, Schutzverordnungen der Gemeinden nach Art. 98 ff. PBG); konkrete kantonale Inventar-/Layerliste noch nicht gesichtet | Linkprüfung 14.10.2026: erreichbar, Bezeichnung im Dokument nicht gefunden («Geoportal»)
A21: Kanton SG | B21: Q2 | C21: Layer | D21: Fruchtfolgeflächen (FFF) SG | E21: – | F21: – | G21: Kanton SG | H21: öffentlich | I21: n. a. | J21: nicht belegt (Recherche offen) | K21: n. a. | L21: FFF-Inventar/Kontingent für Wil prüfen | M21: https://www.geoportal.ch/ktsg | N21: Kataster · geprüft · manuell prüfen | O21: Ergänzung · tief | P21: Rechtsgrundlage vorhanden (Naturschutzverordnung sGS 671.1, Schutzverordnungen der Gemeinden nach Art. 98 ff. PBG); konkrete kantonale Inventar-/Layerliste noch nicht gesichtet | Linkprüfung 14.10.2026: erreichbar, Bezeichnung im Dokument nicht gefunden («Geoportal»)
A22: KANTON URI → Seelisberg
A23: Kanton UR | B23: Q2 | C23: Inventar / Layer | D23: Schutzinventare Uri (Schutzobjekte, Kulturlandrestriktionen) | E23: – | F23: 20.03.2026 | G23: Kanton UR | H23: öffentlich | I23: n. a. | J23: n. a. | K23: belegt | L23: Standortspezifisch erheben (GIS-Overlay, Flächenbilanz) | M23: https://geo.ur.ch | N23: Kataster · geprüft · nur Einstiegsseite | O23: Katalog · hoch
A24: Kanton UR | B24: Q2 | C24: Layer | D24: Fruchtfolgeflächen, Natur-/Landschaftsinventare Uri | E24: – | F24: – | G24: Kanton UR | H24: öffentlich | I24: n. a. | J24: n. a. | K24: nicht belegt (Recherche offen) | L24: Landwirtschaft/FFF; Vernetzung | M24: https://geo.ur.ch | N24: Muster · geprüft · nur Einstiegsseite | O24: Ergänzung · tief
A25: GEMEINDE MÜNCHENSTEIN (BL)
A26: Gde Münchenstein | B26: Q2 | C26: Plan / Reglement | D26: Zonenvorschriften Siedlung | E26: – | F26: 25.02.2025 | G26: Gde Münchenstein | H26: öffentlich | I26: belegt | J26: n. a. | K26: n. a. | L26: Schutzflächen, Gewässerräume, Grünstrukturen prüfen (Schutzplan und GIS) | M26: https://oereblex.bl.ch/api/attachments/22718 | N26: manuell geprüft · OK | O26: Katalog · hoch | P26: Manuell geprüft 14.10.2026: Link (oereblex 22718) = Zonenvorschriften Siedlung, OK. Mehrfach gelistet, weil das Dokument mehrere Q-Dimensionen abdeckt (bisherige Bezeichnung: «Natur- und Landschaftsschutzfestlegungen (Zonenvorschriften)»)
A27: Gde Münchenstein | B27: Q2 | C27: Layer | D27: Geoportal Münchenstein (Nutzungsplanung, Grünstrukturen) | E27: – | F27: – | G27: Gde Münchenstein | H27: öffentlich | I27: nicht belegt (Recherche offen) | J27: n. a. | K27: n. a. | L27: Kommunale Layer | M27: https://www.geoportal.ch/muenchenstein | N27: Muster · geprüft · OK | O27: Ergänzung · tief
A28: GEMEINDE WIL (SG)
A29: Gde Wil | B29: Q2 | C29: Reglement / Plan | D29: Reglement zur Schutzverordnung und Schutzplan | E29: – | F29: 31.08.2022 | G29: Gde Wil | H29: öffentlich | I29: n. a. | J29: belegt | K29: n. a. | L29: Schutzflächen, Gewässerräume, Grünstrukturen prüfen | M29: https://cms.e-mitwirkung.ch/media/wil/Reglement_221013.pdf | N29: Kataster · geprüft · Hinweis | O29: Katalog · hoch | P29: Schutzplan als Geodaten verifizieren | Linkprüfung 14.10.2026: Inhalt passt (Treffer: Schutzverordnung) | PDF ist der Entwurf zur öffentlichen Auflage (13.10.2022), nicht die erlassene Fassung; in der Rechtssammlung Wil (tlex) nicht vorhanden
A30: Gde Wil | B30: Q2 | C30: Layer | D30: Geoportal Wil (Nutzungsplanung, Schutzzonen) | E30: – | F30: – | G30: Gde Wil | H30: öffentlich | I30: n. a. | J30: nicht belegt (Recherche offen) | K30: n. a. | L30: Kommunale Layer | M30: https://www.geoportal.ch/wil_sg | N30: Muster · geprüft · OK | O30: Ergänzung · tief
A31: GEMEINDE SEELISBERG (UR)
A32: Gde Seelisberg | B32: Q2 | C32: Inventar | D32: Kommunales Schutzinventar Seelisberg (Inventarliste) | E32: – | F32: 20.12.2022 | G32: Gde Seelisberg | H32: öffentlich | I32: n. a. | J32: n. a. | K32: belegt | L32: Schutzflächen, Gewässerräume, Grünstrukturen prüfen (Schutzplan und GIS) | M32: https://www.ur.ch/_docn/385540/Inventarliste_Seelisberg_Website.pdf | N32: Kataster · geprüft · OK | O32: Katalog · hoch
A33: Gde Seelisberg | B33: Q2 | C33: Reglement | D33: BZO Art. 20–23 Schutzbestimmungen | E33: – | F33: 01.01.2015 | G33: Gde Seelisberg | H33: öffentlich | I33: n. a. | J33: n. a. | K33: belegt | L33: Schutzbestimmungen Landschaft/Natur | M33: https://www.seelisberg.ch/files/pdf/Bau-und-Zonenordnung-Seelisberg.pdf | N33: Kataster · geprüft · OK | O33: Katalog · hoch
A34: GEMEINDEN – nicht öffentliche Daten (Lieferung durch Gemeinde / Kanton)
A35: Gemeinden (alle) | B35: Q2 | C35: Datensatz | D35: Detaillierte Biotop-/Artenfunddaten (z. B. Info Species), Naturschutzverträge, BFF-Bewirtschaftungsverträge | E35: – | F35: – | G35: Kanton / Fachstellen | H35: nicht öffentlich | I35: Datenanfrage (nicht öffentlich) | J35: Datenanfrage (nicht öffentlich) | K35: Datenanfrage (nicht öffentlich) | L35: Standortgenaue Artdaten und Verträge nur eingeschränkt zugänglich | M35: https://www.fedlex.admin.ch | N35: Einstiegsseite · geprüft · nur Einstiegsseite | O35: Ergänzung · mittel | P35: Existenz: hoch (Kanton führt Biotop-/Artdaten und Bewirtschaftungsverträge; NHG Art. 18b). Zugang: Auskunft Fachstelle, teils gesperrt
A36: Gemeinden (alle) | B36: Q2 | C36: Datensatz | D36: Kommunale Pflege-/Unterhaltskonzepte Grünräume, Baumkataster | E36: – | F36: – | G36: Gemeinde | H36: nicht öffentlich | I36: Datenanfrage (nicht öffentlich) | J36: Datenanfrage (nicht öffentlich) | K36: Datenanfrage (nicht öffentlich) | L36: Grünraumbewirtschaftung | M36: https://www.fedlex.admin.ch | N36: Einstiegsseite · geprüft · nur Einstiegsseite | O36: Ergänzung · tief | P36: Existenz: unbekannt (fakultativ, Gemeindegrösse abhängig)

Sheet 3_Q3_Klima_Energie
A1: 3 · Q3 Klimaschutz, Energie und Ressourcen – Dokumente, Inventare, Geodaten
A2: Kontext Raumentwicklung, Städteplanung, Bauvorschriften. | Gemeinden: Münchenstein (BL), Wil (SG), Seelisberg (UR) | Recherchestand: 14.10.2026
A3: Status: gilt / belegt = Beleg mit Link vorhanden · belegt – Betroffenheit offen = Layer/Inventar existiert, Lage in der Gemeinde per GIS zu prüfen (Blatt 7) · keine Regelung (geprüft) = Ebene regelt nichts, übergeordnetes Recht gilt · nicht belegt (Recherche offen) = bisher kein Beleg · Datenanfrage = nicht öffentlich · n. a. = andere Gebietskörperschaft
A5: Ebene | B5: Q | C5: Typ | D5: Bezeichnung | E5: Referenz (SR/SGS/RB) | F5: Stand | G5: Zuständige Stelle | H5: Zugang | I5: Münchenstein (BL) | J5: Wil (SG) | K5: Seelisberg (UR) | L5: Inhalt / Mindestanforderung | M5: Link / Quelle | N5: Link-Status | O5: Herkunft · Confidence | P5: Prüfnachweis / Hinweis
A6: BUND (gilt für alle drei Gemeinden)
A7: Bund | B7: Q3 | C7: Strategie | D7: Langfristige Klimastrategie der Schweiz 2050; Energieperspektiven 2050+ | E7: – | F7: – | G7: BAFU / BFE | H7: öffentlich | I7: belegt | J7: belegt | K7: belegt | L7: Zielpfade Netto-Null, Gebäude- und Wärmesektor | M7: https://www.bafu.admin.ch | N7: Einstiegsseite · geprüft · nur Einstiegsseite | O7: Ergänzung · mittel
A8: Bund | B8: Q3 | C8: Layer | D8: Sonnendach.ch / Sonnenfassade.ch (Solarpotenzial Dächer und Fassaden) | E8: – | F8: – | G8: BFE | H8: öffentlich | I8: belegt – Betroffenheit offen | J8: belegt – Betroffenheit offen | K8: belegt – Betroffenheit offen | L8: Solarpotenzial je Gebäude | M8: https://map.geo.admin.ch/#/map?lang=de&center=2660000,1190000&z=1&bgLayer=ch.swisstopo.pixelkarte-grau&layers=ch.bfe.solarenergie-eignung-daecher | N8: geprüft · korrigiert | O8: Ergänzung · hoch | P8: Linkprüfung 14.10.2026: Hyperlink führte nur auf https://map.geo.admin.ch/ statt auf den angezeigten Link. Alter Link: https://map.geo.admin.ch/#/map?lang=de&center=2660000,1190000&z=1&bgLayer=ch.swisstopo.pixelkarte-grau&layers=ch.bfe.solarenergie-eignung-daecher
A9: Bund | B9: Q3 | C9: Layer | D9: Geothermie-/Erdwärmesonden-Eignung, Windatlas, Wärmenetz-/Fernwärme-Potenzial | E9: – | F9: – | G9: BFE / swisstopo | H9: öffentlich | I9: nicht belegt (Recherche offen) | J9: nicht belegt (Recherche offen) | K9: nicht belegt (Recherche offen) | L9: Energieträger-Potenziale (Wärmeplanung) | M9: https://map.geo.admin.ch | N9: geprüft · korrigiert | O9: Ergänzung · tief | P9: Verfügbarkeit je Layer prüfen | Linkprüfung 14.10.2026: Hyperlink führte nur auf https://map.geo.admin.ch/ statt auf den angezeigten Link. Alter Link: https://map.geo.admin.ch
A10: Bund | B10: Q3 | C10: Statistik | D10: Gebäude- und Wohnungsregister (GWR): Heizungsart, Energieträger, Baujahr | E10: – | F10: – | G10: BFS | H10: öffentlich | I10: belegt | J10: belegt | K10: belegt | L10: Energieträger- und Gebäudebestand je Gemeinde | M10: https://map.geo.admin.ch/#/map?lang=de&center=2660000,1190000&z=1&bgLayer=ch.swisstopo.pixelkarte-grau&layers=ch.bfs.gebaeude_wohnungs_register | N10: geprüft · korrigiert | O10: Ergänzung · hoch | P10: Linkprüfung 14.10.2026: Hyperlink führte nur auf https://map.geo.admin.ch/ statt auf den angezeigten Link. Alter Link: https://map.geo.admin.ch/#/map?lang=de&center=2660000,1190000&z=1&bgLayer=ch.swisstopo.pixelkarte-grau&layers=ch.bfs.gebaeude_wohnungs_register
A11: Bund | B11: Q3 | C11: Statistik | D11: Treibhausgasinventar / Gemeinde-Energie- und CO₂-Bilanzen | E11: – | F11: – | G11: BAFU / BFE | H11: teilw. öffentlich | I11: nicht belegt (Recherche offen) | J11: nicht belegt (Recherche offen) | K11: nicht belegt (Recherche offen) | L11: Ausgangslage für CO₂-Absenkpfad | M11: https://www.bafu.admin.ch | N11: Einstiegsseite · geprüft · nur Einstiegsseite | O11: Ergänzung · tief
A12: Bund | B12: Q3 | C12: Norm / Standard | D12: MuKEn 2014 (Mustervorschriften der Kantone), SIA 2040, SIA 2032 (Graue Energie), SNBS Hochbau, Minergie | E12: – | F12: – | G12: EnDK / SIA / NNBS | H12: kostenpflichtig (Norm) | I12: belegt | J12: belegt | K12: belegt | L12: Referenzrahmen Gebäudestandard, graue Energie, Ressourcen | M12: https://www.sia.ch | N12: Einstiegsseite · geprüft · nur Einstiegsseite | O12: Ergänzung · mittel | P12: Normen kostenpflichtig; Anwendung gemeindespezifisch
A13: KANTON BASEL-LANDSCHAFT → Münchenstein
A14: Kanton BL | B14: Q3 | C14: Gesetz | D14: Energiegesetz BL (EnG BL) | E14: SGS 490 | F14: 01.03.2025 | G14: Kanton BL | H14: öffentlich | I14: belegt | J14: n. a. | K14: n. a. | L14: Gebäudeenergie, Wärmeerzeugung, Solarpflichten | M14: https://bl.clex.ch/app/de/texts_of_law/490 | N14: Kataster · geprüft · OK | O14: Katalog · hoch
A15: Kanton BL | B15: Q3 | C15: Konzept / Layer | D15: Kantonale Energieplanung BL, Energie-/Klimastrategie, Solar-/Wärmepotenzial im Geoportal | E15: – | F15: – | G15: Kanton BL | H15: öffentlich | I15: nicht belegt (Recherche offen) | J15: n. a. | K15: n. a. | L15: Kantonale Zielpfade, Planungsgrundlagen | M15: https://geoview.bl.ch | N15: Muster · geprüft · nur Einstiegsseite | O15: Ergänzung · tief
A16: KANTON ST. GALLEN → Wil
A17: Kanton SG | B17: Q3 | C17: Gesetz | D17: Energiegesetz SG | E17: sGS 741.1 | F17: 01.07.2021 | G17: Kanton SG | H17: öffentlich | I17: n. a. | J17: belegt | K17: n. a. | L17: Gebäudeenergie, Wärmeerzeugung, Solarpflichten | M17: https://www.gesetzessammlung.sg.ch/app/de/texts_of_law/741.1 | N17: Kataster · geprüft · OK | O17: Katalog · hoch
A18: Kanton SG | B18: Q3 | C18: Konzept / Layer | D18: Kantonales Energiekonzept SG, Wärme-/Solarpotenzial im Geoportal | E18: – | F18: – | G18: Kanton SG | H18: öffentlich | I18: n. a. | J18: nicht belegt (Recherche offen) | K18: n. a. | L18: Kantonale Zielpfade, Planungsgrundlagen | M18: https://www.geoportal.ch/ktsg | N18: Muster · geprüft · OK | O18: Ergänzung · tief
A19: KANTON URI → Seelisberg
A20: Kanton UR | B20: Q3 | C20: Gesetz | D20: Kantonale Energiegesetzgebung Uri | E20: RB 40.7211 | F20: Katalog: 01.01.2000 | G20: Kanton UR | H20: öffentlich | I20: n. a. | J20: n. a. | K20: belegt | L20: Gebäudeenergie, Wärmeerzeugung, Solarpflichten | M20: https://rechtsbuch.ur.ch/app/de/texts_of_law/40.7211 | N20: Kataster · geprüft · OK | O20: Katalog · hoch | P20: Aktuelle Fassung prüfen | verlinkte Nummer 40.7211 ist «Energiegesetz des Kantons Uri (EnG)»; Bezeichnung lautet anders
A21: Kanton UR | B21: Q3 | C21: Konzept | D21: Energie-/Klimastrategie Uri, kantonale Energieplanung | E21: – | F21: – | G21: Kanton UR | H21: öffentlich | I21: n. a. | J21: n. a. | K21: nicht belegt (Recherche offen) | L21: Kantonale Zielpfade | M21: https://www.ur.ch | N21: Einstiegsseite · geprüft · nur Einstiegsseite | O21: Ergänzung · tief
A22: GEMEINDE MÜNCHENSTEIN (BL)
A23: Gde Münchenstein | B23: Q3 | C23: Plan / Reglement | D23: Zonenvorschriften Siedlung | E23: – | F23: 25.02.2025 | G23: Gde Münchenstein | H23: öffentlich | I23: belegt | J23: n. a. | K23: n. a. | L23: Allfällige verbindliche Anschluss- oder Versorgungsregeln (Energie-/Wärmeplanabgleich) | M23: https://oereblex.bl.ch/api/attachments/22718 | N23: manuell geprüft · OK | O23: Katalog · hoch | P23: Manuell geprüft 14.10.2026: Link (oereblex 22718) = Zonenvorschriften Siedlung, OK. Mehrfach gelistet, weil das Dokument mehrere Q-Dimensionen abdeckt (bisherige Bezeichnung: «Kommunale Energieplanung / Wärmeversorgung»)
A24: Gde Münchenstein | B24: Q3 | C24: Label | D24: Energiestadt-Label / kommunale Klimaziele | E24: – | F24: – | G24: Gde Münchenstein | H24: öffentlich | I24: nicht belegt (Recherche offen) | J24: n. a. | K24: n. a. | L24: Energiepolitisches Leitbild | M24: https://www.muenchenstein.ch | N24: Einstiegsseite · geprüft · nur Einstiegsseite | O24: Ergänzung · tief
A25: GEMEINDE WIL (SG)
A26: Gde Wil | B26: Q3 | C26: Programm | D26: Kommunales Klimaprogramm Stadt Wil | E26: – | F26: Katalog: kein Stand | G26: Gde Wil | H26: öffentlich | I26: n. a. | J26: belegt | K26: n. a. | L26: Klimaziele, Massnahmen; Verbindlichkeit prüfen (Programm ≠ Erlass) | M26: https://www.stadtwil.ch/storage/0c6b26d62a364629241b9c9e4535a6b58c82d46aeb166b034ae96c29862a1331 | N26: Kataster · geprüft · OK | O26: Katalog · hoch | P26: Stand ergänzen
A27: Gde Wil | B27: Q3 | C27: Plan / Reglement | D27: Kommunale Energieplanung / Wärmeversorgung | E27: SRS 7.1-1 | F27: 01.03.2021 | G27: Gde Wil | H27: öffentlich | I27: n. a. | J27: belegt | K27: n. a. | L27: Allfällige Anschluss-/Versorgungsregeln (Energie-/Wärmeplanabgleich) | M27: https://wil-sg.tlex.ch/app/de/texts_of_law/7.1-1 | N27: Kataster · geprüft · OK | O27: Katalog · hoch | P27: Link identisch mit Baureglement → eigene Energieplanung separat suchen | Referenz SRS 7.1-1 ist das Baureglement; eine eigene Energieplanung ist in der Rechtssammlung Wil nicht vorhanden
A28: Gde Wil | B28: Q3 | C28: Label | D28: Energiestadt-Label Wil | E28: – | F28: – | G28: Gde Wil | H28: öffentlich | I28: n. a. | J28: nicht belegt (Recherche offen) | K28: n. a. | L28: Energiepolitisches Leitbild | M28: https://www.stadtwil.ch | N28: Einstiegsseite · geprüft · nur Einstiegsseite | O28: Ergänzung · tief
A29: GEMEINDE SEELISBERG (UR)
A30: GEMEINDEN – nicht öffentliche Daten (Lieferung durch Gemeinde / Kanton)
A31: Gemeinden (alle) | B31: Q3 | C31: Datensatz | D31: Energieversorger-Daten (Verbrauch, Netzgebiete, Wärmenetze, Anschlussdichte) | E31: – | F31: – | G31: Energieversorger / Gemeinde | H31: nicht öffentlich | I31: Datenanfrage (nicht öffentlich) | J31: Datenanfrage (nicht öffentlich) | K31: Datenanfrage (nicht öffentlich) | L31: Grundlage Wärmeplanung, Absenkpfad | M31: https://www.fedlex.admin.ch | N31: Einstiegsseite · geprüft · nur Einstiegsseite | O31: Ergänzung · mittel | P31: Existenz: hoch (Versorger je Gemeinde vorhanden). Zugang: Datenschutz/Geschäftsgeheimnis → Anfrage
A32: Gemeinden (alle) | B32: Q3 | C32: Datensatz | D32: Gebäudebezogener Sanierungsstand, Heizungsregister, kommunale Gebäude-Energiebuchhaltung | E32: – | F32: – | G32: Gemeinde / Kanton | H32: nicht öffentlich | I32: Datenanfrage (nicht öffentlich) | J32: Datenanfrage (nicht öffentlich) | K32: Datenanfrage (nicht öffentlich) | L32: Gemeindeeigene Bauten, CO₂-Ausgangslage | M32: https://www.fedlex.admin.ch | N32: Einstiegsseite · geprüft · nur Einstiegsseite | O32: Ergänzung · mittel | P32: Existenz: mittel (Gebäudeprogramm/Feuerungskontrolle vorhanden, Aufbereitung offen)

Sheet 4_Q4_Resilienz
A1: 4 · Q4 Klimaanpassung und Resilienz – Dokumente, Inventare, Geodaten
A2: Kontext Raumentwicklung, Städteplanung, Bauvorschriften. | Gemeinden: Münchenstein (BL), Wil (SG), Seelisberg (UR) | Recherchestand: 14.10.2026
A3: Status: gilt / belegt = Beleg mit Link vorhanden · belegt – Betroffenheit offen = Layer/Inventar existiert, Lage in der Gemeinde per GIS zu prüfen (Blatt 7) · keine Regelung (geprüft) = Ebene regelt nichts, übergeordnetes Recht gilt · nicht belegt (Recherche offen) = bisher kein Beleg · Datenanfrage = nicht öffentlich · n. a. = andere Gebietskörperschaft
A5: Ebene | B5: Q | C5: Typ | D5: Bezeichnung | E5: Referenz (SR/SGS/RB) | F5: Stand | G5: Zuständige Stelle | H5: Zugang | I5: Münchenstein (BL) | J5: Wil (SG) | K5: Seelisberg (UR) | L5: Inhalt / Mindestanforderung | M5: Link / Quelle | N5: Link-Status | O5: Herkunft · Confidence | P5: Prüfnachweis / Hinweis
A6: BUND (gilt für alle drei Gemeinden)
A7: Bund | B7: Q4 | C7: Layer | D7: Naturgefahren: Gefahrenhinweiskarte / Portal (Daten der Kantone, via geo.admin.ch) | E7: – | F7: Katalog: 04.02.2026 | G7: BAFU (Portal) / Kantone | H7: öffentlich | I7: belegt | J7: belegt | K7: belegt | L7: Gefahren und Nutzungseinschränkungen standortspezifisch prüfen | M7: https://www.geo.admin.ch/ | N7: Kataster · geprüft · nur Einstiegsseite | O7: Katalog · hoch | P7: Gefahrenkarten sind kantonale Daten; Bund stellt Hinweiskarte/Portal
A8: Bund | B8: Q4 | C8: Layer | D8: Gefährdungskarte Oberflächenabfluss (Starkregen) | E8: – | F8: – | G8: BAFU / VKF | H8: öffentlich | I8: belegt – Betroffenheit offen | J8: belegt – Betroffenheit offen | K8: belegt – Betroffenheit offen | L8: Starkregen-/Oberflächenabfluss-Gefährdung | M8: https://map.geo.admin.ch/#/map?lang=de&center=2660000,1190000&z=1&bgLayer=ch.swisstopo.pixelkarte-grau&layers=ch.bafu.gefaehrdungskarte-oberflaechenabfluss | N8: geprüft · korrigiert | O8: Ergänzung · mittel | P8: Linkprüfung 14.10.2026: Layer-ID ch.bafu.gefahren-oberflaechenabfluss existiert nicht, richtig: ch.bafu.gefaehrdungskarte-oberflaechenabfluss; Hyperlink führte nur auf https://map.geo.admin.ch/ statt auf den angezeigten Link. Alter Link: https://map.geo.admin.ch/#/map?lang=de&center=2660000,1190000&z=1&bgLayer=ch.swisstopo.pixelkarte-grau&layers=ch.bafu.gefahren-oberflaechenabfluss
A9: Bund | B9: Q4 | C9: Dokument / Daten | D9: Klimaszenarien CH2018 / Hydro-CH2018 / Klimaszenarien 2025; Strategie Anpassung an den Klimawandel | E9: – | F9: – | G9: MeteoSchweiz / BAFU | H9: öffentlich | I9: belegt | J9: belegt | K9: belegt | L9: Klimaprojektionen, Hitze, Trockenheit, Starkniederschlag | M9: https://www.bafu.admin.ch | N9: Einstiegsseite · geprüft · nur Einstiegsseite | O9: Ergänzung · mittel
A10: Bund | B10: Q4 | C10: Layer | D10: Hitzebelastung / Klimaanalyse (urbane Wärmeinseln, Bundesdaten) | E10: – | F10: – | G10: BAFU / MeteoSchweiz | H10: öffentlich | I10: nicht belegt (Recherche offen) | J10: nicht belegt (Recherche offen) | K10: nicht belegt (Recherche offen) | L10: Hitzevorsorge Siedlungsgebiet | M10: https://www.bafu.admin.ch | N10: Einstiegsseite · geprüft · nur Einstiegsseite | O10: Ergänzung · tief | P10: Abdeckung für kleine Gemeinden prüfen
A11: Bund | B11: Q4 | C11: Layer / Norm | D11: Erdbebengefährdung / Mikrozonierung (SED), SIA 261 Bauwerksklassen | E11: – | F11: – | G11: SED / SIA | H11: teilw. öffentlich | I11: belegt – Betroffenheit offen | J11: belegt – Betroffenheit offen | K11: belegt – Betroffenheit offen | L11: Baugrund-Klassen, Bauvorschriften | M11: https://map.geo.admin.ch/#/map?lang=de&center=2660000,1190000&z=1&bgLayer=ch.swisstopo.pixelkarte-grau&layers=ch.bafu.gefahren-baugrundklassen | N11: geprüft · korrigiert | O11: Ergänzung · mittel | P11: Linkprüfung 14.10.2026: Hyperlink führte nur auf https://map.geo.admin.ch/ statt auf den angezeigten Link. Alter Link: https://map.geo.admin.ch/#/map?lang=de&center=2660000,1190000&z=1&bgLayer=ch.swisstopo.pixelkarte-grau&layers=ch.bafu.gefahren-baugrundklassen
A12: Bund | B12: Q4 | C12: Layer | D12: Lärmbelastung (sonBASE), Störfall-Risikokataster, Kataster belasteter Standorte (Bundesbezug) | E12: USG / StFV / AltlV | F12: – | G12: BAFU / Kantone | H12: teilw. öffentlich | I12: belegt – Betroffenheit offen | J12: belegt – Betroffenheit offen | K12: belegt – Betroffenheit offen | L12: Belastungen, Standortrestriktionen | M12: https://map.geo.admin.ch/#/map?lang=de&center=2660000,1190000&z=1&bgLayer=ch.swisstopo.pixelkarte-grau&layers=ch.bafu.laerm-strassenlaerm_tag | N12: geprüft · korrigiert | O12: Ergänzung · mittel | P12: Linkprüfung 14.10.2026: Hyperlink führte nur auf https://map.geo.admin.ch/ statt auf den angezeigten Link. Alter Link: https://map.geo.admin.ch/#/map?lang=de&center=2660000,1190000&z=1&bgLayer=ch.swisstopo.pixelkarte-grau&layers=ch.bafu.laerm-strassenlaerm_tag
A13: KANTON BASEL-LANDSCHAFT → Münchenstein
A14: Kanton BL | B14: Q4 | C14: Layer | D14: Kantonale Naturgefahrenkarten BL (Wasser-, Sturz-, Rutschgefahren) | E14: – | F14: Katalog: 28.11.2005 | G14: Kanton BL | H14: öffentlich | I14: belegt | J14: n. a. | K14: n. a. | L14: Gefährdung und allfällige Nutzungsauflagen prüfen | M14: https://geoview.bl.ch/ | N14: Kataster · geprüft · nur Einstiegsseite | O14: Katalog · hoch | P14: Stand 2005 → Aktualität prüfen
A15: Kanton BL | B15: Q4 | C15: Layer | D15: Kantonale Hitze-/Klimaanalyse, Oberflächenabfluss, Lärm- und Altlastenkataster BL | E15: – | F15: – | G15: Kanton BL | H15: öffentlich | I15: nicht belegt (Recherche offen) | J15: n. a. | K15: n. a. | L15: Hitze, Starkregen, Belastungen | M15: https://geoview.bl.ch | N15: Muster · geprüft · nur Einstiegsseite | O15: Ergänzung · tief
A16: KANTON ST. GALLEN → Wil
A17: Kanton SG | B17: Q4 | C17: Layer | D17: Kantonale Naturgefahrenkarten SG | E17: – | F17: Katalog: 03.09.2026 | G17: Kanton SG | H17: öffentlich | I17: n. a. | J17: belegt | K17: n. a. | L17: Gefährdung und allfällige Nutzungsauflagen prüfen | M17: https://www.geoportal.ch/ktsg/map/3502?y=2721138&x=1258009&scale=50000&rotation=0 | N17: geprüft · korrigiert | O17: Katalog · hoch | P17: Linkprüfung 14.10.2026: Kartenzentrum lag rund 6 km südlich von Wil; auf Wil zentriert. Alter Link: https://www.geoportal.ch/ktsg/map/3502?y=2717572.22&x=1252351.20&scale=50000&rotation=0
A18: Kanton SG | B18: Q4 | C18: Layer | D18: Hitze-/Klimaanalyse, Oberflächenabfluss, Lärm- und Altlastenkataster SG | E18: – | F18: – | G18: Kanton SG | H18: öffentlich | I18: n. a. | J18: nicht belegt (Recherche offen) | K18: n. a. | L18: Hitze, Starkregen, Belastungen | M18: https://www.geoportal.ch/ktsg | N18: Muster · geprüft · manuell prüfen | O18: Ergänzung · tief | P18: Linkprüfung 14.10.2026: erreichbar, Bezeichnung im Dokument nicht gefunden («Geoportal»)
A19: KANTON URI → Seelisberg
A20: Kanton UR | B20: Q4 | C20: Layer | D20: Kantonale Naturgefahrenkarten Uri | E20: – | F20: 22.08.2023 | G20: Kanton UR | H20: öffentlich | I20: n. a. | J20: n. a. | K20: belegt | L20: Gefährdung und allfällige Nutzungsauflagen prüfen | M20: https://geo.ur.ch/ | N20: Kataster · geprüft · nur Einstiegsseite | O20: Katalog · hoch | P20: Seelisberg: Sturz-/Rutschgefahr erwartbar → Gefahrenstufen im Perimeter auswerten
A21: Kanton UR | B21: Q4 | C21: Layer | D21: Schutzwald, Lawinen-/Steinschlagschutz, Lärm-/Altlastenkataster Uri | E21: – | F21: – | G21: Kanton UR | H21: öffentlich | I21: n. a. | J21: n. a. | K21: nicht belegt (Recherche offen) | L21: Schutzbauten, Belastungen | M21: https://geo.ur.ch/ | N21: Muster · geprüft · nur Einstiegsseite | O21: Ergänzung · tief
A22: GEMEINDE MÜNCHENSTEIN (BL)
A23: Gde Münchenstein | B23: Q4 | C23: Reglement | D23: Abwasserreglement (28.10.2020) | E23: TR 5.4 | F23: 07.01.2021 | G23: Gde Münchenstein | H23: öffentlich | I23: belegt | J23: n. a. | K23: n. a. | L23: Entwässerungs- und Retentionsanforderungen | M23: https://www.muenchenstein.ch/_docn/5130739/TR_5.4_Abwasserreglement_vom_28._Oktober_2020_-_Stand_07.01.2021.pdf | N23: Kataster · geprüft · OK | O23: Katalog · hoch
A24: Gde Münchenstein | B24: Q4 | C24: Layer | D24: Generelle Entwässerungsplanung (GEP) / Starkregengrundlagen (Geoportal) | E24: – | F24: Katalog: kein Stand | G24: Gde Münchenstein | H24: teilw. öffentlich | I24: belegt | J24: n. a. | K24: n. a. | L24: GEP- und Starkregenprüfung | M24: https://www.geoportal.ch/muenchenstein/map/1037?y=2611563.50&x=1263436.40&scale=25000&rotation=0 | N24: Kataster · geprüft · OK | O24: Katalog · hoch | P24: Einsehbar ohne Attribute, externe Legende; Bezug bei Baudirektion
A25: GEMEINDE WIL (SG)
A26: Gde Wil | B26: Q4 | C26: Reglement | D26: Abwasserreglement | E26: SRS 7.4.3-6 | F26: Katalog: kein Stand | G26: Gde Wil | H26: öffentlich | I26: n. a. | J26: belegt | K26: n. a. | L26: Entwässerungs- und Retentionsanforderungen | M26: https://wil-sg.tlex.ch/app/de/texts_of_law/7.4.3-6 | N26: geprüft · korrigiert | O26: Katalog · hoch | P26: Linkprüfung 14.10.2026: Link zeigte auf einen Entwurf («vom ____»); geltende Fassung = SRS 7.4.3-6 (Titel lt. Sammlung: «Abwasserreglement»). Alter Link: https://www.stadtwil.ch/storage/8ae27a52e6272acbe7a00ddad257f439fbae9a367f80166a75d97ea28f6771cf
