Workbook

Sheet Anleitung
A1: Kanton St.Gallen
A2: Amt für Gemeinden und Bürgerrecht
A5: Berechnung Finanzausgleichsbeiträge 2025
A7: In dieser Datei werden die Finanzausgleichsbeiträge für das Jahr 2025 berechnet.
A9: In den grünen Laschen werden die Berechnungen vorgenommen. Diese Laschen sind ausschliesslich für den internen Gebrauch!
A13: Die drei blauen Laschen werden für die Auszahlungen der Finanzausgleichsbeiträge benötigt!
A17: Die roten Laschen dienen als Informationszweck für die Gemeinden. Diese Informationen werden regelmässig auf der Homepage aufgeschaltet! Bei der Aufschaltungsdatei sind die nicht relevanten Laschen auszublenden!

Sheet Ressourcenausgleich Basis
A1: Kanton St.Gallen
A2: Amt für Gemeinden und Bürgerrecht
A5: Ressourcenausgleich 2025
B7: Eingabefelder
C8: Total | D8: St.Gallen | E8: Wittenbach | F8: Häggenschwil | G8: Muolen | H8: Mörschwil | I8: Goldach | J8: Steinach | K8: Berg | L8: Tübach | M8: Untereggen | N8: Eggersriet | O8: Rorschacherberg | P8: Rorschach | Q8: Thal | R8: Rheineck | S8: St.Margrethen | T8: Au | U8: Berneck | V8: Balgach | W8: Diepoldsau | X8: Widnau | Y8: Rebstein | Z8: Marbach | AA8: Altstätten | AB8: Eichberg | AC8: Oberriet | AD8: Rüthi | AE8: Sennwald | AF8: Gams | AG8: Grabs | AH8: Buchs | AI8: Sevelen | AJ8: Wartau | AK8: Sargans | AL8: Vilters-Wangs | AM8: Bad Ragaz | AN8: Pfäfers | AO8: Mels | AP8: Flums | AQ8: Walenstadt | AR8: Quarten | AS8: Amden | AT8: Weesen | AU8: Schänis | AV8: Benken | AW8: Kaltbrunn | AX8: Gommiswald | AY8: Uznach | AZ8: Schmerikon | BA8: Rapperswil-Jona | BB8: Eschenbach | BC8: Wildhaus-Alt St.Johann | BD8: Nesslau | BE8: Ebnat-Kappel | BF8: Wattwil | BG8: Lichtensteig | BH8: Neckertal | BI8: Bütschwil-Ganterschwil | BJ8: Lütisburg | BK8: Mosnang | BL8: Kirchberg | BM8: Jonschwil | BN8: Oberuzwil | BO8: Uzwil | BP8: Flawil | BQ8: Degersheim | BR8: Wil | BS8: Zuzwil | BT8: Oberbüren | BU8: Niederbüren | BV8: Niederhelfenschwil | BW8: Gossau | BX8: Andwil | BY8: Waldkirch | BZ8: Gaiserwald | CB8: Quelle
A10: 1.) | B10: Steuerdaten 2023
A12: 1.1) | B12: Einkommens-/Vermögenssteuer
B13: Steuerfuss | C13: =C19/C17 -> 1.112714 | D13: 1.41 | E13: 1.28 | F13: 1.15 | G13: 1.23 | H13: 0.7 | I13: 0.91 | J13: 1.15 | K13: 1.26 | L13: 0.79 | M13: 1.19 | N13: 1.2 | O13: 0.93 | P13: 1.29 | Q13: 0.89 | R13: 1.13 | S13: 1.02 | T13: 0.89 | U13: 0.95 | V13: 0.61 | W13: 0.81 | X13: 0.76 | Y13: 1.01 | Z13: 1.07 | AA13: 1.19 | AB13: 1.04 | AC13: 0.99 | AD13: 1.15 | AE13: 0.75 | AF13: 1.18 | AG13: 1 | AH13: 1.18 | AI13: 1.1 | AJ13: 1.5 | AK13: 1.34 | AL13: 1.25 | AM13: 0.92 | AN13: 1.39 | AO13: 1.33 | AP13: 1.25 | AQ13: 1.15 | AR13: 1.07 | AS13: 1.12 | AT13: 1.15 | AU13: 1.25 | AV13: 1.19 | AW13: 1.06 | AX13: 1.08 | AY13: 1.12 | AZ13: 1.13 | BA13: 0.74 | BB13: 1.19 | BC13: 1.23 | BD13: 1.19 | BE13: 1.39 | BF13: 1.32 | BG13: 1.29 | BH13: 1.2 | BI13: 1.19 | BJ13: 1.15 | BK13: 1.29 | BL13: 1.2 | BM13: 1.17 | BN13: 1.17 | BO13: 1.27 | BP13: 1.27 | BQ13: 1.47 | BR13: 1.18 | BS13: 0.77 | BT13: 1 | BU13: 1.26 | BV13: 1.04 | BW13: 1.16 | BX13: 1.13 | BY13: 1.22 | BZ13: 1.03 | CB13: KStA
B15: Einfache Steuer Brutto | C15: =SUM(D15:BZ15) -> 1.267089e+09 | D15: 1.878166e+08 | E15: 19800001 | F15: 3126213 | G15: 2605174.8 | H15: 16744495 | I15: 24193019 | J15: 8384764.4 | K15: 3327004.4 | L15: 4561605.8 | M15: 2609380.8 | N15: 6425305.4 | O15: 20342881 | P15: 16012558 | Q15: 18465006 | R15: 6306940.7 | S15: 10248394 | T15: 20051683 | U15: 11390924 | V15: 18393452 | W15: 16185528 | X15: 24895132 | Y15: 10961179 | Z15: 5096520.3 | AA15: 27029609 | AB15: 3271931.3 | AC15: 19802617 | AD15: 4950818.8 | AE15: 14017525 | AF15: 7586630.2 | AG15: 16004291 | AH15: 31352464 | AI15: 10808520 | AJ15: 9876472.9 | AK15: 13758486 | AL15: 10393897 | AM15: 17547839 | AN15: 2756717 | AO15: 19190243 | AP15: 9892271.9 | AQ15: 13391133 | AR15: 7140130.6 | AS15: 5763960.2 | AT15: 5462877.5 | AU15: 7406962.8 | AV15: 5964295.8 | AW15: 10976752 | AX15: 15742683 | AY15: 14803214 | AZ15: 11293157 | BA15: 1.1355965e+08 | BB15: 23481192 | BC15: 5988472.4 | BD15: 7296659.2 | BE15: 8768260.8 | BF15: 16387597 | BG15: 4352460 | BH15: 10787747 | BI15: 9756532.2 | BJ15: 2948677.8 | BK15: 5148594.8 | BL15: 18629148 | BM15: 8856549 | BN15: 14911780 | BO15: 28559272 | BP15: 20549757 | BQ15: 6572747.3 | BR15: 65759635 | BS15: 17929962 | BT15: 11158375 | BU15: 3591048.9 | BV15: 7211398.2 | BW15: 41718111 | BX15: 5771636 | BY15: 7534001 | BZ15: 25730486 | CB15: KStA
B16: Abschreibungen | C16: =SUM(D16:BZ16) -> 3942852.1 | D16: 318598.67 | E16: 140790.54 | F16: -1770.1011 | G16: 18856.697 | H16: 1867.4827 | I16: 138776.9 | J16: 17573.546 | K16: -2025.2424 | L16: 163.27149 | M16: 431.53156 | N16: -4980.1646 | O16: 53317.985 | P16: 125665.7 | Q16: 24735.072 | R16: 19026.874 | S16: 113909.42 | T16: 143052.88 | U16: 28924.602 | V16: 36849.399 | W16: -20634.456 | X16: 354026.17 | Y16: 112129.22 | Z16: 15553.522 | AA16: 138859.94 | AB16: 21235.847 | AC16: 21487.378 | AD16: 36530.545 | AE16: 22861.57 | AF16: 12050.883 | AG16: 56217.182 | AH16: 82844.695 | AI16: -18010.612 | AJ16: 57498.277 | AK16: 44219.183 | AL16: 11818.521 | AM16: 62484.553 | AN16: 14326.347 | AO16: 12044.242 | AP16: 21525.99 | AQ16: -42704.048 | AR16: 55030.792 | AS16: 4293.1551 | AT16: 29848.971 | AU16: -7111.9984 | AV16: 44221.639 | AW16: 25065.182 | AX16: 53970.632 | AY16: 66331.2 | AZ16: 2468.6273 | BA16: 269955.62 | BB16: 26147.741 | BC16: 46891.341 | BD16: 10665.127 | BE16: 36743.062 | BF16: 198054.63 | BG16: 8578.5273 | BH16: 117743.62 | BI16: 50548.78 | BJ16: -4337.9978 | BK16: -3134.1263 | BL16: 36582.52 | BM16: 20123.296 | BN16: 33063.79 | BO16: 134062.7 | BP16: -4501.656 | BQ16: 26535.518 | BR16: 352652.73 | BS16: 11292.781 | BT16: -5290.3104 | BU16: -3070.0514 | BV16: 3059.5127 | BW16: 8766.8556 | BX16: 19928.853 | BY16: 12235.964 | BZ16: 75305.1 | CB16: KStA
B17: Einfache Steuer Netto | C17: =SUM(D17:BZ17) -> 1.2631462e+09 | D17: =D15-D16 -> 1.87498e+08 | E17: =E15-E16 -> 19659210 | F17: =F15-F16 -> 3127983.2 | G17: =G15-G16 -> 2586318.1 | H17: =H15-H16 -> 16742628 | I17: =I15-I16 -> 24054242 | J17: =J15-J16 -> 8367190.9 | K17: =K15-K16 -> 3329029.7 | ... BZ17: =BZ15-BZ16 -> 25655181
B19: Effektiver Nettoertrag | C19: =SUM(D19:BZ19) -> 1.4055204e+09 | D19: =D17*D13 -> 2.6437218e+08 | E19: =E17*E13 -> 25163789 | F19: =F17*F13 -> 3597180.6 | G19: =G17*G13 -> 3181171.3 | H19: =H17*H13 -> 11719839 | I19: =I17*I13 -> 21889360 | J19: =J17*J13 -> 9622269.5 | K19: =K17*K13 -> 4194577.4 | ... BZ19: =BZ17*BZ13 -> 26424836
B21: Standardisierter Ertrag | C21: =C17*$C13 -> 1.4055204e+09 | D21: =D17*$C13 -> 2.0863164e+08 | E21: =E17*$C13 -> 21875078 | F21: =F17*$C13 -> 3480550.6 | G21: =G17*$C13 -> 2877832.3 | H21: =H17*$C13 -> 18629756 | I21: =I17*$C13 -> 26765491 | J21: =J17*$C13 -> 9310290.2 | ... BZ21: =BZ17*$C13 -> 28546878
A23: 1.2) | B23: Quellensteuer
B24: Bruttoertrag | C24: =SUM(D24:BZ24) -> 82950711 | D24: 18214414 | E24: 767948.5 | F24: 128214.6 | G24: 85545.55 | H24: 137404.45 | I24: 1024789.2 | J24: 711553.25 | K24: 46262.6 | L24: 88988.15 | M24: 39011.85 | N24: 79487.4 | O24: 717111.65 | P24: 2809546.4 | Q24: 1727923.3 | R24: 564122.2 | S24: 2725295.1 | T24: 3547114.6 | U24: 817150.1 | V24: 2483401.5 | W24: 2534747.4 | X24: 1848314.3 | Y24: 878233.9 | Z24: 255185.1 | AA24: 3218999.4 | AB24: 129489.8 | AC24: 2041284.5 | AD24: 585796.1 | AE24: 3004467.5 | AF24: 423932.1 | AG24: 1539153.2 | AH24: 3638836.4 | AI24: 1041571.8 | AJ24: 864215.4 | AK24: 954139.2 | AL24: 411306.5 | AM24: 1328461.2 | AN24: 268129.1 | AO24: 680631 | AP24: 525359.3 | AQ24: 500568.1 | AR24: 272907.5 | AS24: 48104.95 | AT24: 69418.3 | AU24: 350006.5 | AV24: 204220.55 | AW24: 305058.85 | AX24: 307735.85 | AY24: 836155.1 | AZ24: 379688.5 | BA24: 2671301.4 | BB24: 772740.4 | BC24: 376945.95 | BD24: 149964.1 | BE24: 212955.25 | BF24: 654324.2 | BG24: 257966.5 | BH24: 323213.55 | BI24: 397504.25 | BJ24: 112673.9 | BK24: 89681.3 | BL24: 1388914.3 | BM24: 348502.7 | BN24: 464482.9 | BO24: 1756378 | BP24: 926999.55 | BQ24: 314616.95 | BR24: 2715752.7 | BS24: 216475.5 | BT24: 300449.8 | BU24: 86070.4 | BV24: 97882.2 | BW24: 1533549.8 | BX24: 78972.85 | BY24: 192967.45 | BZ24: 348022.85 | CB24: KStA
B25: Abschreibungen | C25: =SUM(D25:BZ25) -> 545968.24 | D25: 113012.77 | E25: 712.25 | F25: 806.85 | G25: 18.3 | H25: -5.7 | I25: 4411.75 | J25: 275.8 | K25: 24.5 | L25: 5517.8 | M25: 0.2 | N25: 8.8 | O25: 9514.75 | P25: 60608.29 | Q25: 19625.85 | R25: 3064.05 | S25: 35321.5 | T25: 43660.9 | U25: 32.8 | V25: 1227.85 | W25: 1575.9 | X25: 10444.52 | Y25: 5697.07 | Z25: 5957.5 | AA25: 11615.95 | AB25: 1033.37 | AC25: 6641.35 | AD25: 1703.65 | AE25: 1418.4 | AF25: 624.05 | AG25: 5697.64 | AH25: -4113.36 | AI25: 8664.1 | AJ25: 5504.14 | AK25: 56.56 | AL25: 1085.2 | AM25: 90.85 | AN25: 14.1 | AO25: 83.56 | AP25: 577.25 | AQ25: 1255.1 | AR25: 426.72 | AS25: 15.2 | AT25: 49.2 | AU25: 2745.55 | AV25: 12257.5 | AW25: 1177.45 | AX25: 1161.45 | AY25: 6586.53 | AZ25: 969.1 | BA25: 17614.35 | BB25: 6435.15 | BC25: 6915.9 | BD25: 17.95 | BE25: -2482.75 | BF25: 5522.66 | BG25: 2228.15 | BH25: 2255.35 | BI25: 57.35 | BJ25: 2222.8 | BK25: -1.75 | BL25: 470.7 | BM25: 1599.7 | BN25: 5544.15 | BO25: 38653.5 | BP25: 12374.4 | BQ25: 5760.4 | BR25: 36568.15 | BS25: 1784.87 | BT25: 758.8 | BU25: 0.15 | BV25: 6.6 | BW25: 11392.55 | BX25: 0.7 | BY25: 24.2 | BZ25: 1389.3 | CB25: KStA
B26: Nettoertrag (standardisierter Ertrag) | C26: =SUM(D26:BZ26) -> 82404742 | D26: =D24-D25 -> 18101401 | E26: =E24-E25 -> 767236.25 | F26: =F24-F25 -> 127407.75 | G26: =G24-G25 -> 85527.25 | H26: =H24-H25 -> 137410.15 | I26: =I24-I25 -> 1020377.4 | J26: =J24-J25 -> 711277.45 | K26: =K24-K25 -> 46238.1 | ... BZ26: =BZ24-BZ25 -> 346633.55
A28: 1.3) | B28: Gewinn- und Kapitalsteuer
B29: Bruttoertrag | C29: =SUM(D29:BZ29) -> 1.9263074e+08 | D29: 46167167 | E29: 1799044.9 | F29: 86881.1 | G29: 82643.4 | H29: 933177.85 | I29: 4440128.5 | J29: 763591.25 | K29: 66774.5 | L29: 430521.5 | M29: 66295.05 | N29: 147587.8 | O29: 1292065.9 | P29: 3598272.9 | Q29: 2409781.5 | R29: 781763.65 | S29: 2415120.8 | T29: 3138606.5 | U29: 1327749.9 | V29: 6295768.5 | W29: 2532743.5 | X29: 5899597.7 | Y29: 1413486.8 | Z29: 309224.1 | AA29: 4023815.7 | AB29: 35581.35 | AC29: 2926196 | AD29: 869261.95 | AE29: 5815538 | AF29: 506444.2 | AG29: 1106448.6 | AH29: 8026595.8 | AI29: 649779.5 | AJ29: 1008695.5 | AK29: 1256394.3 | AL29: 1444471.1 | AM29: 1558893.1 | AN29: 81645.3 | AO29: 1647552.3 | AP29: 939580.95 | AQ29: 650040.1 | AR29: 339327.95 | AS29: 201455.65 | AT29: 161260.6 | AU29: 495522.55 | AV29: 549249 | AW29: 594883.15 | AX29: 549447.25 | AY29: 2308572 | AZ29: 1534688.9 | BA29: 20844124 | BB29: 1850937.8 | BC29: 266542.05 | BD29: 461028.05 | BE29: 1327700.8 | BF29: 2042882.2 | BG29: 335054.7 | BH29: 387567.05 | BI29: 1114184.6 | BJ29: 112486.85 | BK29: 322178.65 | BL29: 2066831.1 | BM29: 1109957.6 | BN29: 875257.6 | BO29: 3483388 | BP29: 2298281.9 | BQ29: 1732285 | BR29: 14473712 | BS29: 946673.8 | BT29: 2490776.7 | BU29: 76828.7 | BV29: 244459.65 | BW29: 6679776.8 | BX29: 257005.15 | BY29: 615399.65 | BZ29: 536085.4 | CB29: KStA
B30: Abschreibungen | C30: =SUM(D30:BZ30) -> 1363211 | D30: 446047.4 | E30: 1946.75 | F30: 52.45 | G30: 34.05 | H30: 1588.85 | I30: 17672.95 | J30: 284.25 | K30: 18.4 | L30: 77.45 | M30: 66.85 | N30: 107.55 | O30: 3120.65 | P30: 53032.75 | Q30: 9801.65 | R30: 3309.15 | S30: 8914.55 | T30: 153523.25 | U30: 1606.55 | V30: 17431.5 | W30: 15099.4 | X30: 35451.85 | Y30: 1264 | Z30: 3218.6 | AA30: 8893.65 | AB30: 2399.95 | AC30: 78856.55 | AD30: 1114.85 | AE30: 7934 | AF30: 345.55 | AG30: 5538.55 | AH30: 52374 | AI30: 13049.25 | AJ30: 3191.75 | AK30: 2634.1 | AL30: 1761.3 | AM30: 2029.2 | AN30: 1332 | AO30: 7139.35 | AP30: 369.8 | AQ30: 1095.35 | AR30: 874.5 | AS30: 4443.65 | AT30: 99.7 | AU30: 452.15 | AV30: 36027.8 | AW30: 13637.15 | AX30: 1395.6 | AY30: 107881.75 | AZ30: 406.85 | BA30: 15212.7 | BB30: 1783.8 | BC30: 1820.25 | BD30: 3900.55 | BE30: 4557.75 | BF30: 8477.65 | BG30: 364.95 | BH30: 38426.75 | BI30: 3435.05 | BJ30: 200.1 | BK30: 64.6 | BL30: 1288.7 | BM30: 4975.5 | BN30: 23782.55 | BO30: 4109.85 | BP30: 14552.7 | BQ30: 846.7 | BR30: 70024.3 | BS30: 2060.95 | BT30: 2112.6 | BU30: 80.6 | BV30: 90 | BW30: 31296.65 | BX30: 38.1 | BY30: 251.4 | BZ30: 507.05 | CB30: KStA
B31: pauschale Steueranrechnung | C31: =SUM(D31:BZ31) -> 672651.9 | D31: 12611.6 | E31: 1395.15 | F31: 0 | G31: 0 | H31: 6989 | I31: 0 | J31: 0 | K31: 0 | L31: 0 | M31: 0 | N31: 0 | O31: 0 | P31: 179.65 | Q31: 0 | R31: 0 | S31: 0 | T31: 0 | U31: 452.35 | V31: 549965.4 | W31: 0 | X31: 5623.7 | Y31: 0 | Z31: 0 | AA31: 0 | AB31: 0 | AC31: 0 | AD31: 0 | AE31: 0 | AF31: 0 | AG31: 0 | AH31: 0 | AI31: 0 | AJ31: 0 | AK31: 0 | AL31: 0 | AM31: 0 | AN31: 0 | AO31: 0 | AP31: 0 | AQ31: 0 | AR31: 0 | AS31: 0 | AT31: 0 | AU31: 0 | AV31: 0 | AW31: 0 | AX31: 0 | AY31: 0 | AZ31: 0 | BA31: 79731.3 | BB31: 0 | BC31: 0 | BD31: 0 | BE31: 0 | BF31: 0 | BG31: 0 | BH31: 0 | BI31: 0 | BJ31: 0 | BK31: 0 | BL31: 0 | BM31: 0 | BN31: 0 | BO31: 0 | BP31: 14861.45 | BQ31: 0 | BR31: 0 | BS31: 0 | BT31: 0 | BU31: 0 | BV31: 0 | BW31: 842.3 | BX31: 0 | BY31: 0 | BZ31: 0 | CB31: KStA
B32: Nettoertrag (standardisierter Ertrag) | C32: =SUM(D32:BZ32) -> 1.9059488e+08 | D32: =D29-D30-D31 -> 45708508 | E32: =E29-E30-E31 -> 1795703 | F32: =F29-F30-F31 -> 86828.65 | G32: =G29-G30-G31 -> 82609.35 | H32: =H29-H30-H31 -> 924600 | I32: =I29-I30-I31 -> 4422455.6 | J32: =J29-J30-J31 -> 763307 | K32: =K29-K30-K31 -> 66756.1 | ... BZ32: =BZ29-BZ30-BZ31 -> 535578.35
A34: 1.4) | B34: Grundsteuer (ord. Satz)
B35: Steuersatz in ‰ | C35: =C39/C41 -> 0.68623685 | D35: 0.8 | E35: 0.8 | F35: 0.8 | G35: 0.8 | H35: 0.2 | I35: 0.4 | J35: 0.6 | K35: 0.3 | L35: 0.2 | M35: 0.8 | N35: 0.8 | O35: 0.8 | P35: 0.8 | Q35: 0.4 | R35: 0.8 | S35: 0.8 | T35: 0.4 | U35: 0.8 | V35: 0.5 | W35: 0.5 | X35: 0.8 | Y35: 0.7 | Z35: 0.8 | AA35: 0.8 | AB35: 0.8 | AC35: 0.8 | AD35: 0.8 | AE35: 0.8 | AF35: 0.8 | AG35: 0.8 | AH35: 0.7 | AI35: 0.8 | AJ35: 0.7 | AK35: 0.8 | AL35: 0.8 | AM35: 0.8 | AN35: 0.8 | AO35: 0.8 | AP35: 0.8 | AQ35: 0.8 | AR35: 0.8 | AS35: 0.8 | AT35: 0.8 | AU35: 0.8 | AV35: 0.8 | AW35: 0.8 | AX35: 0.8 | AY35: 0.8 | AZ35: 0.8 | BA35: 0.3 | BB35: 0.8 | BC35: 0.8 | BD35: 0.8 | BE35: 0.8 | BF35: 0.8 | BG35: 0.8 | BH35: 0.8 | BI35: 0.6 | BJ35: 0.8 | BK35: 0.5 | BL35: 0.8 | BM35: 0.6 | BN35: 0.8 | BO35: 0.6 | BP35: 0.8 | BQ35: 0.8 | BR35: 0.6 | BS35: 0.4 | BT35: 0.3 | BU35: 0.8 | BV35: 0.4 | BW35: 0.6 | BX35: 0.6 | BY35: 0.8 | BZ35: 0.8 | CB35: KStA/Gemeinden
B37: Bruttoertrag | C37: =SUM(D37:BZ37) -> 1.0333655e+08 | D37: 19085491 | E37: 1832609.4 | F37: 298303.1 | G37: 242743.95 | H37: 278485.6 | I37: 1090729.9 | J37: 655906 | K37: 80593.85 | L37: 110781 | M37: 230643.9 | N37: 475693.65 | O37: 1690738.8 | P37: 1855456.6 | Q37: 893512.1 | R37: 684173.95 | S37: 1428215.1 | T37: 952514.3 | U37: 987760.22 | V37: 832481.75 | W37: 1025995.5 | X37: 2586124 | Y37: 819382.92 | Z37: 443822.7 | AA37: 2639182.5 | AB37: 327266.56 | AC37: 2099310.2 | AD37: 568730.22 | AE37: 1562053.3 | AF37: 725417.45 | AG37: 1470721.6 | AH37: 2648500 | AI37: 1045815.8 | AJ37: 940561.5 | AK37: 1304820.8 | AL37: 1126258.1 | AM37: 1798957.3 | AN37: 439520.47 | AO37: 2107271.2 | AP37: 1304555.7 | AQ37: 1235368.2 | AR37: 1014942.4 | AS37: 556772.7 | AT37: 447628 | AU37: 776963.62 | AV37: 607312 | AW37: 935317.05 | AX37: 1387082.1 | AY37: 1499702.5 | AZ37: 983601.43 | BA37: 3165806 | BB37: 2279946.6 | BC37: 880430.65 | BD37: 694711.45 | BE37: 963323.25 | BF37: 1671666.6 | BG37: 356900.85 | BH37: 1035841.1 | BI37: 725891.95 | BJ37: 287068.19 | BK37: 309526.68 | BL37: 1959128.9 | BM37: 772391 | BN37: 1263500.6 | BO37: 2078386.1 | BP37: 1836111.8 | BQ37: 700362.8 | BR37: 4235361.2 | BS37: 644060.4 | BT37: 426151.55 | BU37: 320542.64 | BV37: 331262.15 | BW37: 3200069 | BX37: 331204.72 | BY37: 739523.04 | BZ37: 1991584.1 | CB37: Gemeinden
B38: Erlasse/Verluste | C38: =SUM(D38:BZ38) -> 2871.4 | D38: 0 | E38: 0 | F38: 0 | G38: 0 | H38: 0 | I38: 0 | J38: 0 | K38: 0 | L38: 0 | M38: 0 | N38: 0 | O38: 0 | P38: 0 | Q38: 0 | R38: 0 | S38: 0 | T38: 0 | U38: 0 | V38: 10.7 | W38: 0 | X38: 0 | Y38: 0 | Z38: 0 | AA38: 0 | AB38: 0 | AC38: 311.15 | AD38: 0 | AE38: 0 | AF38: 0 | AG38: 0 | AH38: 0 | AI38: 0 | AJ38: 0 | AK38: 0 | AL38: 0 | AM38: 0 | AN38: 0 | AO38: 0 | AP38: 0.23 | AQ38: -8.4 | AR38: 0 | AS38: 0 | AT38: 0 | AU38: 0 | AV38: 0 | AW38: 0 | AX38: 0 | AY38: 0 | AZ38: 0.95 | BA38: 0 | BB38: 0 | BC38: 0 | BD38: 1.5 | BE38: 0 | BF38: 0 | BG38: 0 | BH38: 0 | BI38: 0 | BJ38: 0 | BK38: 41.19 | BL38: 108.03 | BM38: 0 | BN38: 0 | BO38: 1823 | BP38: 583.05 | BQ38: 0 | BR38: 0 | BS38: 0 | BT38: 0 | BU38: 0 | BV38: 0 | BW38: 0 | BX38: 0 | BY38: 0 | BZ38: 0 | CB38: Gemeinden
B39: Nettoertrag | C39: =SUM(D39:BZ39) -> 1.0333367e+08 | D39: =D37-D38 -> 19085491 | E39: =E37-E38 -> 1832609.4 | F39: =F37-F38 -> 298303.1 | G39: =G37-G38 -> 242743.95 | H39: =H37-H38 -> 278485.6 | I39: =I37-I38 -> 1090729.9 | J39: =J37-J38 -> 655906 | K39: =K37-K38 -> 80593.85 | ... BZ39: =BZ37-BZ38 -> 1991584.1
B41: Ertrag bei Satz von 1‰ | C41: =SUM(D41:BZ41) -> 1.5058019e+08 | D41: =D39/D35 -> 23856863 | E41: =E39/E35 -> 2290761.8 | F41: =F39/F35 -> 372878.87 | G41: =G39/G35 -> 303429.94 | H41: =H39/H35 -> 1392428 | I41: =I39/I35 -> 2726824.7 | J41: =J39/J35 -> 1093176.7 | K41: =K39/K35 -> 268646.17 | ... BZ41: =BZ39/BZ35 -> 2489480.2
B43: Standardisierter Ertrag | C43: =C41*$C35 -> 1.0333367e+08 | D43: =D41*$C35 -> 16371459 | E43: =E41*$C35 -> 1572005.2 | F43: =F41*$C35 -> 255883.23 | G43: =G41*$C35 -> 208224.81 | H43: =H41*$C35 -> 955535.41 | I43: =I41*$C35 -> 1871247.6 | J43: =J41*$C35 -> 750178.12 | ... BZ43: =BZ41*$C35 -> 1708373.1
A45: 1.5) | B45: Grundsteuer (Spezialsatz)
B46: Bruttoertrag | C46: =SUM(D46:BZ46) -> 1630051.2 | D46: 339501.63 | E46: 31977.08 | F46: 3326.5 | G46: 2921.6 | H46: 10930.4 | I46: 16285.84 | J46: 14374 | K46: 1878.3 | L46: 0 | M46: 2843.15 | N46: 6184.3 | O46: 17053.2 | P46: 37120.6 | Q46: 23900.5 | R46: 12555.95 | S46: 13203.52 | T46: 29035.09 | U46: 7458.6 | V46: 11143.4 | W46: 21788.44 | X46: 20549.95 | Y46: 7968.2 | Z46: 3863.04 | AA46: 42924.98 | AB46: 2200 | AC46: 25820.27 | AD46: 4020.62 | AE46: 27408.15 | AF46: 7667.8 | AG46: 44157.05 | AH46: 33433 | AI46: 9619.2 | AJ46: 11965.55 | AK46: 12319.75 | AL46: 9797.75 | AM46: 11665.5 | AN46: 25600.94 | AO46: 27212.95 | AP46: 11985.38 | AQ46: 11991.8 | AR46: 184.2 | AS46: 5690.15 | AT46: 6231 | AU46: 6864.64 | AV46: 6029 | AW46: 8935.25 | AX46: 11471 | AY46: 25841.94 | AZ46: 13783.6 | BA46: 105516.6 | BB46: 22402.69 | BC46: 8108.2 | BD46: 19866.85 | BE46: 14631.22 | BF46: 30194.25 | BG46: 4183.55 | BH46: 22689.6 | BI46: 17348.7 | BJ46: 919.57 | BK46: 10660.26 | BL46: 30306.66 | BM46: 8419 | BN46: 15453.7 | BO46: 32753.2 | BP46: 27197.45 | BQ46: 12695.25 | BR46: 102501.85 | BS46: 8751.25 | BT46: 10761.95 | BU46: 1268.4 | BV46: 8016.65 | BW46: 32040 | BX46: 5595.4 | BY46: 12916.96 | BZ46: 24167.25 | CB46: Gemeinden
B47: Erlasse/Verluste | C47: =SUM(D47:BZ47) -> 12.11 | D47: 0 | E47: 0 | F47: 0 | G47: 0 | H47: 0 | I47: 0 | J47: 0.2 | K47: 0 | L47: 0 | M47: 0 | N47: 0 | O47: 0 | P47: 0 | Q47: 0 | R47: 0 | S47: 0 | T47: 0 | U47: 0 | V47: 0 | W47: 0 | X47: 0 | Y47: 0 | Z47: 0 | AA47: 0 | AB47: 0 | AC47: 0 | AD47: 0 | AE47: 0 | AF47: 0 | AG47: 0 | AH47: 0 | AI47: 0 | AJ47: 0 | AK47: 0 | AL47: 0 | AM47: 0 | AN47: 0 | AO47: 0 | AP47: 0 | AQ47: 0 | AR47: 0 | AS47: 0 | AT47: 0 | AU47: 0 | AV47: 0 | AW47: 0 | AX47: 0 | AY47: 0 | AZ47: 0 | BA47: 0 | BB47: 0 | BC47: 0 | BD47: 0 | BE47: 0 | BF47: 0 | BG47: 0 | BH47: 0 | BI47: 0 | BJ47: 0 | BK47: 0 | BL47: 11.71 | BM47: 0 | BN47: 0 | BO47: 0 | BP47: 0 | BQ47: 0 | BR47: 0 | BS47: 0 | BT47: 0 | BU47: 0 | BV47: 0 | BW47: 0 | BX47: 0.2 | BY47: 0 | BZ47: 0 | CB47: Gemeinden
B48: Nettoertrag (standardisierter Ertrag) | C48: =SUM(D48:BZ48) -> 1630039.1 | D48: =D46-D47 -> 339501.63 | E48: =E46-E47 -> 31977.08 | F48: =F46-F47 -> 3326.5 | G48: =G46-G47 -> 2921.6 | H48: =H46-H47 -> 10930.4 | I48: =I46-I47 -> 16285.84 | J48: =J46-J47 -> 14373.8 | K48: =K46-K47 -> 1878.3 | ... BZ48: =BZ46-BZ47 -> 24167.25
A50: 1.6) | B50: Handänderungssteuer
B51: Bruttoertrag | C51: =SUM(D51:BZ51) -> 59811726 | D51: 10387286 | E51: 912441.64 | F51: 185351.85 | G51: 86210.44 | H51: 600536.95 | I51: 930406 | J51: 234393 | K51: 29776 | L51: 60475 | M51: 78724.75 | N51: 341357.5 | O51: 1437093.7 | P51: 1368530.9 | Q51: 1308723.4 | R51: 208071.5 | S51: 1126899.8 | T51: 862486.84 | U51: 535210.24 | V51: 533677.95 | W51: 398843.6 | X51: 968996.8 | Y51: 468125.79 | Z51: 166423.67 | AA51: 1265992.4 | AB51: 161970 | AC51: 497524.99 | AD51: 325591.33 | AE51: 865209.3 | AF51: 367587.8 | AG51: 597556.45 | AH51: 1624695 | AI51: 284900.7 | AJ51: 824728.9 | AK51: 740033.5 | AL51: 399609 | AM51: 1042034.8 | AN51: 121047.9 | AO51: 1493596.9 | AP51: 831892.61 | AQ51: 327902.03 | AR51: 447439.4 | AS51: 270893.85 | AT51: 152915 | AU51: 553171.2 | AV51: 367129.1 | AW51: 304323.8 | AX51: 761999.5 | AY51: 425033.39 | AZ51: 136149.95 | BA51: 3326250.7 | BB51: 1308917.5 | BC51: 291165.4 | BD51: 270517.48 | BE51: 571905.85 | BF51: 1153720.9 | BG51: 220128.65 | BH51: 433491.3 | BI51: 701451.25 | BJ51: 193302.71 | BK51: 204503.55 | BL51: 1398569.2 | BM51: 319742 | BN51: 745478.55 | BO51: 1577461.6 | BP51: 496148 | BQ51: 252982.75 | BR51: 2834887.4 | BS51: 671883.3 | BT51: 718516.3 | BU51: 113448.67 | BV51: 442705.15 | BW51: 1926176 | BX51: 133294.62 | BY51: 198180.18 | BZ51: 885924.09 | CB51: Gemeinden
B52: Erlasse/Verluste | C52: =SUM(D52:BZ52) -> 0 | D52: 0 | E52: 0 | F52: 0 | G52: 0 | H52: 0 | I52: 0 | J52: 0 | K52: 0 | L52: 0 | M52: 0 | N52: 0 | O52: 0 | P52: 0 | Q52: 0 | R52: 0 | S52: 0 | T52: 0 | U52: 0 | V52: 0 | W52: 0 | X52: 0 | Y52: 0 | Z52: 0 | AA52: 0 | AB52: 0 | AC52: 0 | AD52: 0 | AE52: 0 | AF52: 0 | AG52: 0 | AH52: 0 | AI52: 0 | AJ52: 0 | AK52: 0 | AL52: 0 | AM52: 0 | AN52: 0 | AO52: 0 | AP52: 0 | AQ52: 0 | AR52: 0 | AS52: 0 | AT52: 0 | AU52: 0 | AV52: 0 | AW52: 0 | AX52: 0 | AY52: 0 | AZ52: 0 | BA52: 0 | BB52: 0 | BC52: 0 | BD52: 0 | BE52: 0 | BF52: 0 | BG52: 0 | BH52: 0 | BI52: 0 | BJ52: 0 | BK52: 0 | BL52: 0 | BM52: 0 | BN52: 0 | BO52: 0 | BP52: 0 | BQ52: 0 | BR52: 0 | BS52: 0 | BT52: 0 | BU52: 0 | BV52: 0 | BW52: 0 | BX52: 0 | BY52: 0 | BZ52: 0 | CB52: Gemeinden
B53: Nettoertrag (standardisierter Ertrag) | C53: =SUM(D53:BZ53) -> 59811726 | D53: =D51-D52 -> 10387286 | E53: =E51-E52 -> 912441.64 | F53: =F51-F52 -> 185351.85 | G53: =G51-G52 -> 86210.44 | H53: =H51-H52 -> 600536.95 | I53: =I51-I52 -> 930406 | J53: =J51-J52 -> 234393 | K53: =K51-K52 -> 29776 | ... BZ53: =BZ51-BZ52 -> 885924.09
A55: 1.7) | B55: Grundstückgewinnsteuer
B56: Bruttoertrag | C56: =SUM(D56:BZ56) -> 93028694 | D56: 14503679 | E56: 2194477.7 | F56: 206264.6 | G56: 304945.25 | H56: 1345683.6 | I56: 1325581.4 | J56: 378262.05 | K56: 118967.6 | L56: 288846 | M56: 132502.9 | N56: 680006.85 | O56: 974320.15 | P56: 566986.8 | Q56: 1346172 | R56: 512265.8 | S56: 1549933.8 | T56: 962845.6 | U56: 1081536.1 | V56: 1171300.6 | W56: 854594.35 | X56: 1749470.3 | Y56: 334138.65 | Z56: 392702.9 | AA56: 1854608.9 | AB56: 329099.65 | AC56: 1775127.9 | AD56: 1039953.4 | AE56: 807322.65 | AF56: 756713.75 | AG56: 1302279.4 | AH56: 1460649.6 | AI56: 520668.05 | AJ56: 715527.15 | AK56: 1335660.9 | AL56: 893285.2 | AM56: 2160312.5 | AN56: 48691.9 | AO56: 1190608.1 | AP56: 1167545.2 | AQ56: 747369 | AR56: 588733.55 | AS56: 569198.75 | AT56: 310365.15 | AU56: 616133.8 | AV56: 634761.55 | AW56: 513879.6 | AX56: 1195158.4 | AY56: 635047.95 | AZ56: 414650.8 | BA56: 9785081.9 | BB56: 1860856.6 | BC56: 751230.15 | BD56: 586253.5 | BE56: 840518.8 | BF56: 1345998.8 | BG56: 627217.6 | BH56: 579351 | BI56: 1135127.1 | BJ56: 182921.35 | BK56: 459970.9 | BL56: 1389210.1 | BM56: 550889.65 | BN56: 1252614.2 | BO56: 1794937.2 | BP56: 1306155.1 | BQ56: 244665.4 | BR56: 3419985.5 | BS56: 1289067.2 | BT56: 1428421.4 | BU56: 122269.65 | BV56: 511258.8 | BW56: 3049380.1 | BX56: 199617.2 | BY56: 608478.9 | BZ56: 1148378.6 | CB56: KStA
B57: Abschreibungen | C57: =SUM(D57:BZ57) -> 3924.45 | D57: 68.8 | E57: 43.75 | F57: 8.75 | G57: 1.55 | H57: 0 | I57: 18.05 | J57: 5.6 | K57: 0 | L57: 0 | M57: 2.5 | N57: 0.15 | O57: 4.15 | P57: 10.75 | Q57: 16.6 | R57: 0.3 | S57: 20.65 | T57: 33.3 | U57: 19.2 | V57: 2.95 | W57: 0 | X57: 15.9 | Y57: 6.4 | Z57: 16.8 | AA57: 11.05 | AB57: 0.05 | AC57: 2.05 | AD57: 3.95 | AE57: 2.9 | AF57: 21.05 | AG57: 19.4 | AH57: 5.4 | AI57: 0 | AJ57: 25.15 | AK57: 41.6 | AL57: 14.5 | AM57: 0 | AN57: 0 | AO57: 40.65 | AP57: 30.4 | AQ57: 9.45 | AR57: -31.95 | AS57: 269.3 | AT57: 2.9 | AU57: 5.55 | AV57: 0 | AW57: 0 | AX57: 3.2 | AY57: 4.2 | AZ57: 0 | BA57: 4.2 | BB57: 1918.35 | BC57: 0 | BD57: 2.1 | BE57: 5.5 | BF57: 6 | BG57: 17.2 | BH57: 4.3 | BI57: 27 | BJ57: 17.55 | BK57: 4.35 | BL57: 11.5 | BM57: 16.6 | BN57: 3.7 | BO57: 25.45 | BP57: 0 | BQ57: 0 | BR57: 18.65 | BS57: 22.2 | BT57: 89.8 | BU57: 0 | BV57: 1.65 | BW57: 906.65 | BX57: 15.2 | BY57: 0 | BZ57: 29.55 | CB57: KStA
...

Sheet SL Weite Basis
A1: Kanton St.Gallen
A2: Amt für Gemeinden und Bürgerrecht
A5: Sonderlastenausgleich Weite 2025
B7: Eingabefelder
C8: Total | D8: St.Gallen | E8: Wittenbach | F8: Häggenschwil | G8: Muolen | H8: Mörschwil | I8: Goldach | J8: Steinach | K8: Berg | L8: Tübach | M8: Untereggen | N8: Eggersriet | O8: Rorschacherberg | P8: Rorschach | Q8: Thal | R8: Rheineck | S8: St.Margrethen | T8: Au | U8: Berneck | V8: Balgach | W8: Diepoldsau | X8: Widnau | Y8: Rebstein | Z8: Marbach | AA8: Altstätten | AB8: Eichberg | AC8: Oberriet | AD8: Rüthi | AE8: Sennwald | AF8: Gams | AG8: Grabs | AH8: Buchs | AI8: Sevelen | AJ8: Wartau | AK8: Sargans | AL8: Vilters-Wangs | AM8: Bad Ragaz | AN8: Pfäfers | AO8: Mels | AP8: Flums | AQ8: Walenstadt | AR8: Quarten | AS8: Amden | AT8: Weesen | AU8: Schänis | AV8: Benken | AW8: Kaltbrunn | AX8: Gommiswald | AY8: Uznach | AZ8: Schmerikon | BA8: Rapperswil-Jona | BB8: Eschenbach | BC8: Wildhaus-Alt St.Johann | BD8: Nesslau | BE8: Ebnat-Kappel | BF8: Wattwil | BG8: Lichtensteig | BH8: Neckertal | BI8: Bütschwil-Ganterschwil | BJ8: Lütisburg | BK8: Mosnang | BL8: Kirchberg | BM8: Jonschwil | BN8: Oberuzwil | BO8: Uzwil | BP8: Flawil | BQ8: Degersheim | BR8: Wil | BS8: Zuzwil | BT8: Oberbüren | BU8: Niederbüren | BV8: Niederhelfenschwil | BW8: Gossau | BX8: Andwil | BY8: Waldkirch | BZ8: Gaiserwald | CB8: Quelle
A10: 1.) | B10: Allgemeine Daten
B12: ='Ressourcenausgleich Basis'!B124 -> Einwohnerzahl per 31.12. | C12: ='Ressourcenausgleich Basis'!C124 -> 535114 | D12: ='Ressourcenausgleich Basis'!D124 -> 78213 | E12: ='Ressourcenausgleich Basis'!E124 -> 10026 | F12: ='Ressourcenausgleich Basis'!F124 -> 1431 | G12: ='Ressourcenausgleich Basis'!G124 -> 1257 | H12: ='Ressourcenausgleich Basis'!H124 -> 3662 | I12: ='Ressourcenausgleich Basis'!I124 -> 9709 | ... BZ12: ='Ressourcenausgleich Basis'!BZ124 -> 8609
A15: 2.) | B15: Berechnung Sonderlastenausgleich Weite
A17: 2.1) | B17: Länge des Strassennetzes
B19: gewichtete Strassenlänge in km per 31.12. | C19: =SUM(D19:BZ19) -> 125235.24 | D19: 10066.292 | E19: 1310.8918 | F19: 701.577 | G19: 855.182 | H19: 993.2544 | I19: 1249.827 | J19: 576.485 | K19: 284.222 | L19: 205.687 | M19: 519.8956 | N19: 874.2578 | O19: 1160.425 | P19: 1124.358 | Q19: 1427.3 | R19: 572.782 | S19: 1020.14 | T19: 1055.805 | U19: 847.8914 | V19: 783.923 | W19: 1172.627 | X19: 1314.211 | Y19: 764.733 | Z19: 687.784 | AA19: 4106.595 | AB19: 602.717 | AC19: 3379.2274 | AD19: 883.492 | AE19: 1941.105 | AF19: 1311.427 | AG19: 2734.0092 | AH19: 1653.93 | AI19: 1478.321 | AJ19: 1564.5064 | AK19: 958.037 | AL19: 1439.271 | AM19: 1158.3412 | AN19: 1859.6064 | AO19: 3085.0162 | AP19: 2034.2468 | AQ19: 1313.409 | AR19: 968.56 | AS19: 1535.6024 | AT19: 299.946 | AU19: 1259.112 | AV19: 953.002 | AW19: 971.197 | AX19: 1370.6226 | AY19: 894.218 | AZ19: 540.465 | BA19: 2652.419 | BB19: 3400.0128 | BC19: 2075.4826 | BD19: 2633.0698 | BE19: 2441.4366 | BF19: 3280.3196 | BG19: 355.9052 | BH19: 5094.0272 | BI19: 1871.1374 | BJ19: 923.506 | BK19: 2291.0282 | BL19: 4033.4392 | BM19: 1015.3124 | BN19: 1281.5226 | BO19: 2407.979 | BP19: 2009.1152 | BQ19: 1492.3382 | BR19: 3299.3842 | BS19: 872.811 | BT19: 1695.6946 | BU19: 842.759 | BV19: 1286.016 | BW19: 3461.2002 | BX19: 654.5826 | BY19: 2371.4128 | BZ19: 1627.7938 | CB19: BD
B20: gewichtete Strassenlänge in km pro Einwohner | D20: =D19/D12 -> 0.12870357 | E20: =E19/E12 -> 0.13074923 | F20: =F19/F12 -> 0.49027044 | G20: =G19/G12 -> 0.68033572 | H20: =H19/H12 -> 0.27123277 | I20: =I19/I12 -> 0.12872871 | J20: =J19/J12 -> 0.16102933 | K20: =K19/K12 -> 0.28085178 | ... BZ20: =BZ19/BZ12 -> 0.18908047
B21: Pauschalbeitrag je gewichtetem Kilometer | C21: 1166 | CB21: FAG
B22: Beitrag je Einwohner | D22: =D20*$C21 -> 150.06836 | E22: =E20*$C21 -> 152.4536 | F22: =F20*$C21 -> 571.65533 | G22: =G20*$C21 -> 793.27145 | H22: =H20*$C21 -> 316.25741 | I22: =I20*$C21 -> 150.09767 | J22: =J20*$C21 -> 187.7602 | K22: =K20*$C21 -> 327.47317 | ... BZ22: =BZ20*$C21 -> 220.46783
B24: Sonderlast total | D24: =D12*D22 -> 11737297 | E24: =E12*E22 -> 1528499.8 | F24: =F12*F22 -> 818038.78 | G24: =G12*G22 -> 997142.21 | H24: =H12*H22 -> 1158134.6 | I24: =I12*I22 -> 1457298.3 | J24: =J12*J22 -> 672181.51 | K24: =K12*K22 -> 331402.85 | ... BZ24: =BZ12*BZ22 -> 1898007.6
A26: 2.2) | B26: Wohnbevölkerung mit Wohnsitz über 800 Metern über Meer
B28: Einwohner über 800m per 31.12. | C28: =SUM(D28:BZ28) -> 21712 | D28: 1750 | E28: 0 | F28: 1 | G28: 0 | H28: 0 | I28: 0 | J28: 0 | K28: 0 | L28: 0 | M28: 0 | N28: 2224 | O28: 0 | P28: 0 | Q28: 0 | R28: 0 | S28: 0 | T28: 0 | U28: 0 | V28: 0 | W28: 0 | X28: 0 | Y28: 0 | Z28: 0 | AA28: 131 | AB28: 0 | AC28: 3 | AD28: 0 | AE28: 1 | AF28: 58 | AG28: 171 | AH28: 15 | AI28: 70 | AJ28: 37 | AK28: 0 | AL28: 17 | AM28: 11 | AN28: 1508 | AO28: 266 | AP28: 658 | AQ28: 148 | AR28: 135 | AS28: 1478 | AT28: 14 | AU28: 9 | AV28: 0 | AW28: 21 | AX28: 253 | AY28: 0 | AZ28: 0 | BA28: 0 | BB28: 742 | BC28: 2618 | BD28: 1609 | BE28: 463 | BF28: 726 | BG28: 4 | BH28: 3073 | BI28: 27 | BJ28: 59 | BK28: 307 | BL28: 120 | BM28: 0 | BN28: 0 | BO28: 0 | BP28: 0 | BQ28: 2838 | BR28: 0 | BS28: 0 | BT28: 0 | BU28: 0 | BV28: 0 | BW28: 0 | BX28: 3 | BY28: 111 | BZ28: 33 | CB28: BD
B29: Anteil an Gesamtbevölkerung | D29: =D28/D12 -> 0.022374797 | E29: =E28/E12 -> 0 | F29: =F28/F12 -> 0.00069881202 | G29: =G28/G12 -> 0 | H29: =H28/H12 -> 0 | I29: =I28/I12 -> 0 | J29: =J28/J12 -> 0 | K29: =K28/K12 -> 0 | ... BZ29: =BZ28/BZ12 -> 0.0038331978
B30: Pauschalbeitrag je Einwohner | C30: 134 | CB30: FAG
B31: Beitrag je Einwohner | D31: =D29*$C30 -> 2.9982228 | E31: =E29*$C30 -> 0 | F31: =F29*$C30 -> 0.093640811 | G31: =G29*$C30 -> 0 | H31: =H29*$C30 -> 0 | I31: =I29*$C30 -> 0 | J31: =J29*$C30 -> 0 | K31: =K29*$C30 -> 0 | ... BZ31: =BZ29*$C30 -> 0.51364851
B33: Sonderlast total | D33: =D31*D12 -> 234500 | E33: =E31*E12 -> 0 | F33: =F31*F12 -> 134 | G33: =G31*G12 -> 0 | H33: =H31*H12 -> 0 | I33: =I31*I12 -> 0 | J33: =J31*J12 -> 0 | K33: =K31*K12 -> 0 | ... BZ33: =BZ31*BZ12 -> 4422
A35: 2.3) | B35: Streuung des Siedlungsgebiets
B37: Streuung des Siedlungsgebiets per 31.12. | C37: =SUM(D37:BZ37) -> 89559.804 | D37: 5635.265 | E37: 0 | F37: 0 | G37: 0 | H37: 1416.3457 | I37: 0 | J37: 0 | K37: 0 | L37: 0 | M37: 0 | N37: 3386.469 | O37: 0 | P37: 0 | Q37: 0 | R37: 0 | S37: 0 | T37: 0 | U37: 0 | V37: 0 | W37: 0 | X37: 0 | Y37: 0 | Z37: 0 | AA37: 0 | AB37: 1303.7378 | AC37: 4634.3461 | AD37: 0 | AE37: 6275.212 | AF37: 0 | AG37: 0 | AH37: 0 | AI37: 0 | AJ37: 2878.4221 | AK37: 0 | AL37: 0 | AM37: 0 | AN37: 10487.398 | AO37: 0 | AP37: 0 | AQ37: 2706.927 | AR37: 3227.3218 | AS37: 0 | AT37: 0 | AU37: 0 | AV37: 0 | AW37: 0 | AX37: 4689.7287 | AY37: 0 | AZ37: 0 | BA37: 4402.5641 | BB37: 6359.2101 | BC37: 3817.8607 | BD37: 0 | BE37: 0 | BF37: 0 | BG37: 0 | BH37: 9280.882 | BI37: 0 | BJ37: 1621.8872 | BK37: 0 | BL37: 4971.8542 | BM37: 0 | BN37: 0 | BO37: 0 | BP37: 0 | BQ37: 0 | BR37: 0 | BS37: 0 | BT37: 4118.8784 | BU37: 0 | BV37: 2216.7633 | BW37: 0 | BX37: 0 | BY37: 3701.677 | BZ37: 2427.0541 | CB37: BD
B38: Pauschalbeitrag je Einwohner | C38: 0.008 | CB38: FAG
B39: Beitrag je Einwohner | D39: =D37*$C38 -> 45.08212 | E39: =E37*$C38 -> 0 | F39: =F37*$C38 -> 0 | G39: =G37*$C38 -> 0 | H39: =H37*$C38 -> 11.330765 | I39: =I37*$C38 -> 0 | J39: =J37*$C38 -> 0 | K39: =K37*$C38 -> 0 | ... BZ39: =BZ37*$C38 -> 19.416433
B41: Sonderlast total | D41: =D39*D12 -> 3526007.9 | E41: =E39*E12 -> 0 | F41: =F39*F12 -> 0 | G41: =G39*G12 -> 0 | H41: =H39*H12 -> 41493.263 | I41: =I39*I12 -> 0 | J41: =J39*J12 -> 0 | K41: =K39*K12 -> 0 | ... BZ41: =BZ39*BZ12 -> 167156.07
A43: 2.4) | B43: geringe Einwohnerdichte
B45: Gemeindefläche in ha per 31.12. | C45: =SUM(D45:BZ45) -> 198379.11 | D45: 3937.9027 | E45: 1219.8863 | F45: 907.13576 | G45: 1032.6048 | H45: 983.80483 | I45: 493.55439 | J45: 475.64582 | K45: 375.5481 | L45: 198.92533 | M45: 713.53101 | N45: 890.26861 | O45: 739.52706 | P45: 230.66874 | Q45: 1061.3525 | R45: 220.4941 | S45: 686.86051 | T45: 465.38316 | U45: 562.10794 | V45: 652.02473 | W45: 1124.5537 | X45: 421.82522 | Y45: 439.35968 | Z45: 438.05007 | AA45: 3946.2257 | AB45: 543.72095 | AC45: 3460.2139 | AD45: 933.35056 | AE45: 4156.4203 | AF45: 2227.3426 | AG45: 5464.7331 | AH45: 1595.008 | AI45: 3032.6793 | AJ45: 4175.1626 | AK45: 946.38909 | AL45: 3271.6752 | AM45: 2539.5592 | AN45: 12846.14 | AO45: 13910.56 | AP45: 7515.4821 | AQ45: 4884.1079 | AR45: 7321.0384 | AS45: 4761.8226 | AT45: 574.88233 | AU45: 3990.4293 | AV45: 1649.5495 | AW45: 1864.1369 | AX45: 3358.5925 | AY45: 753.53892 | AZ45: 597.65725 | BA45: 3136.8576 | BB45: 5489.1676 | BC45: 8752.84 | BD45: 9270.1651 | BE45: 4354.5887 | BF45: 5117.5465 | BG45: 282.00813 | BH45: 8184.0326 | BI45: 2183.3848 | BJ45: 1409.6043 | BK45: 5051.0875 | BL45: 4253.973 | BM45: 1099.4986 | BN45: 1407.6019 | BO45: 1449.5028 | BP45: 1146.9009 | BQ45: 1447.7431 | BR45: 2081.6392 | BS45: 896.73393 | BT45: 1773.1319 | BU45: 1583.6607 | BV45: 1637.1642 | BW45: 2750.6228 | BX45: 630.62275 | BY45: 3134.3092 | BZ45: 1263.2849 | CB45: BD
B46: Gemeindefläche je Einwohner | D46: =D45/D12 -> 0.050348443 | E46: =E45/E12 -> 0.12167228 | F46: =F45/F12 -> 0.63391737 | G46: =G45/G12 -> 0.82148356 | H46: =H45/H12 -> 0.26865233 | I46: =I45/I12 -> 0.05083473 | J46: =J45/J12 -> 0.13286196 | K46: =K45/K12 -> 0.37109496 | ... BZ46: =BZ45/BZ12 -> 0.14674002
B47: Pauschalbeitrag je ha je Einwohner | C47: 29 | CB47: FAG
B48: Beitrag je Einwohner | D48: =D46*$C47 -> 1.4601048 | E48: =E46*$C47 -> 3.528496 | F48: =F46*$C47 -> 18.383604 | G48: =G46*$C47 -> 23.823023 | H48: =H46*$C47 -> 7.7909176 | I48: =I46*$C47 -> 1.4742072 | J48: =J46*$C47 -> 3.8529969 | K48: =K46*$C47 -> 10.761754 | ... BZ48: =BZ46*$C47 -> 4.2554607
B50: Sonderlast total | D50: =D48*D12 -> 114199.18 | E50: =E48*E12 -> 35376.701 | F50: =F48*F12 -> 26306.937 | G50: =G48*G12 -> 29945.54 | H50: =H48*H12 -> 28530.34 | I50: =I48*I12 -> 14313.077 | J50: =J48*J12 -> 13793.729 | K50: =K48*K12 -> 10890.895 | ... BZ50: =BZ48*BZ12 -> 36635.261
A52: 2.5) | B52: Korrekturwert
B54: Korrekturwert je Einwohner für mittlere Belastung | C54: 320 | CB54: FAG
B56: Minderlast total | D56: =D12*$C54*-1 -> -25028160 | E56: =E12*$C54*-1 -> -3208320 | F56: =F12*$C54*-1 -> -457920 | G56: =G12*$C54*-1 -> -402240 | H56: =H12*$C54*-1 -> -1171840 | I56: =I12*$C54*-1 -> -3106880 | J56: =J12*$C54*-1 -> -1145600 | K56: =K12*$C54*-1 -> -323840 | ... BZ56: =BZ12*$C54*-1 -> -2754880
A58: 2.6) | B58: Sonderlastenausgleich Weite (vor allfälliger Kürzung) | D58: =IF((D24+D33+D41+D50+D56)<0,0,D24+D33+D41+D50+D56) -> 0 | E58: =IF((E24+E33+E41+E50+E56)<0,0,E24+E33+E41+E50+E56) -> 0 | F58: =IF((F24+F33+F41+F50+F56)<0,0,F24+F33+F41+F50+F56) -> 386559.72 | G58: =IF((G24+G33+G41+G50+G56)<0,0,G24+G33+G41+G50+G56) -> 624847.75 | H58: =IF((H24+H33+H41+H50+H56)<0,0,H24+H33+H41+H50+H56) -> 56318.234 | I58: =IF((I24+I33+I41+I50+I56)<0,0,I24+I33+I41+I50+I56) -> 0 | J58: =IF((J24+J33+J41+J50+J56)<0,0,J24+J33+J41+J50+J56) -> 0 | K58: =IF((K24+K33+K41+K50+K56)<0,0,K24+K33+K41+K50+K56) -> 18453.747 | ... BZ58: =IF((BZ24+BZ33+BZ41+BZ50+BZ56)<0,0,BZ24+BZ33+BZ41+BZ50+BZ56) -> 0
A60: 2.7) | B60: Kürzung infolge hoher technischer Steuerkraft
B62: Technische Steuerkraft in % zum kantonalen Durchschnitt | D62: ='Ressourcenausgleich Basis'!D144 -> 1.119226 | E62: ='Ressourcenausgleich Basis'!E144 -> 0.80767902 | F62: ='Ressourcenausgleich Basis'!F144 -> 0.84030989 | G62: ='Ressourcenausgleich Basis'!G144 -> 0.77439043 | H62: ='Ressourcenausgleich Basis'!H144 -> 1.8170994 | I62: ='Ressourcenausgleich Basis'!I144 -> 1.0415529 | J62: ='Ressourcenausgleich Basis'!J144 -> 0.94023797 | K62: ='Ressourcenausgleich Basis'!K144 -> 1.1118426 | ... BZ62: ='Ressourcenausgleich Basis'!BZ144 -> 1.0767138
B64: Kürzungsfaktor in % | D64: =IF(D62<100%,0%,IF(D62>120%,100%,(-100%+D62)/20*100)) -> 0.59613 | E64: =IF(E62<100%,0%,IF(E62>120%,100%,(-100%+E62)/20*100)) -> 0 | F64: =IF(F62<100%,0%,IF(F62>120%,100%,(-100%+F62)/20*100)) -> 0 | G64: =IF(G62<100%,0%,IF(G62>120%,100%,(-100%+G62)/20*100)) -> 0 | H64: =IF(H62<100%,0%,IF(H62>120%,100%,(-100%+H62)/20*100)) -> 1 | I64: =IF(I62<100%,0%,IF(I62>120%,100%,(-100%+I62)/20*100)) -> 0.20776451 | J64: =IF(J62<100%,0%,IF(J62>120%,100%,(-100%+J62)/20*100)) -> 0 | K64: =IF(K62<100%,0%,IF(K62>120%,100%,(-100%+K62)/20*100)) -> 0.559213 | ... BZ64: =IF(BZ62<100%,0%,IF(BZ62>120%,100%,(-100%+BZ62)/20*100)) -> 0.3835692
B65: Kürzung in Fr. | D65: =D58*-D64 -> 0 | E65: =E58*-E64 -> 0 | F65: =F58*-F64 -> 0 | G65: =G58*-G64 -> 0 | H65: =H58*-H64 -> -56318.234 | I65: =I58*-I64 -> 0 | J65: =J58*-J64 -> 0 | K65: =K58*-K64 -> -10319.575 | ... BZ65: =BZ58*-BZ64 -> 0
A68: 3.) | B68: Zusammenfassung
...

Sheet SL Schule Basis
A1: Kanton St.Gallen
A2: Amt für Gemeinden und Bürgerrecht
A5: Sonderlastenausgleich Schule 2025 | D5: Vorgenommene Korrekturen für Nachkalkulation!
B7: Eingabefelder
C8: Total | D8: St.Gallen | E8: Wittenbach | F8: Häggenschwil | G8: Muolen | H8: Mörschwil | I8: Goldach | J8: Steinach | K8: Berg | L8: Tübach | M8: Untereggen | N8: Eggersriet | O8: Rorschacherberg | P8: Rorschach | Q8: Thal | R8: Rheineck | S8: St.Margrethen | T8: Au | U8: Berneck | V8: Balgach | W8: Diepoldsau | X8: Widnau | Y8: Rebstein | Z8: Marbach | AA8: Altstätten | AB8: Eichberg | AC8: Oberriet | AD8: Rüthi | AE8: Sennwald | AF8: Gams | AG8: Grabs | AH8: Buchs | AI8: Sevelen | AJ8: Wartau | AK8: Sargans | AL8: Vilters-Wangs | AM8: Bad Ragaz | AN8: Pfäfers | AO8: Mels | AP8: Flums | AQ8: Walenstadt | AR8: Quarten | AS8: Amden | AT8: Weesen | AU8: Schänis | AV8: Benken | AW8: Kaltbrunn | AX8: Gommiswald | AY8: Uznach | AZ8: Schmerikon | BA8: Rapperswil-Jona | BB8: Eschenbach | BC8: Wildhaus-Alt St.Johann | BD8: Nesslau | BE8: Ebnat-Kappel | BF8: Wattwil | BG8: Lichtensteig | BH8: Neckertal | BI8: Bütschwil-Ganterschwil | BJ8: Lütisburg | BK8: Mosnang | BL8: Kirchberg | BM8: Jonschwil | BN8: Oberuzwil | BO8: Uzwil | BP8: Flawil | BQ8: Degersheim | BR8: Wil | BS8: Zuzwil | BT8: Oberbüren | BU8: Niederbüren | BV8: Niederhelfenschwil | BW8: Gossau | BX8: Andwil | BY8: Waldkirch | BZ8: Gaiserwald | CB8: Quelle
A10: 1.) | B10: Allgemeine Daten
B12: ='Ressourcenausgleich Basis'!B124 -> Einwohnerzahl per 31.12. | C12: ='Ressourcenausgleich Basis'!C124 -> 535114 | D12: ='Ressourcenausgleich Basis'!D124 -> 78213 | E12: ='Ressourcenausgleich Basis'!E124 -> 10026 | F12: ='Ressourcenausgleich Basis'!F124 -> 1431 | G12: ='Ressourcenausgleich Basis'!G124 -> 1257 | H12: ='Ressourcenausgleich Basis'!H124 -> 3662 | I12: ='Ressourcenausgleich Basis'!I124 -> 9709 | ... BZ12: ='Ressourcenausgleich Basis'!BZ124 -> 8609
B14: Schülerzahlen Volksschule per 31.12.2023 | C14: =SUM(D14:BZ14) -> 60379 | D14: 7466 | E14: 1157 | F14: 210 | G14: 153 | H14: 420 | I14: 1045 | J14: 369 | K14: 124 | L14: 231 | M14: 136 | N14: 311 | O14: 763 | P14: 946 | Q14: 731 | R14: 324 | S14: 752 | T14: 901 | U14: 466 | V14: 588 | W14: 818 | X14: 1173 | Y14: 506 | Z14: 229 | AA14: 1384 | AB14: 191 | AC14: 1131 | AD14: 344 | AE14: 613 | AF14: 491 | AG14: 903 | AH14: 1616 | AI14: 685 | AJ14: 718 | AK14: 793 | AL14: 589 | AM14: 698 | AN14: 186 | AO14: 1147 | AP14: 664 | AQ14: 688 | AR14: 313 | AS14: 171 | AT14: 181 | AU14: 582 | AV14: 393 | AW14: 604 | AX14: 581 | AY14: 853 | AZ14: 441 | BA14: 2968 | BB14: 1206 | BC14: 319 | BD14: 417 | BE14: 564 | BF14: 1034 | BG14: 197 | BH14: 835 | BI14: 681 | BJ14: 234 | BK14: 420 | BL14: 1298 | BM14: 537 | BN14: 860 | BO14: 1744 | BP14: 1277 | BQ14: 558 | BR14: 2744 | BS14: 563 | BT14: 558 | BU14: 217 | BV14: 459 | BW14: 2065 | BX14: 298 | BY14: 530 | BZ14: 1017 | CB14: BLD
B15: Schülerzahlen Sonderschule per 31.12.2023 | C15: =SUM(D15:BZ15) -> 1583 | D15: 219 | E15: 42 | F15: 2 | G15: 3 | H15: 8 | I15: 32 | J15: 10 | K15: 1 | L15: 2 | M15: 5 | N15: 13 | O15: 32 | P15: 47 | Q15: 13 | R15: 12 | S15: 22 | T15: 28 | U15: 10 | V15: 10 | W15: 13 | X15: 38 | Y15: 24 | Z15: 4 | AA15: 39 | AB15: 2 | AC15: 25 | AD15: 5 | AE15: 9 | AF15: 5 | AG15: 21 | AH15: 46 | AI15: 17 | AJ15: 14 | AK15: 19 | AL15: 11 | AM15: 18 | AN15: 3 | AO15: 28 | AP15: 13 | AQ15: 16 | AR15: 1 | AS15: 3 | AT15: 4 | AU15: 13 | AV15: 12 | AW15: 10 | AX15: 11 | AY15: 35 | AZ15: 10 | BA15: 63 | BB15: 31 | BC15: 0 | BD15: 12 | BE15: 22 | BF15: 46 | BG15: 12 | BH15: 29 | BI15: 21 | BJ15: 6 | BK15: 5 | BL15: 37 | BM15: 6 | BN15: 26 | BO15: 43 | BP15: 43 | BQ15: 10 | BR15: 82 | BS15: 14 | BT15: 8 | BU15: 2 | BV15: 5 | BW15: 45 | BX15: 3 | BY15: 5 | BZ15: 27 | CB15: BLD
B17: Nettoaufwand Schulrat in Einheitsgemeinden (Funktion 0121) | C17: =SUM(D17:BZ17) -> 6056128.4 | D17: 26415.95 | E17: 15160 | F17: 47814.75 | G17: 29394.2 | H17: 0 | I17: 156205 | J17: 79802.65 | K17: 70229.25 | L17: 29928 | M17: 50949.11 | N17: 77894.8 | O17: 261485.15 | P17: 249309.45 | Q17: 75871.07 | R17: 109590.15 | S17: 142707.25 | T17: 0 | U17: 115564.1 | V17: 0 | W17: 249430.9 | X17: 336027.05 | Y17: 0 | Z17: 0 | AA17: 0 | AB17: 0 | AC17: 0 | AD17: 19939.2 | AE17: 149071.3 | AF17: 152488.48 | AG17: 54651.1 | AH17: 125182 | AI17: 143787.1 | AJ17: 114955.45 | AK17: 113756.7 | AL17: 83437.19 | AM17: 145649.61 | AN17: 43079.45 | AO17: 173573.95 | AP17: 102806.68 | AQ17: 16751.35 | AR17: 116178.6 | AS17: 0 | AT17: 0 | AU17: 0 | AV17: 74938.55 | AW17: 6858.6 | AX17: 0 | AY17: 0 | AZ17: 0 | BA17: 98605 | BB17: 43123.5 | BC17: 49582.17 | BD17: 31603.15 | BE17: 129850 | BF17: 0 | BG17: 59249.45 | BH17: 6071.65 | BI17: 137622.35 | BJ17: 0 | BK17: 111421.25 | BL17: 131797.2 | BM17: 110114.3 | BN17: 69710.05 | BO17: 45072.5 | BP17: 266518.24 | BQ17: 98895.25 | BR17: 36364.6 | BS17: 96290.15 | BT17: 0 | BU17: 0 | BV17: 35057.35 | BW17: 321412.1 | BX17: 0 | BY17: 169745.83 | BZ17: 247138.15 | CB17: GFS
B18: Nettoaufwand Obligatorische Schule (Funktion 21) | C18: =SUM(D18:BZ18) -> 1.1954987e+09 | D18: 1.6479301e+08 | E18: 22153097 | F18: 3868385.5 | G18: 3149919.8 | H18: 8937112.8 | I18: 19532274 | J18: 7451553.4 | K18: 2559988.5 | L18: 3897994.2 | M18: 2730834.2 | N18: 5930382.2 | O18: 15778317 | P18: 21124538 | Q18: 14716465 | R18: 6067391.9 | S18: 13286184 | T18: 18030766 | U18: 8959580.4 | V18: 10332333 | W18: 14634824 | X18: 19418440 | Y18: 10676102 | Z18: 4868991 | AA18: 26895536 | AB18: 3613717.9 | AC18: 22184318 | AD18: 6330471.7 | AE18: 12131719 | AF18: 8986756.5 | AG18: 17073004 | AH18: 29202052 | AI18: 13161143 | AJ18: 13315056 | AK18: 14248350 | AL18: 11752890 | AM18: 13007285 | AN18: 4577235.7 | AO18: 20559907 | AP18: 11380075 | AQ18: 11975123 | AR18: 5581747.5 | AS18: 3851683.2 | AT18: 3933518 | AU18: 8948826.5 | AV18: 7533931.9 | AW18: 10947302 | AX18: 12678046 | AY18: 16322011 | AZ18: 9234890.4 | BA18: 64971345 | BB18: 23788559 | BC18: 6042872.2 | BD18: 8069592.6 | BE18: 13366358 | BF18: 17961728 | BG18: 3786616 | BH18: 17505607 | BI18: 12802283 | BJ18: 4885962.8 | BK18: 8608225.6 | BL18: 27680949 | BM18: 11415024 | BN18: 17851847 | BO18: 29670026 | BP18: 25007218 | BQ18: 9829828.7 | BR18: 56050109 | BS18: 11798940 | BT18: 11879645 | BU18: 4788722.2 | BV18: 9168570.1 | BW18: 38844774 | BX18: 5590125 | BY18: 10303068 | BZ18: 21505665 | CB18: GFS
B19: Nettoaufwand Schulgesundheitsdienst in EHG (Funktion 433) | C19: =SUM(D19:BZ19) -> 3910715.7 | D19: 1736001.8 | E19: 37046.45 | F19: 8034.2 | G19: 4431 | H19: 0 | I19: 65020.2 | J19: 17787.1 | K19: 3219.15 | L19: 9316.95 | M19: 7034.7 | N19: 10007.15 | O19: 36218.55 | P19: 30945.4 | Q19: 38767.82 | R19: 15065.7 | S19: 22894 | T19: 0 | U19: 15080.95 | V19: 0 | W19: 36917.3 | X19: 48998.24 | Y19: 0 | Z19: 0 | AA19: 0 | AB19: 0 | AC19: 0 | AD19: 8746.49 | AE19: 30642.5 | AF19: 23538.05 | AG19: 54799.66 | AH19: 86784.1 | AI19: 28854.55 | AJ19: 29927.85 | AK19: 28771.25 | AL19: 31745.6 | AM19: 33557.25 | AN19: 9012.77 | AO19: 27877.65 | AP19: 37114.05 | AQ19: 38674.95 | AR19: 29732.6 | AS19: 0 | AT19: 0 | AU19: 38837.3 | AV19: 17110.9 | AW19: 33778.2 | AX19: 22098.3 | AY19: 45322.1 | AZ19: 26285.8 | BA19: 161101.41 | BB19: 65967.85 | BC19: 16169.8 | BD19: 32979.44 | BE19: 32234.25 | BF19: 0 | BG19: 7729.8 | BH19: 21442 | BI19: 22486.71 | BJ19: 0 | BK19: 27404.15 | BL19: 66930.35 | BM19: 26132.45 | BN19: 23515.69 | BO19: 66877.14 | BP19: 53979.25 | BQ19: 11534.25 | BR19: 231893.2 | BS19: 31065.85 | BT19: 0 | BU19: 0 | BV19: 18957.3 | BW19: 88327.06 | BX19: 0 | BY19: 24569.88 | BZ19: 53419.3 | CB19: GFS
B20: Total | C20: =SUM(C17:C19) -> 1.2054656e+09 | D20: =SUM(D17:D19) -> 1.6655543e+08 | E20: =SUM(E17:E19) -> 22205303 | F20: =SUM(F17:F19) -> 3924234.5 | G20: =SUM(G17:G19) -> 3183745 | H20: =SUM(H17:H19) -> 8937112.8 | I20: =SUM(I17:I19) -> 19753499 | J20: =SUM(J17:J19) -> 7549143.2 | ... BZ20: =SUM(BZ17:BZ19) -> 21806223
B22: Kantonaler Durchschnitt Kosten je Schüler | C22: =C20/C14 -> 19964.981
A25: 2.) | B25: Berechnung Sonderlastenausgleich Schule
A27: 2.1) | B27: Sonder-/Minderlasten Volksschule
B29: Beitragssatz Volksschule bei überdurchschnittlicher Belastung | C29: 0.65
B30: Beitragssatz Volksschule bei unterdurchschnittlicher Belastung | C30: 0.2
B31: Volksschüler je Einwohner | C31: =C14/C12 -> 0.1128339 | D31: =D14/D12 -> 0.095457277 | E31: =E14/E12 -> 0.11539996 | F31: =F14/F12 -> 0.14675052 | G31: =G14/G12 -> 0.12171838 | H31: =H14/H12 -> 0.11469143 | I31: =I14/I12 -> 0.10763209 | J31: =J14/J12 -> 0.10307263 | ... BZ31: =BZ14/BZ12 -> 0.11813219
B32: BLD-Sozialindex per 31.12. | D32: 1.11 | E32: 1.06 | F32: 0.83 | G32: 0.84 | H32: 0.81 | I32: 0.99 | J32: 0.97 | K32: 0.85 | L32: 0.83 | M32: 0.8 | N32: 0.85 | O32: 1 | P32: 1.2 | Q32: 0.94 | R32: 1.04 | S32: 1.11 | T32: 1.02 | U32: 0.88 | V32: 0.89 | W32: 0.91 | X32: 0.94 | Y32: 1.03 | Z32: 0.88 | AA32: 0.98 | AB32: 0.87 | AC32: 0.91 | AD32: 0.92 | AE32: 0.94 | AF32: 0.9 | AG32: 0.92 | AH32: 1.03 | AI32: 1.05 | AJ32: 0.98 | AK32: 0.95 | AL32: 0.89 | AM32: 0.93 | AN32: 0.86 | AO32: 0.92 | AP32: 0.96 | AQ32: 0.92 | AR32: 0.87 | AS32: 0.83 | AT32: 0.93 | AU32: 0.92 | AV32: 0.87 | AW32: 0.93 | AX32: 0.9 | AY32: 1.01 | AZ32: 0.98 | BA32: 0.92 | BB32: 0.9 | BC32: 0.86 | BD32: 0.95 | BE32: 0.99 | BF32: 1.05 | BG32: 1.05 | BH32: 0.97 | BI32: 0.96 | BJ32: 0.91 | BK32: 0.86 | BL32: 1.02 | BM32: 0.88 | BN32: 0.94 | BO32: 1.01 | BP32: 1.03 | BQ32: 0.97 | BR32: 1.09 | BS32: 0.86 | BT32: 0.87 | BU32: 0.8 | BV32: 0.83 | BW32: 0.94 | BX32: 0.85 | BY32: 0.85 | BZ32: 0.92 | CB32: Fachstelle für Statistik
B33: reduzierter BLD-Sozialindex per 31.12. | D33: =1+(D32-1)*0.15 -> 1.0165 | E33: =1+(E32-1)*0.15 -> 1.009 | F33: =1+(F32-1)*0.15 -> 0.9745 | G33: =1+(G32-1)*0.15 -> 0.976 | H33: =1+(H32-1)*0.15 -> 0.9715 | I33: =1+(I32-1)*0.15 -> 0.9985 | J33: =1+(J32-1)*0.15 -> 0.9955 | K33: =1+(K32-1)*0.15 -> 0.9775 | ... BZ33: =1+(BZ32-1)*0.15 -> 0.988
B35: Sonder-/Minderlasten Volksschule (vor allfälliger Kürzung) | D35: =IF(D31*D33>$C31,(D31*D33-$C31)*D12*$C22*$C29,(D31*D33-$C31)*D12*$C22*$C30) -> -4934899.6 | E35: =IF(E31*E33>$C31,(E31*E33-$C31)*E12*$C22*$C29,(E31*E33-$C31)*E12*$C22*$C30) -> 469001.4 | F35: =IF(F31*F33>$C31,(F31*F33-$C31)*F12*$C22*$C29,(F31*F33-$C31)*F12*$C22*$C30) -> 560353.07 | G35: =IF(G31*G33>$C31,(G31*G33-$C31)*G12*$C22*$C29,(G31*G33-$C31)*G12*$C22*$C30) -> 97274.605 | H35: =IF(H31*H33>$C31,(H31*H33-$C31)*H12*$C22*$C29,(H31*H33-$C31)*H12*$C22*$C30) -> -20634.785 | I35: =IF(I31*I33>$C31,(I31*I33-$C31)*I12*$C22*$C29,(I31*I33-$C31)*I12*$C22*$C30) -> -207922.67 | J35: =IF(J31*J33>$C31,(J31*J33-$C31)*J12*$C22*$C29,(J31*J33-$C31)*J12*$C22*$C30) -> -146167.08 | K35: =IF(K31*K33>$C31,(K31*K33-$C31)*K12*$C22*$C29,(K31*K33-$C31)*K12*$C22*$C30) -> 91127.361 | ... BZ35: =IF(BZ31*BZ33>$C31,(BZ31*BZ33-$C31)*BZ12*$C22*$C29,(BZ31*BZ33-$C31)*BZ12*$C22*$C30) -> 433555.85
A37: 2.2) | B37: Sonderlasten Sonderschule
B39: Pauschalbeitrag je Schüler in der Sonderschule | C39: 11000
B40: Beitragssatz Sonderschule | C40: 0.65
B41: Sonderschüler je Einwohner | C41: =C15/C12 -> 0.0029582481 | D41: =D15/D12 -> 0.002800046 | E41: =E15/E12 -> 0.0041891083 | F41: =F15/F12 -> 0.001397624 | G41: =G15/G12 -> 0.0023866348 | H41: =H15/H12 -> 0.0021845986 | I41: =I15/I12 -> 0.003295911 | J41: =J15/J12 -> 0.0027932961 | ... BZ41: =BZ15/BZ12 -> 0.0031362528
B43: Sonderlasten Sonderschule (vor allfälliger Kürzung) | D43: =IF(D41>$C41,(D41-$C41)*D12*$C39*$C40,0) -> 0 | E43: =IF(E41>$C41,(E41-$C41)*E12*$C39*$C40,0) -> 88235.319 | F43: =IF(F41>$C41,(F41-$C41)*F12*$C39*$C40,0) -> 0 | G43: =IF(G41>$C41,(G41-$C41)*G12*$C39*$C40,0) -> 0 | H43: =IF(H41>$C41,(H41-$C41)*H12*$C39*$C40,0) -> 0 | I43: =IF(I41>$C41,(I41-$C41)*I12*$C39*$C40,0) -> 23440.336 | J43: =IF(J41>$C41,(J41-$C41)*J12*$C39*$C40,0) -> 0 | K43: =IF(K41>$C41,(K41-$C41)*K12*$C39*$C40,0) -> 0 | ... BZ43: =IF(BZ41>$C41,(BZ41-$C41)*BZ12*$C39*$C40,0) -> 10956.958
A45: 2.3) | B45: Sonderlastenausgleich Schule (vor allfälliger Kürzung) | D45: =IF(D35+D43<0,0,D35+D43) -> 0 | E45: =IF(E35+E43<0,0,E35+E43) -> 557236.71 | F45: =IF(F35+F43<0,0,F35+F43) -> 560353.07 | G45: =IF(G35+G43<0,0,G35+G43) -> 97274.605 | H45: =IF(H35+H43<0,0,H35+H43) -> 0 | I45: =IF(I35+I43<0,0,I35+I43) -> 0 | J45: =IF(J35+J43<0,0,J35+J43) -> 0 | K45: =IF(K35+K43<0,0,K35+K43) -> 91127.361 | ... BZ45: =IF(BZ35+BZ43<0,0,BZ35+BZ43) -> 444512.81
A47: 2.4) | B47: Kürzung infolge hoher technischer Steuerkraft
B49: Technische Steuerkraft in % zum kantonalen Durchschnitt | D49: ='Ressourcenausgleich Basis'!D144 -> 1.119226 | E49: ='Ressourcenausgleich Basis'!E144 -> 0.80767902 | F49: ='Ressourcenausgleich Basis'!F144 -> 0.84030989 | G49: ='Ressourcenausgleich Basis'!G144 -> 0.77439043 | H49: ='Ressourcenausgleich Basis'!H144 -> 1.8170994 | I49: ='Ressourcenausgleich Basis'!I144 -> 1.0415529 | J49: ='Ressourcenausgleich Basis'!J144 -> 0.94023797 | K49: ='Ressourcenausgleich Basis'!K144 -> 1.1118426 | ... BZ49: ='Ressourcenausgleich Basis'!BZ144 -> 1.0767138
B51: Kürzungsfaktor in % | D51: =IF(D49<100%,0%,IF(D49>120%,100%,(-100%+D49)/20*100)) -> 0.59613 | E51: =IF(E49<100%,0%,IF(E49>120%,100%,(-100%+E49)/20*100)) -> 0 | F51: =IF(F49<100%,0%,IF(F49>120%,100%,(-100%+F49)/20*100)) -> 0 | G51: =IF(G49<100%,0%,IF(G49>120%,100%,(-100%+G49)/20*100)) -> 0 | H51: =IF(H49<100%,0%,IF(H49>120%,100%,(-100%+H49)/20*100)) -> 1 | I51: =IF(I49<100%,0%,IF(I49>120%,100%,(-100%+I49)/20*100)) -> 0.20776451 | J51: =IF(J49<100%,0%,IF(J49>120%,100%,(-100%+J49)/20*100)) -> 0 | K51: =IF(K49<100%,0%,IF(K49>120%,100%,(-100%+K49)/20*100)) -> 0.559213 | ... BZ51: =IF(BZ49<100%,0%,IF(BZ49>120%,100%,(-100%+BZ49)/20*100)) -> 0.3835692
B52: Kürzung in Fr. | D52: =D45*-D51 -> 0 | E52: =E45*-E51 -> 0 | F52: =F45*-F51 -> 0 | G52: =G45*-G51 -> 0 | H52: =H45*-H51 -> 0 | I52: =I45*-I51 -> 0 | J52: =J45*-J51 -> 0 | K52: =K45*-K51 -> -50959.605 | ... BZ52: =BZ45*-BZ51 -> -170501.42
A55: 3.) | B55: Zusammenfassung
B57: Sonder-/Minderlasten Volksschule | C57: =SUM(D57:BZ57) -> 22242517 | D57: =D35 -> -4934899.6 | E57: =E35 -> 469001.4 | F57: =F35 -> 560353.07 | G57: =G35 -> 97274.605 | H57: =H35 -> -20634.785 | I57: =I35 -> -207922.67 | J57: =J35 -> -146167.08 | K57: =K35 -> 91127.361 | ... BZ57: =BZ35 -> 433555.85
B58: Sonderlasten Sonderschule | C58: =SUM(D58:BZ58) -> 1329536.9 | D58: =D43 -> 0 | E58: =E43 -> 88235.319 | F58: =F43 -> 0 | G58: =G43 -> 0 | H58: =H43 -> 0 | I58: =I43 -> 23440.336 | J58: =J43 -> 0 | K58: =K43 -> 0 | ... BZ58: =BZ43 -> 10956.958
B60: Sonderlastenausgleich Schule (vor allfälliger Kürzung) | C60: =SUM(D60:BZ60) -> 34029883 | D60: =D45 -> 0 | E60: =E45 -> 557236.71 | F60: =F45 -> 560353.07 | G60: =G45 -> 97274.605 | H60: =H45 -> 0 | I60: =I45 -> 0 | J60: =J45 -> 0 | K60: =K45 -> 91127.361 | ... BZ60: =BZ45 -> 444512.81
B62: Kürzung infolge hoher technischer Steuerkraft | C62: =SUM(D62:BZ62) -> -974984.31 | D62: =D52 -> 0 | E62: =E52 -> 0 | F62: =F52 -> 0 | G62: =G52 -> 0 | H62: =H52 -> 0 | I62: =I52 -> 0 | J62: =J52 -> 0 | K62: =K52 -> -50959.605 | ... BZ62: =BZ52 -> -170501.42
B64: Beitrag Sonderlastenausgleich Schule | C64: =SUM(D64:BZ64) -> 33054900 | D64: =ROUND(D60+D62,-2) -> 0 | E64: =ROUND(E60+E62,-2) -> 557200 | F64: =ROUND(F60+F62,-2) -> 560400 | G64: =ROUND(G60+G62,-2) -> 97300 | H64: =ROUND(H60+H62,-2) -> 0 | I64: =ROUND(I60+I62,-2) -> 0 | J64: =ROUND(J60+J62,-2) -> 0 | K64: =ROUND(K60+K62,-2) -> 40200 | ... BZ64: =ROUND(BZ60+BZ62,-2) -> 274000

Sheet SL Sozio Basis
A1: Kanton St.Gallen
A2: Amt für Gemeinden und Bürgerrecht
A5: Soziodemographischer Sonderlastenausgleich 2025 | E5: Vorgenommene Korrekturen für Nachkalkulation!
B7: Eingabefelder
C8: Total | D8: St.Gallen | E8: Wittenbach | F8: Häggenschwil | G8: Muolen | H8: Mörschwil | I8: Goldach | J8: Steinach | K8: Berg | L8: Tübach | M8: Untereggen | N8: Eggersriet | O8: Rorschacherberg | P8: Rorschach | Q8: Thal | R8: Rheineck | S8: St.Margrethen | T8: Au | U8: Berneck | V8: Balgach | W8: Diepoldsau | X8: Widnau | Y8: Rebstein | Z8: Marbach | AA8: Altstätten | AB8: Eichberg | AC8: Oberriet | AD8: Rüthi | AE8: Sennwald | AF8: Gams | AG8: Grabs | AH8: Buchs | AI8: Sevelen | AJ8: Wartau | AK8: Sargans | AL8: Vilters-Wangs | AM8: Bad Ragaz | AN8: Pfäfers | AO8: Mels | AP8: Flums | AQ8: Walenstadt | AR8: Quarten | AS8: Amden | AT8: Weesen | AU8: Schänis | AV8: Benken | AW8: Kaltbrunn | AX8: Gommiswald | AY8: Uznach | AZ8: Schmerikon | BA8: Rapperswil-Jona | BB8: Eschenbach | BC8: Wildhaus-Alt St.Johann | BD8: Nesslau | BE8: Ebnat-Kappel | BF8: Wattwil | BG8: Lichtensteig | BH8: Neckertal | BI8: Bütschwil-Ganterschwil | BJ8: Lütisburg | BK8: Mosnang | BL8: Kirchberg | BM8: Jonschwil | BN8: Oberuzwil | BO8: Uzwil | BP8: Flawil | BQ8: Degersheim | BR8: Wil | BS8: Zuzwil | BT8: Oberbüren | BU8: Niederbüren | BV8: Niederhelfenschwil | BW8: Gossau | BX8: Andwil | BY8: Waldkirch | BZ8: Gaiserwald | CB8: Quelle
A10: 1.) | B10: Allgemeine Daten
B12: ='Ressourcenausgleich Basis'!B124 -> Einwohnerzahl per 31.12. | C12: ='Ressourcenausgleich Basis'!C124 -> 535114 | D12: ='Ressourcenausgleich Basis'!D124 -> 78213 | E12: ='Ressourcenausgleich Basis'!E124 -> 10026 | F12: ='Ressourcenausgleich Basis'!F124 -> 1431 | G12: ='Ressourcenausgleich Basis'!G124 -> 1257 | H12: ='Ressourcenausgleich Basis'!H124 -> 3662 | I12: ='Ressourcenausgleich Basis'!I124 -> 9709 | ... BZ12: ='Ressourcenausgleich Basis'!BZ124 -> 8609
A15: 2.) | B15: Berechnung Soziodemographischer Sonderlastenausgleich
A17: 2.1) | B17: Sonderlasten Familie und Jugend
B19: Beitragssatz bei überdurchschnittlicher Belastung | C19: 0.6
B20: Beitragssatz bei unterdurchschnittlicher Belastung | C20: 0
B22: Nettoaufwand Familie und Jugend (Funktion 54) | C22: =SUM(D22:BZ22) -> 72059794 | D22: 21771194 | E22: 1802506.7 | F22: 94269.85 | G22: 60989.52 | H22: 174296.1 | I22: 911808 | J22: 392428 | K22: 5021.7 | L22: 98350 | M22: 85416.4 | N22: 142109.92 | O22: 1034327.2 | P22: 2627215.5 | Q22: 444079.79 | R22: 269492.88 | S22: 1744712.7 | T22: 771676.82 | U22: 365825.92 | V22: 451561.69 | W22: 634045.75 | X22: 1280808.7 | Y22: 705632.25 | Z22: -1469.51 | AA22: 1141359.3 | AB22: 77708 | AC22: 177954.79 | AD22: 352191.47 | AE22: 379166.15 | AF22: 297749.6 | AG22: 661217.06 | AH22: 1430178 | AI22: 763414.43 | AJ22: 712635.14 | AK22: 376715.57 | AL22: 203391.25 | AM22: 387621.99 | AN22: 64997.8 | AO22: 1184427.8 | AP22: 389988.89 | AQ22: 604537.61 | AR22: 86200.15 | AS22: 20277 | AT22: 78443 | AU22: 363608.5 | AV22: 189520.95 | AW22: 842148.48 | AX22: 162382.51 | AY22: 808830.71 | AZ22: 411379.45 | BA22: 4663945.6 | BB22: 1114584.4 | BC22: 44881.21 | BD22: 345686.59 | BE22: 738303.64 | BF22: 1247792.7 | BG22: 253555.61 | BH22: 555947.85 | BI22: 288101.2 | BJ22: 339376.8 | BK22: 44011.6 | BL22: 949453.1 | BM22: 371258 | BN22: 539853.8 | BO22: 1035116.9 | BP22: 1534198.6 | BQ22: 649485.62 | BR22: 4710020.2 | BS22: 103414.92 | BT22: 202640.99 | BU22: 66.15 | BV22: 44926.47 | BW22: 2591019.6 | BX22: 50369.72 | BY22: 539342.96 | BZ22: 1068093.8 | CB22: GFS
B23: Nettoaufwand Familie und Jugend pro Einwohner | C23: =C22/C12 -> 134.66251 | D23: =D22/D12 -> 278.35774 | E23: =E22/E12 -> 179.78324 | F23: =F22/F12 -> 65.876904 | G23: =G22/G12 -> 48.519905 | H23: =H22/H12 -> 47.595877 | I23: =I22/I12 -> 93.913688 | J23: =J22/J12 -> 109.61676 | ... BZ23: =BZ22/BZ12 -> 124.06711
B25: Sonderlasten Familie und Jugend | C25: =SUM(D25:BZ25) -> 10062792 | D25: =IF(D23-$C23>0,(D23-$C23)*D12*$C19,(D23-$C23)*D12*$C20) -> 6743301.1 | E25: =IF(E23-$C23>0,(E23-$C23)*E12*$C19,(E23-$C23)*E12*$C20) -> 271428.26 | F25: =IF(F23-$C23>0,(F23-$C23)*F12*$C19,(F23-$C23)*F12*$C20) -> 0 | G25: =IF(G23-$C23>0,(G23-$C23)*G12*$C19,(G23-$C23)*G12*$C20) -> 0 | H25: =IF(H23-$C23>0,(H23-$C23)*H12*$C19,(H23-$C23)*H12*$C20) -> 0 | I25: =IF(I23-$C23>0,(I23-$C23)*I12*$C19,(I23-$C23)*I12*$C20) -> 0 | J25: =IF(J23-$C23>0,(J23-$C23)*J12*$C19,(J23-$C23)*J12*$C20) -> 0 | K25: =IF(K23-$C23>0,(K23-$C23)*K12*$C19,(K23-$C23)*K12*$C20) -> 0 | ... BZ25: =IF(BZ23-$C23>0,(BZ23-$C23)*BZ12*$C19,(BZ23-$C23)*BZ12*$C20) -> 0
A28: 2.2) | B28: Sonder-/Minderlasten Sozialhilfe
B30: Beitragssatz bei überdurchschnittlicher Belastung | C30: 0.6
B31: Beitragssatz bei unterdurchschnittlicher Belastung | C31: 0.2
B33: Nettoaufwand Finanzielle Sozialhilfe (Funktion 572) | C33: =SUM(D33:BZ33) -> 63432251 | D33: 21649705 | E33: 1674131.6 | F33: 88381.75 | G33: 98794.3 | H33: 52666.15 | I33: 525430 | J33: 309808 | K33: 0 | L33: 13903 | M33: 100893.35 | N33: 8625.05 | O33: 1298450.1 | P33: 1201616.1 | Q33: 324197.1 | R33: 831767.52 | S33: 461720.31 | T33: 1132770.8 | U33: 183700.11 | V33: -59035.45 | W33: 156147.38 | X33: 258973.54 | Y33: 214685.33 | Z33: 175258.02 | AA33: 735352.31 | AB33: 135147 | AC33: -87876.45 | AD33: 75908.3 | AE33: 430160.27 | AF33: 50432.75 | AG33: 469516.51 | AH33: 1194268 | AI33: 590519.61 | AJ33: 512049 | AK33: 497985.1 | AL33: 116539.85 | AM33: 334915.6 | AN33: 114665.36 | AO33: 383983.25 | AP33: 294421.13 | AQ33: 74135.48 | AR33: 136260.05 | AS33: 59817.5 | AT33: -68471 | AU33: 388641.37 | AV33: 368269.86 | AW33: 693942.98 | AX33: 222851.88 | AY33: 298290.48 | AZ33: 531005.38 | BA33: 3899133.5 | BB33: 574037.87 | BC33: 15201.97 | BD33: 278950.17 | BE33: 666021.94 | BF33: 1031510.9 | BG33: 109932.75 | BH33: 823900.16 | BI33: 496318.57 | BJ33: 93580.6 | BK33: 152268.11 | BL33: 2092587.5 | BM33: 219532 | BN33: 423119.85 | BO33: 1277741 | BP33: 2104758.8 | BQ33: 434193.55 | BR33: 5678103.6 | BS33: 278665.6 | BT33: 187427.6 | BU33: 9516.84 | BV33: 211300.4 | BW33: 1673321.1 | BX33: 70748.95 | BY33: 326945.77 | BZ33: 1048110.8 | CB33: GFS
B34: Nettoaufwand Finanzielle Sozialhilfe pro Einwohner | C34: =C33/C12 -> 118.5397 | D34: =D33/D12 -> 276.80443 | E34: =E33/E12 -> 166.97902 | F34: =F33/F12 -> 61.762229 | G34: =G33/G12 -> 78.595306 | H34: =H33/H12 -> 14.3818 | I34: =I33/I12 -> 54.117829 | J34: =J33/J12 -> 86.538547 | ... BZ34: =BZ33/BZ12 -> 121.74594
